        "raw": "{\"channel\":\"order_book:1\",\"last_updated_at\":1785276648271131,\"offset\":3903633,\"order_book\":{\"code\":0,\"asks\":[{\"price\":\"63965.1\",\"size\":\"0.00000\"},{\"price\":\"63965.8\",\"size\":\"3.12836\"}],\"bids\":[{\"price\":\"63891.2\",\"size\":\"0.00000\"},{\"price\":\"63890.6\",\"size\":\"3.11562\"}],\"offset\":3903633,\"nonce\":36958754,\"last_updated_at\":1785276648271131,\"begin_nonce\":36958749},\"timestamp\":1785276648283,\"type\":\"update/order_book\"}"
        "raw": "{\"channel\":\"order_book:1\",\"last_updated_at\":1785276648375481,\"offset\":3903635,\"order_book\":{\"code\":0,\"asks\":[],\"bids\":[{\"price\":\"63889.4\",\"size\":\"0.00149\"},{\"price\":\"63889.3\",\"size\":\"0.00000\"}],\"offset\":3903635,\"nonce\":36958758,\"last_updated_at\":1785276648375481,\"begin_nonce\":36958754},\"timestamp\":1785276648384,\"type\":\"update/order_book\"}"
        "raw": "{\"channel\":\"order_book:1\",\"last_updated_at\":1785276648490004,\"offset\":3903637,\"order_book\":{\"code\":0,\"asks\":[{\"price\":\"63964.5\",\"size\":\"3.12836\"},{\"price\":\"63965.8\",\"size\":\"0.00000\"}],\"bids\":[{\"price\":\"63891.8\",\"size\":\"3.11562\"},{\"price\":\"63890.6\",\"size\":\"0.00000\"}],\"offset\":3903637,\"nonce\":36958763,\"last_updated_at\":1785276648490004,\"begin_nonce\":36958758},\"timestamp\":1785276648534,\"type\":\"update/order_book\"}"
        "raw": "{\"channel\":\"order_book:1\",\"last_updated_at\":1785276649323286,\"offset\":3903638,\"order_book\":{\"code\":0,\"asks\":[],\"bids\":[{\"price\":\"63895.0\",\"size\":\"3.11562\"},{\"price\":\"63891.8\",\"size\":\"0.00000\"}],\"offset\":3903638,\"nonce\":36958775,\"last_updated_at\":1785276649323286,\"begin_nonce\":36958763},\"timestamp\":1785276649334,\"type\":\"update/order_book\"}"
        "raw": "{\"channel\":\"order_book:1\",\"last_updated_at\":1785276649557761,\"offset\":3903639,\"order_book\":{\"code\":0,\"asks\":[{\"price\":\"63964.5\",\"size\":\"0.00000\"},{\"price\":\"63969.3\",\"size\":\"3.12836\"}],\"bids\":[{\"price\":\"63895.0\",\"size\":\"0.00000\"},{\"price\":\"63892.8\",\"size\":\"3.11562\"}],\"offset\":3903639,\"nonce\":36958780,\"last_updated_at\":1785276649557761,\"begin_nonce\":36958775},\"timestamp\":1785276649584,\"type\":\"update/order_book\"}"
        "raw": "{\"channel\":\"order_book:1\",\"last_updated_at\":1785276649632615,\"offset\":3903641,\"order_book\":{\"code\":0,\"asks\":[{\"price\":\"63972.5\",\"size\":\"0.00000\"},{\"price\":\"63972.6\",\"size\":\"0.00163\"}],\"bids\":[],\"offset\":3903641,\"nonce\":36958783,\"last_updated_at\":1785276649632615,\"begin_nonce\":36958780},\"timestamp\":1785276649634,\"type\":\"update/order_book\"}"
        "raw": "{\"channel\":\"order_book:1\",\"last_updated_at\":1785276649713894,\"offset\":3903642,\"order_book\":{\"code\":0,\"asks\":[{\"price\":\"63967.7\",\"size\":\"3.12836\"},{\"price\":\"63969.3\",\"size\":\"0.00000\"}],\"bids\":[{\"price\":\"63894.4\",\"size\":\"3.11562\"},{\"price\":\"63892.8\",\"size\":\"0.00000\"}],\"offset\":3903642,\"nonce\":36958785,\"last_updated_at\":1785276649713894,\"begin_nonce\":36958783},\"timestamp\":1785276649734,\"type\":\"update/order_book\"}"
        "raw": "{\"channel\":\"order_book:1\",\"last_updated_at\":1785276649882217,\"offset\":3903643,\"order_book\":{\"code\":0,\"asks\":[{\"price\":\"63964.7\",\"size\":\"3.12836\"},{\"price\":\"63967.7\",\"size\":\"0.00000\"}],\"bids\":[{\"price\":\"63897.5\",\"size\":\"3.11562\"},{\"price\":\"63894.4\",\"size\":\"0.00000\"}],\"offset\":3903643,\"nonce\":36958789,\"last_updated_at\":1785276649882217,\"begin_nonce\":36958785},\"timestamp\":1785276649884,\"type\":\"update/order_book\"}"
        "raw": "{\"channel\":\"order_book:1\",\"last_updated_at\":1785276650056523,\"offset\":3903645,\"order_book\":{\"code\":0,\"asks\":[],\"bids\":[{\"price\":\"63889.5\",\"size\":\"0.00149\"},{\"price\":\"63889.4\",\"size\":\"0.00000\"}],\"offset\":3903645,\"nonce\":36958792,\"last_updated_at\":1785276650056523,\"begin_nonce\":36958789},\"timestamp\":1785276650084,\"type\":\"update/order_book\"}"
        "raw": "{\"channel\":\"order_book:1\",\"last_updated_at\":1785276650421925,\"offset\":3903646,\"order_book\":{\"code\":0,\"asks\":[{\"price\":\"63964.5\",\"size\":\"3.12836\"},{\"price\":\"63964.7\",\"size\":\"0.00000\"}],\"bids\":[],\"offset\":3903646,\"nonce\":36958794,\"last_updated_at\":1785276650421925,\"begin_nonce\":36958792},\"timestamp\":1785276650433,\"type\":\"update/order_book\"}"
        "raw": "{\"channel\":\"order_book:1\",\"last_updated_at\":1785276650943737,\"offset\":3903647,\"order_book\":{\"code\":0,\"asks\":[],\"bids\":[{\"price\":\"63897.6\",\"size\":\"3.11562\"},{\"price\":\"63897.5\",\"size\":\"0.00000\"}],\"offset\":3903647,\"nonce\":36958799,\"last_updated_at\":1785276650943737,\"begin_nonce\":36958794},\"timestamp\":1785276650984,\"type\":\"update/order_book\"}"
        "raw": "{\"channel\":\"order_book:1\",\"last_updated_at\":1785276651115016,\"offset\":3903649,\"order_book\":{\"code\":0,\"asks\":[{\"price\":\"63972.6\",\"size\":\"0.00000\"},{\"price\":\"63972.7\",\"size\":\"0.00163\"}],\"bids\":[],\"offset\":3903649,\"nonce\":36958802,\"last_updated_at\":1785276651115016,\"begin_nonce\":36958799},\"timestamp\":1785276651134,\"type\":\"update/order_book\"}"
        "raw": "{\"channel\":\"order_book:1\",\"last_updated_at\":1785276651310182,\"offset\":3903650,\"order_book\":{\"code\":0,\"asks\":[{\"price\":\"63964.4\",\"size\":\"3.12836\"},{\"price\":\"63964.5\",\"size\":\"0.00000\"}],\"bids\":[{\"price\":\"63897.6\",\"size\":\"0.00000\"},{\"price\":\"63896.9\",\"size\":\"3.11562\"}],\"offset\":3903650,\"nonce\":36958806,\"last_updated_at\":1785276651310182,\"begin_nonce\":36958802},\"timestamp\":1785276651334,\"type\":\"update/order_book\"}"
        "raw": "{\"channel\":\"order_book:1\",\"last_updated_at\":1785276651447306,\"offset\":3903651,\"order_book\":{\"code\":0,\"asks\":[],\"bids\":[{\"price\":\"63896.9\",\"size\":\"0.00000\"},{\"price\":\"63894.4\",\"size\":\"3.11562\"}],\"offset\":3903651,\"nonce\":36958807,\"last_updated_at\":1785276651447306,\"begin_nonce\":36958806},\"timestamp\":1785276651484,\"type\":\"update/order_book\"}"
        "raw": "{\"channel\":\"order_book:1\",\"last_updated_at\":1785276651674062,\"offset\":3903653,\"order_book\":{\"code\":0,\"asks\":[],\"bids\":[{\"price\":\"63889.6\",\"size\":\"0.00149\"},{\"price\":\"63889.5\",\"size\":\"0.00000\"}],\"offset\":3903653,\"nonce\":36958812,\"last_updated_at\":1785276651674062,\"begin_nonce\":36958807},\"timestamp\":1785276651684,\"type\":\"update/order_book\"}"
        "raw": "{\"channel\":\"order_book:1\",\"last_updated_at\":1785276651905187,\"offset\":3903655,\"order_book\":{\"code\":0,\"asks\":[{\"price\":\"63963.1\",\"size\":\"3.12842\"},{\"price\":\"63964.4\",\"size\":\"0.00000\"}],\"bids\":[{\"price\":\"63894.4\",\"size\":\"0.00000\"},{\"price\":\"63894.1\",\"size\":\"3.11569\"}],\"offset\":3903655,\"nonce\":36958817,\"last_updated_at\":1785276651905187,\"begin_nonce\":36958812},\"timestamp\":1785276651933,\"type\":\"update/order_book\"}"
        "raw": "{\"channel\":\"order_book:1\",\"last_updated_at\":1785276651975556,\"offset\":3903658,\"order_book\":{\"code\":0,\"asks\":[{\"price\":\"63972.6\",\"size\":\"0.00163\"},{\"price\":\"63972.7\",\"size\":\"0.00000\"}],\"bids\":[{\"price\":\"63889.6\",\"size\":\"0.00000\"},{\"price\":\"63889.5\",\"size\":\"0.00149\"}],\"offset\":3903658,\"nonce\":36958820,\"last_updated_at\":1785276651975556,\"begin_nonce\":36958817},\"timestamp\":1785276651983,\"type\":\"update/order_book\"}"
        "raw": "{\"channel\":\"order_book:1\",\"last_updated_at\":1785276652026111,\"offset\":3903671,\"order_book\":{\"code\":0,\"asks\":[{\"price\":\"63961.6\",\"size\":\"3.12851\"},{\"price\":\"63963.1\",\"size\":\"0.00000\"},{\"price\":\"63969.3\",\"size\":\"0.00163\"},{\"price\":\"63972.6\",\"size\":\"0.00000\"}],\"bids\":[{\"price\":\"63894.1\",\"size\":\"0.00000\"},{\"price\":\"63893.0\",\"size\":\"3.11577\"},{\"price\":\"63889.5\",\"size\":\"0.00000\"},{\"price\":\"63886.2\",\"size\":\"0.00149\"}],\"offset\":3903671,\"nonce\":36958833,\"last_updated_at\":1785276652026111,\"begin_nonce\":36958820},\"timestamp\":1785276652033,\"type\":\"update/order_book\"}"
        "raw": "{\"channel\":\"order_book:1\",\"last_updated_at\":1785276652230496,\"offset\":3903672,\"order_book\":{\"code\":0,\"asks\":[{\"price\":\"63961.6\",\"size\":\"0.00000\"},{\"price\":\"63964.5\",\"size\":\"3.12851\"}],\"bids\":[],\"offset\":3903672,\"nonce\":36958837,\"last_updated_at\":1785276652230496,\"begin_nonce\":36958833},\"timestamp\":1785276652234,\"type\":\"update/order_book\"}"
        "raw": "{\"channel\":\"order_book:1\",\"last_updated_at\":1785276652251282,\"offset\":3903675,\"order_book\":{\"code\":0,\"asks\":[{\"price\":\"63968.7\",\"size\":\"0.00163\"},{\"price\":\"63969.3\",\"size\":\"0.00000\"}],\"bids\":[{\"price\":\"63886.2\",\"size\":\"0.00000\"},{\"price\":\"63885.6\",\"size\":\"0.00149\"}],\"offset\":3903675,\"nonce\":36958843,\"last_updated_at\":1785276652251282,\"begin_nonce\":36958837},\"timestamp\":1785276652283,\"type\":\"update/order_book\"}"
        "raw": "{\"channel\":\"order_book:1\",\"last_updated_at\":1785276652446818,\"offset\":3903676,\"order_book\":{\"code\":0,\"asks\":[{\"price\":\"63961.9\",\"size\":\"3.12851\"},{\"price\":\"63964.5\",\"size\":\"0.00000\"}],\"bids\":[{\"price\":\"63893.0\",\"size\":\"0.00000\"},{\"price\":\"63890.7\",\"size\":\"3.11577\"}],\"offset\":3903676,\"nonce\":36958846,\"last_updated_at\":1785276652446818,\"begin_nonce\":36958843},\"timestamp\":1785276652484,\"type\":\"update/order_book\"}"
        "raw": "{\"channel\":\"order_book:1\",\"last_updated_at\":1785276652692345,\"offset\":3903677,\"order_book\":{\"code\":0,\"asks\":[{\"price\":\"63968.7\",\"size\":\"0.00000\"},{\"price\":\"63968.8\",\"size\":\"0.00163\"}],\"bids\":[],\"offset\":3903677,\"nonce\":36958848,\"last_updated_at\":1785276652692345,\"begin_nonce\":36958846},\"timestamp\":1785276652733,\"type\":\"update/order_book\"}"
        "raw": "{\"channel\":\"order_book:1\",\"last_updated_at\":1785276653088984,\"offset\":3903678,\"order_book\":{\"code\":0,\"asks\":[{\"price\":\"63961.9\",\"size\":\"3.12850\"}],\"bids\":[],\"offset\":3903678,\"nonce\":36958850,\"last_updated_at\":1785276653088984,\"begin_nonce\":36958848},\"timestamp\":1785276653134,\"type\":\"update/order_book\"}"
        "raw": "{\"channel\":\"order_book:1\",\"last_updated_at\":1785276653213030,\"offset\":3903679,\"order_book\":{\"code\":0,\"asks\":[{\"price\":\"63961.9\",\"size\":\"0.00000\"},{\"price\":\"63962.3\",\"size\":\"3.12850\"}],\"bids\":[{\"price\":\"63893.0\",\"size\":\"3.11577\"},{\"price\":\"63890.7\",\"size\":\"0.00000\"}],\"offset\":3903679,\"nonce\":36958852,\"last_updated_at\":1785276653213030,\"begin_nonce\":36958850},\"timestamp\":1785276653234,\"type\":\"update/order_book\"}"
        "raw": "{\"channel\":\"order_book:1\",\"last_updated_at\":1785276653769555,\"offset\":3903680,\"order_book\":{\"code\":0,\"asks\":[{\"price\":\"63962.3\",\"size\":\"0.00000\"},{\"price\":\"63964.5\",\"size\":\"3.12850\"}],\"bids\":[{\"price\":\"63893.1\",\"size\":\"3.11577\"},{\"price\":\"63893.0\",\"size\":\"0.00000\"}],\"offset\":3903680,\"nonce\":36958857,\"last_updated_at\":1785276653769555,\"begin_nonce\":36958852},\"timestamp\":1785276653783,\"type\":\"update/order_book\"}"
        "raw": "{\"channel\":\"order_book:1\",\"last_updated_at\":1785276653928252,\"offset\":3903683,\"order_book\":{\"code\":0,\"asks\":[{\"price\":\"63961.6\",\"size\":\"3.12850\"},{\"price\":\"63964.5\",\"size\":\"0.00000\"},{\"price\":\"63968.8\",\"size\":\"0.00000\"},{\"price\":\"63970.9\",\"size\":\"0.00163\"}],\"bids\":[{\"price\":\"63893.1\",\"size\":\"0.00000\"},{\"price\":\"63892.0\",\"size\":\"3.11577\"},{\"price\":\"63887.7\",\"size\":\"0.00149\"},{\"price\":\"63885.6\",\"size\":\"0.00000\"}],\"offset\":3903683,\"nonce\":36958862,\"last_updated_at\":1785276653928252,\"begin_nonce\":36958857},\"timestamp\":1785276653933,\"type\":\"update/order_book\"}"
        "raw": "{\"channel\":\"order_book:1\",\"last_updated_at\":1785276653946213,\"offset\":3903686,\"order_book\":{\"code\":0,\"asks\":[{\"price\":\"63970.9\",\"size\":\"0.00000\"},{\"price\":\"63972.7\",\"size\":\"0.00163\"}],\"bids\":[{\"price\":\"63889.5\",\"size\":\"0.00149\"},{\"price\":\"63887.7\",\"size\":\"0.00000\"}],\"offset\":3903686,\"nonce\":36958865,\"last_updated_at\":1785276653946213,\"begin_nonce\":36958862},\"timestamp\":1785276653984,\"type\":\"update/order_book\"}"
        "raw": "{\"channel\":\"order_book:1\",\"last_updated_at\":1785276654081426,\"offset\":3903690,\"order_book\":{\"code\":0,\"asks\":[{\"price\":\"63972.7\",\"size\":\"0.00000\"},{\"price\":\"63972.8\",\"size\":\"0.00163\"}],\"bids\":[{\"price\":\"63889.6\",\"size\":\"0.00149\"},{\"price\":\"63889.5\",\"size\":\"0.00000\"}],\"offset\":3903690,\"nonce\":36958870,\"last_updated_at\":1785276654081426,\"begin_nonce\":36958865},\"timestamp\":1785276654084,\"type\":\"update/order_book\"}"
        "raw": "{\"channel\":\"order_book:1\",\"last_updated_at\":1785276654147071,\"offset\":3903692,\"order_book\":{\"code\":0,\"asks\":[{\"price\":\"63961.6\",\"size\":\"0.00000\"},{\"price\":\"63964.9\",\"size\":\"3.12850\"}],\"bids\":[{\"price\":\"63892.0\",\"size\":\"0.00000\"},{\"price\":\"63891.9\",\"size\":\"3.11577\"}],\"offset\":3903692,\"nonce\":36958873,\"last_updated_at\":1785276654147071,\"begin_nonce\":36958870},\"timestamp\":1785276654183,\"type\":\"update/order_book\"}"
        "raw": "{\"channel\":\"order_book:1\",\"last_updated_at\":1785276654348221,\"offset\":3903693,\"order_book\":{\"code\":0,\"asks\":[{\"price\":\"63964.9\",\"size\":\"0.00000\"},{\"price\":\"63965.8\",\"size\":\"3.12850\"}],\"bids\":[{\"price\":\"63894.6\",\"size\":\"3.11577\"},{\"price\":\"63891.9\",\"size\":\"0.00000\"}],\"offset\":3903693,\"nonce\":36958881,\"last_updated_at\":1785276654348221,\"begin_nonce\":36958873},\"timestamp\":1785276654384,\"type\":\"update/order_book\"}"
        "raw": "{\"channel\":\"order_book:1\",\"last_updated_at\":1785276654930508,\"offset\":3903695,\"order_book\":{\"code\":0,\"asks\":[{\"price\":\"63965.8\",\"size\":\"0.00000\"},{\"price\":\"63970.1\",\"size\":\"3.12850\"}],\"bids\":[{\"price\":\"63894.6\",\"size\":\"0.00000\"},{\"price\":\"63890.2\",\"size\":\"3.11577\"}],\"offset\":3903695,\"nonce\":36958891,\"last_updated_at\":1785276654930508,\"begin_nonce\":36958881},\"timestamp\":1785276654933,\"type\":\"update/order_book\"}"
        "raw": "{\"channel\":\"order_book:1\",\"last_updated_at\":1785276655131593,\"offset\":3903698,\"order_book\":{\"code\":0,\"asks\":[{\"price\":\"63966.2\",\"size\":\"3.12850\"},{\"price\":\"63970.1\",\"size\":\"0.00000\"}],\"bids\":[{\"price\":\"63894.1\",\"size\":\"3.11577\"},{\"price\":\"63890.2\",\"size\":\"0.00000\"},{\"price\":\"63889.7\",\"size\":\"0.00149\"},{\"price\":\"63889.6\",\"size\":\"0.00000\"}],\"offset\":3903698,\"nonce\":36958897,\"last_updated_at\":1785276655131593,\"begin_nonce\":36958891},\"timestamp\":1785276655134,\"type\":\"update/order_book\"}"
        "raw": "{\"channel\":\"order_book:1\",\"last_updated_at\":1785276655215213,\"offset\":3903703,\"order_book\":{\"code\":0,\"asks\":[{\"price\":\"63972.8\",\"size\":\"0.00000\"},{\"price\":\"63981.8\",\"size\":\"0.00163\"}],\"bids\":[{\"price\":\"63898.7\",\"size\":\"0.00149\"},{\"price\":\"63889.7\",\"size\":\"0.00000\"}],\"offset\":3903703,\"nonce\":36958905,\"last_updated_at\":1785276655215213,\"begin_nonce\":36958897},\"timestamp\":1785276655234,\"type\":\"update/order_book\"}"
        "raw": "{\"channel\":\"order_book:1\",\"last_updated_at\":1785276655254635,\"offset\":3903705,\"order_book\":{\"code\":0,\"asks\":[{\"price\":\"63966.2\",\"size\":\"0.00000\"},{\"price\":\"63967.0\",\"size\":\"3.12838\"}],\"bids\":[{\"price\":\"63896.9\",\"size\":\"3.11565\"},{\"price\":\"63894.1\",\"size\":\"0.00000\"}],\"offset\":3903705,\"nonce\":36958907,\"last_updated_at\":1785276655254635,\"begin_nonce\":36958905},\"timestamp\":1785276655284,\"type\":\"update/order_book\"}"
        "raw": "{\"channel\":\"order_book:1\",\"last_updated_at\":1785276655314140,\"offset\":3903708,\"order_book\":{\"code\":0,\"asks\":[{\"price\":\"63981.2\",\"size\":\"0.00163\"},{\"price\":\"63981.8\",\"size\":\"0.00000\"}],\"bids\":[{\"price\":\"63898.7\",\"size\":\"0.00000\"},{\"price\":\"63898.1\",\"size\":\"0.00149\"}],\"offset\":3903708,\"nonce\":36958911,\"last_updated_at\":1785276655314140,\"begin_nonce\":36958907},\"timestamp\":1785276655333,\"type\":\"update/order_book\"}"
        "raw": "{\"channel\":\"order_book:1\",\"last_updated_at\":1785276655431778,\"offset\":3903710,\"order_book\":{\"code\":0,\"asks\":[{\"price\":\"63967.0\",\"size\":\"0.00000\"},{\"price\":\"63969.2\",\"size\":\"3.12838\"}],\"bids\":[{\"price\":\"63896.9\",\"size\":\"0.00000\"},{\"price\":\"63894.6\",\"size\":\"3.11565\"}],\"offset\":3903710,\"nonce\":36958915,\"last_updated_at\":1785276655431778,\"begin_nonce\":36958911},\"timestamp\":1785276655433,\"type\":\"update/order_book\"}"
        "raw": "{\"channel\":\"order_book:1\",\"last_updated_at\":1785276655902517,\"offset\":3903713,\"order_book\":{\"code\":0,\"asks\":[],\"bids\":[{\"price\":\"63898.2\",\"size\":\"0.00149\"},{\"price\":\"63898.1\",\"size\":\"0.00000\"}],\"offset\":3903713,\"nonce\":36958924,\"last_updated_at\":1785276655902517,\"begin_nonce\":36958915},\"timestamp\":1785276655933,\"type\":\"update/order_book\"}"
        "raw": "{\"channel\":\"order_book:1\",\"last_updated_at\":1785276656032117,\"offset\":3903714,\"order_book\":{\"code\":0,\"asks\":[{\"price\":\"63966.9\",\"size\":\"3.12838\"},{\"price\":\"63969.2\",\"size\":\"0.00000\"}],\"bids\":[{\"price\":\"63896.8\",\"size\":\"3.11565\"},{\"price\":\"63894.6\",\"size\":\"0.00000\"}],\"offset\":3903714,\"nonce\":36958925,\"last_updated_at\":1785276656032117,\"begin_nonce\":36958924},\"timestamp\":1785276656033,\"type\":\"update/order_book\"}"
        "raw": "{\"channel\":\"order_book:1\",\"last_updated_at\":1785276656073617,\"offset\":3903716,\"order_book\":{\"code\":0,\"asks\":[{\"price\":\"63981.2\",\"size\":\"0.00000\"},{\"price\":\"63981.3\",\"size\":\"0.00163\"}],\"bids\":[],\"offset\":3903716,\"nonce\":36958927,\"last_updated_at\":1785276656073617,\"begin_nonce\":36958925},\"timestamp\":1785276656083,\"type\":\"update/order_book\"}"
        "raw": "{\"channel\":\"order_book:1\",\"last_updated_at\":1785276656166807,\"offset\":3903720,\"order_book\":{\"code\":0,\"asks\":[{\"price\":\"63977.6\",\"size\":\"0.00163\"},{\"price\":\"63981.3\",\"size\":\"0.00000\"}],\"bids\":[{\"price\":\"63920.0\",\"size\":\"0.00097\"},{\"price\":\"63898.2\",\"size\":\"0.00000\"},{\"price\":\"63894.6\",\"size\":\"0.00149\"}],\"offset\":3903720,\"nonce\":36958931,\"last_updated_at\":1785276656166807,\"begin_nonce\":36958927},\"timestamp\":1785276656184,\"type\":\"update/order_book\"}"
        "raw": "{\"channel\":\"order_book:1\",\"last_updated_at\":1785276656232634,\"offset\":3903722,\"order_book\":{\"code\":0,\"asks\":[{\"price\":\"63977.6\",\"size\":\"0.00000\"},{\"price\":\"63977.7\",\"size\":\"0.00163\"}],\"bids\":[],\"offset\":3903722,\"nonce\":36958933,\"last_updated_at\":1785276656232634,\"begin_nonce\":36958931},\"timestamp\":1785276656234,\"type\":\"update/order_book\"}"
        "raw": "{\"channel\":\"order_book:1\",\"last_updated_at\":1785276656244763,\"offset\":3903723,\"order_book\":{\"code\":0,\"asks\":[{\"price\":\"63965.2\",\"size\":\"3.12838\"},{\"price\":\"63966.9\",\"size\":\"0.00000\"}],\"bids\":[],\"offset\":3903723,\"nonce\":36958934,\"last_updated_at\":1785276656244763,\"begin_nonce\":36958933},\"timestamp\":1785276656284,\"type\":\"update/order_book\"}"
        "raw": "{\"channel\":\"order_book:1\",\"last_updated_at\":1785276656721155,\"offset\":3903725,\"order_book\":{\"code\":0,\"asks\":[{\"price\":\"63965.1\",\"size\":\"3.12838\"},{\"price\":\"63965.2\",\"size\":\"0.00000\"}],\"bids\":[{\"price\":\"63896.8\",\"size\":\"0.00000\"},{\"price\":\"63896.1\",\"size\":\"3.11565\"},{\"price\":\"63894.7\",\"size\":\"0.00149\"},{\"price\":\"63894.6\",\"size\":\"0.00000\"}],\"offset\":3903725,\"nonce\":36958942,\"last_updated_at\":1785276656721155,\"begin_nonce\":36958934},\"timestamp\":1785276656734,\"type\":\"update/order_book\"}"
        "raw": "{\"channel\":\"order_book:1\",\"last_updated_at\":1785276656955177,\"offset\":3903728,\"order_book\":{\"code\":0,\"asks\":[{\"price\":\"63977.7\",\"size\":\"0.00000\"},{\"price\":\"63978.3\",\"size\":\"0.00163\"}],\"bids\":[{\"price\":\"63895.3\",\"size\":\"0.00149\"},{\"price\":\"63894.7\",\"size\":\"0.00000\"}],\"offset\":3903728,\"nonce\":36958949,\"last_updated_at\":1785276656955177,\"begin_nonce\":36958942},\"timestamp\":1785276656984,\"type\":\"update/order_book\"}"
        "raw": "{\"channel\":\"order_book:1\",\"last_updated_at\":1785276657165305,\"offset\":3903730,\"order_book\":{\"code\":0,\"asks\":[{\"price\":\"63965.1\",\"size\":\"0.00000\"},{\"price\":\"63966.2\",\"size\":\"3.12838\"}],\"bids\":[{\"price\":\"63897.0\",\"size\":\"3.11565\"},{\"price\":\"63896.1\",\"size\":\"0.00000\"}],\"offset\":3903730,\"nonce\":36958954,\"last_updated_at\":1785276657165305,\"begin_nonce\":36958949},\"timestamp\":1785276657183,\"type\":\"update/order_book\"}"
        "raw": "{\"channel\":\"order_book:1\",\"last_updated_at\":1785276657405843,\"offset\":3903731,\"order_book\":{\"code\":0,\"asks\":[{\"price\":\"63963.8\",\"size\":\"3.12838\"},{\"price\":\"63966.2\",\"size\":\"0.00000\"}],\"bids\":[{\"price\":\"63897.1\",\"size\":\"3.11565\"},{\"price\":\"63897.0\",\"size\":\"0.00000\"}],\"offset\":3903731,\"nonce\":36958957,\"last_updated_at\":1785276657405843,\"begin_nonce\":36958954},\"timestamp\":1785276657434,\"type\":\"update/order_book\"}"
        "raw": "{\"channel\":\"order_book:1\",\"last_updated_at\":1785276657511266,\"offset\":3903732,\"order_book\":{\"code\":0,\"asks\":[],\"bids\":[{\"price\":\"63895.4\",\"size\":\"0.00149\"},{\"price\":\"63895.3\",\"size\":\"0.00000\"}],\"offset\":3903732,\"nonce\":36958959,\"last_updated_at\":1785276657511266,\"begin_nonce\":36958957},\"timestamp\":1785276657533,\"type\":\"update/order_book\"}"
        "raw": "{\"channel\":\"order_book:1\",\"last_updated_at\":1785276657998009,\"offset\":3903735,\"order_book\":{\"code\":0,\"asks\":[{\"price\":\"63978.3\",\"size\":\"0.00000\"},{\"price\":\"63981.9\",\"size\":\"0.00163\"}],\"bids\":[{\"price\":\"63899.0\",\"size\":\"0.00149\"},{\"price\":\"63895.4\",\"size\":\"0.00000\"}],\"offset\":3903735,\"nonce\":36958965,\"last_updated_at\":1785276657998009,\"begin_nonce\":36958959},\"timestamp\":1785276658034,\"type\":\"update/order_book\"}"
        "raw": "{\"channel\":\"order_book:1\",\"last_updated_at\":1785276658155900,\"offset\":3903736,\"order_book\":{\"code\":0,\"asks\":[{\"price\":\"63963.8\",\"size\":\"0.00000\"},{\"price\":\"63964.7\",\"size\":\"3.12838\"}],\"bids\":[],\"offset\":3903736,\"nonce\":36958968,\"last_updated_at\":1785276658155900,\"begin_nonce\":36958965},\"timestamp\":1785276658184,\"type\":\"update/order_book\"}"
        "raw": "{\"channel\":\"order_book:1\",\"last_updated_at\":1785276658282958,\"offset\":3903739,\"order_book\":{\"code\":0,\"asks\":[{\"price\":\"63964.7\",\"size\":\"0.00000\"},{\"price\":\"63966.0\",\"size\":\"3.12839\"}],\"bids\":[{\"price\":\"63899.1\",\"size\":\"0.00149\"},{\"price\":\"63899.0\",\"size\":\"0.00000\"}],\"offset\":3903739,\"nonce\":36958972,\"last_updated_at\":1785276658282958,\"begin_nonce\":36958968},\"timestamp\":1785276658283,\"type\":\"update/order_book\"}"
        "raw": "{\"channel\":\"order_book:1\",\"last_updated_at\":1785276658775199,\"offset\":3903741,\"order_book\":{\"code\":0,\"asks\":[{\"price\":\"63966.0\",\"size\":\"0.00000\"},{\"price\":\"63966.1\",\"size\":\"3.12839\"}],\"bids\":[{\"price\":\"63897.1\",\"size\":\"0.00000\"},{\"price\":\"63897.0\",\"size\":\"3.11565\"}],\"offset\":3903741,\"nonce\":36958977,\"last_updated_at\":1785276658775199,\"begin_nonce\":36958972},\"timestamp\":1785276658784,\"type\":\"update/order_book\"}"
        "raw": "{\"channel\":\"order_book:1\",\"last_updated_at\":1785276658977851,\"offset\":3903748,\"order_book\":{\"code\":0,\"asks\":[{\"price\":\"63978.5\",\"size\":\"0.00163\"},{\"price\":\"63981.9\",\"size\":\"0.00000\"}],\"bids\":[{\"price\":\"63899.1\",\"size\":\"0.00000\"},{\"price\":\"63895.7\",\"size\":\"0.00149\"}],\"offset\":3903748,\"nonce\":36958986,\"last_updated_at\":1785276658977851,\"begin_nonce\":36958977},\"timestamp\":1785276658984,\"type\":\"update/order_book\"}"
        "raw": "{\"channel\":\"order_book:1\",\"last_updated_at\":1785276659054062,\"offset\":3903751,\"order_book\":{\"code\":0,\"asks\":[{\"price\":\"63964.1\",\"size\":\"3.12839\"},{\"price\":\"63966.1\",\"size\":\"0.00000\"}],\"bids\":[{\"price\":\"63897.1\",\"size\":\"3.11565\"},{\"price\":\"63897.0\",\"size\":\"0.00000\"},{\"price\":\"63895.8\",\"size\":\"0.00149\"},{\"price\":\"63895.7\",\"size\":\"0.00000\"}],\"offset\":3903751,\"nonce\":36958990,\"last_updated_at\":1785276659054062,\"begin_nonce\":36958986},\"timestamp\":1785276659084,\"type\":\"update/order_book\"}"
        "raw": "{\"channel\":\"order_book:1\",\"last_updated_at\":1785276659682811,\"offset\":3903752,\"order_book\":{\"code\":0,\"asks\":[],\"bids\":[{\"price\":\"63895.8\",\"size\":\"0.00000\"}],\"offset\":3903752,\"nonce\":36958994,\"last_updated_at\":1785276659682811,\"begin_nonce\":36958990},\"timestamp\":1785276659683,\"type\":\"update/order_book\"}"
        "raw": "{\"channel\":\"order_book:1\",\"last_updated_at\":1785276659687070,\"offset\":3903753,\"order_book\":{\"code\":0,\"asks\":[],\"bids\":[{\"price\":\"63895.9\",\"size\":\"0.00149\"}],\"offset\":3903753,\"nonce\":36958995,\"last_updated_at\":1785276659687070,\"begin_nonce\":36958994},\"timestamp\":1785276659734,\"type\":\"update/order_book\"}"
        "raw": "{\"channel\":\"order_book:1\",\"last_updated_at\":1785276659745795,\"offset\":3903754,\"order_book\":{\"code\":0,\"asks\":[],\"bids\":[{\"price\":\"63897.1\",\"size\":\"0.00000\"},{\"price\":\"63896.9\",\"size\":\"3.11565\"}],\"offset\":3903754,\"nonce\":36958997,\"last_updated_at\":1785276659745795,\"begin_nonce\":36958995},\"timestamp\":1785276659783,\"type\":\"update/order_book\"}"
        "raw": "{\"channel\":\"order_book:1\",\"last_updated_at\":1785276660017856,\"offset\":3903755,\"order_book\":{\"code\":0,\"asks\":[{\"price\":\"63963.8\",\"size\":\"3.12839\"},{\"price\":\"63964.1\",\"size\":\"0.00000\"}],\"bids\":[{\"price\":\"63896.9\",\"size\":\"0.00000\"},{\"price\":\"63888.1\",\"size\":\"3.11565\"}],\"offset\":3903755,\"nonce\":36958999,\"last_updated_at\":1785276660017856,\"begin_nonce\":36958997},\"timestamp\":1785276660034,\"type\":\"update/order_book\"}"
        "raw": "{\"channel\":\"order_book:1\",\"last_updated_at\":1785276660099251,\"offset\":3903757,\"order_book\":{\"code\":0,\"asks\":[],\"bids\":[{\"price\":\"63896.0\",\"size\":\"0.00149\"},{\"price\":\"63895.9\",\"size\":\"0.00000\"}],\"offset\":3903757,\"nonce\":36959002,\"last_updated_at\":1785276660099251,\"begin_nonce\":36958999},\"timestamp\":1785276660133,\"type\":\"update/order_book\"}"
        "raw": "{\"channel\":\"order_book:1\",\"last_updated_at\":1785276660153799,\"offset\":3903758,\"order_book\":{\"code\":0,\"asks\":[{\"price\":\"63963.8\",\"size\":\"0.00000\"},{\"price\":\"63964.0\",\"size\":\"3.12839\"}],\"bids\":[{\"price\":\"63894.7\",\"size\":\"3.11565\"},{\"price\":\"63888.1\",\"size\":\"0.00000\"}],\"offset\":3903758,\"nonce\":36959003,\"last_updated_at\":1785276660153799,\"begin_nonce\":36959002},\"timestamp\":1785276660184,\"type\":\"update/order_book\"}"
        "raw": "{\"channel\":\"order_book:1\",\"last_updated_at\":1785276660502076,\"offset\":3903760,\"order_book\":{\"code\":0,\"asks\":[],\"bids\":[{\"price\":\"63896.1\",\"size\":\"0.00149\"},{\"price\":\"63896.0\",\"size\":\"0.00000\"}],\"offset\":3903760,\"nonce\":36959007,\"last_updated_at\":1785276660502076,\"begin_nonce\":36959003},\"timestamp\":1785276660533,\"type\":\"update/order_book\"}"
        "raw": "{\"channel\":\"order_book:1\",\"last_updated_at\":1785276660658037,\"offset\":3903761,\"order_book\":{\"code\":0,\"asks\":[{\"price\":\"63963.9\",\"size\":\"3.12839\"},{\"price\":\"63964.0\",\"size\":\"0.00000\"}],\"bids\":[],\"offset\":3903761,\"nonce\":36959010,\"last_updated_at\":1785276660658037,\"begin_nonce\":36959007},\"timestamp\":1785276660683,\"type\":\"update/order_book\"}"
        "raw": "{\"channel\":\"order_book:1\",\"last_updated_at\":1785276660870080,\"offset\":3903763,\"order_book\":{\"code\":0,\"asks\":[],\"bids\":[{\"price\":\"63896.2\",\"size\":\"0.00149\"},{\"price\":\"63896.1\",\"size\":\"0.00000\"}],\"offset\":3903763,\"nonce\":36959013,\"last_updated_at\":1785276660870080,\"begin_nonce\":36959010},\"timestamp\":1785276660884,\"type\":\"update/order_book\"}"
        "raw": "{\"channel\":\"order_book:1\",\"last_updated_at\":1785276661042469,\"offset\":3903764,\"order_book\":{\"code\":0,\"asks\":[],\"bids\":[{\"price\":\"63896.0\",\"size\":\"3.11565\"},{\"price\":\"63894.7\",\"size\":\"0.00000\"}],\"offset\":3903764,\"nonce\":36959015,\"last_updated_at\":1785276661042469,\"begin_nonce\":36959013},\"timestamp\":1785276661084,\"type\":\"update/order_book\"}"
        "raw": "{\"channel\":\"order_book:1\",\"last_updated_at\":1785276661167866,\"offset\":3903765,\"order_book\":{\"code\":0,\"asks\":[],\"bids\":[{\"price\":\"63896.0\",\"size\":\"0.00000\"},{\"price\":\"63891.0\",\"size\":\"3.11565\"}],\"offset\":3903765,\"nonce\":36959018,\"last_updated_at\":1785276661167866,\"begin_nonce\":36959015},\"timestamp\":1785276661184,\"type\":\"update/order_book\"}"
        "raw": "{\"channel\":\"order_book:1\",\"last_updated_at\":1785276661240925,\"offset\":3903766,\"order_book\":{\"code\":0,\"asks\":[],\"bids\":[{\"price\":\"63896.3\",\"size\":\"0.00149\"},{\"price\":\"63896.2\",\"size\":\"0.00000\"}],\"offset\":3903766,\"nonce\":36959019,\"last_updated_at\":1785276661240925,\"begin_nonce\":36959018},\"timestamp\":1785276661283,\"type\":\"update/order_book\"}"
        "raw": "{\"channel\":\"order_book:1\",\"last_updated_at\":1785276661542384,\"offset\":3903767,\"order_book\":{\"code\":0,\"asks\":[],\"bids\":[{\"price\":\"63891.9\",\"size\":\"3.11565\"},{\"price\":\"63891.0\",\"size\":\"0.00000\"}],\"offset\":3903767,\"nonce\":36959021,\"last_updated_at\":1785276661542384,\"begin_nonce\":36959019},\"timestamp\":1785276661584,\"type\":\"update/order_book\"}"
        "raw": "{\"channel\":\"order_book:1\",\"last_updated_at\":1785276661603843,\"offset\":3903769,\"order_book\":{\"code\":0,\"asks\":[],\"bids\":[{\"price\":\"63896.4\",\"size\":\"0.00149\"},{\"price\":\"63896.3\",\"size\":\"0.00000\"}],\"offset\":3903769,\"nonce\":36959023,\"last_updated_at\":1785276661603843,\"begin_nonce\":36959021},\"timestamp\":1785276661634,\"type\":\"update/order_book\"}"
        "raw": "{\"channel\":\"order_book:1\",\"last_updated_at\":1785276661827786,\"offset\":3903773,\"order_book\":{\"code\":0,\"asks\":[{\"price\":\"63963.9\",\"size\":\"0.00000\"},{\"price\":\"63969.9\",\"size\":\"3.12820\"},{\"price\":\"63978.5\",\"size\":\"0.00000\"},{\"price\":\"63983.7\",\"size\":\"0.00163\"}],\"bids\":[{\"price\":\"63901.6\",\"size\":\"0.00149\"},{\"price\":\"63896.4\",\"size\":\"0.00000\"},{\"price\":\"63891.9\",\"size\":\"0.00000\"},{\"price\":\"63891.7\",\"size\":\"3.11547\"}],\"offset\":3903773,\"nonce\":36959032,\"last_updated_at\":1785276661827786,\"begin_nonce\":36959023},\"timestamp\":1785276661833,\"type\":\"update/order_book\"}"
        "raw": "{\"channel\":\"order_book:1\",\"last_updated_at\":1785276661911691,\"offset\":3903774,\"order_book\":{\"code\":0,\"asks\":[],\"bids\":[{\"price\":\"63899.3\",\"size\":\"3.11547\"},{\"price\":\"63891.7\",\"size\":\"0.00000\"}],\"offset\":3903774,\"nonce\":36959037,\"last_updated_at\":1785276661911691,\"begin_nonce\":36959032},\"timestamp\":1785276661934,\"type\":\"update/order_book\"}"
        "raw": "{\"channel\":\"order_book:1\",\"last_updated_at\":1785276661978186,\"offset\":3903775,\"order_book\":{\"code\":0,\"asks\":[],\"bids\":[{\"price\":\"63920.0\",\"size\":\"0.00000\"}],\"offset\":3903775,\"nonce\":36959038,\"last_updated_at\":1785276661978186,\"begin_nonce\":36959037},\"timestamp\":1785276661984,\"type\":\"update/order_book\"}"
        "raw": "{\"channel\":\"order_book:1\",\"last_updated_at\":1785276662028606,\"offset\":3903777,\"order_book\":{\"code\":0,\"asks\":[{\"price\":\"63969.9\",\"size\":\"0.00000\"},{\"price\":\"63975.2\",\"size\":\"3.12820\"},{\"price\":\"64003.2\",\"size\":\"0.00000\"},{\"price\":\"64147.2\",\"size\":\"15.63184\"}],\"bids\":[],\"offset\":3903777,\"nonce\":36959040,\"last_updated_at\":1785276662028606,\"begin_nonce\":36959038},\"timestamp\":1785276662034,\"type\":\"update/order_book\"}"
        "raw": "{\"channel\":\"order_book:1\",\"last_updated_at\":1785276662046411,\"offset\":3903778,\"order_book\":{\"code\":0,\"asks\":[],\"bids\":[{\"price\":\"63899.3\",\"size\":\"0.00000\"},{\"price\":\"63896.8\",\"size\":\"3.11547\"}],\"offset\":3903778,\"nonce\":36959043,\"last_updated_at\":1785276662046411,\"begin_nonce\":36959040},\"timestamp\":1785276662084,\"type\":\"update/order_book\"}"
        "raw": "{\"channel\":\"order_book:1\",\"last_updated_at\":1785276662131416,\"offset\":3903780,\"order_book\":{\"code\":0,\"asks\":[],\"bids\":[{\"price\":\"63901.7\",\"size\":\"0.00149\"},{\"price\":\"63901.6\",\"size\":\"0.00000\"},{\"price\":\"63886.4\",\"size\":\"0.00000\"}],\"offset\":3903780,\"nonce\":36959045,\"last_updated_at\":1785276662131416,\"begin_nonce\":36959043},\"timestamp\":1785276662134,\"type\":\"update/order_book\"}"
        "raw": "{\"channel\":\"order_book:1\",\"last_updated_at\":1785276662272363,\"offset\":3903784,\"order_book\":{\"code\":0,\"asks\":[{\"price\":\"63975.2\",\"size\":\"0.00000\"},{\"price\":\"63979.3\",\"size\":\"3.12820\"},{\"price\":\"63983.6\",\"size\":\"0.00163\"},{\"price\":\"63983.7\",\"size\":\"0.00000\"}],\"bids\":[{\"price\":\"63901.7\",\"size\":\"0.00000\"},{\"price\":\"63901.6\",\"size\":\"0.00149\"},{\"price\":\"63896.8\",\"size\":\"0.00000\"},{\"price\":\"63895.4\",\"size\":\"3.11547\"}],\"offset\":3903784,\"nonce\":36959051,\"last_updated_at\":1785276662272363,\"begin_nonce\":36959045},\"timestamp\":1785276662284,\"type\":\"update/order_book\"}"
        "raw": "{\"channel\":\"order_book:1\",\"last_updated_at\":1785276662344549,\"offset\":3903785,\"order_book\":{\"code\":0,\"asks\":[{\"price\":\"63978.3\",\"size\":\"3.12820\"},{\"price\":\"63979.3\",\"size\":\"0.00000\"}],\"bids\":[{\"price\":\"63896.4\",\"size\":\"3.11547\"},{\"price\":\"63895.4\",\"size\":\"0.00000\"}],\"offset\":3903785,\"nonce\":36959055,\"last_updated_at\":1785276662344549,\"begin_nonce\":36959051},\"timestamp\":1785276662384,\"type\":\"update/order_book\"}"
        "raw": "{\"channel\":\"order_book:1\",\"last_updated_at\":1785276662398408,\"offset\":3903786,\"order_book\":{\"code\":0,\"asks\":[{\"price\":\"63980.0\",\"size\":\"0.00000\"}],\"bids\":[],\"offset\":3903786,\"nonce\":36959057,\"last_updated_at\":1785276662398408,\"begin_nonce\":36959055},\"timestamp\":1785276662434,\"type\":\"update/order_book\"}"
