        "raw": "{\"channel\":\"order_book:1\",\"last_updated_at\":1785276549132996,\"offset\":3902775,\"order_book\":{\"code\":0,\"asks\":[{\"price\":\"64022.8\",\"size\":\"3.12552\"},{\"price\":\"64022.9\",\"size\":\"0.00000\"}],\"bids\":[{\"price\":\"63955.8\",\"size\":\"3.11277\"},{\"price\":\"63955.7\",\"size\":\"0.00000\"}],\"offset\":3902775,\"nonce\":36956922,\"last_updated_at\":1785276549132996,\"begin_nonce\":36956919},\"timestamp\":1785276549133,\"type\":\"update/order_book\"}"
        "raw": "{\"channel\":\"order_book:1\",\"last_updated_at\":1785276549971382,\"offset\":3902776,\"order_book\":{\"code\":0,\"asks\":[],\"bids\":[{\"price\":\"63955.8\",\"size\":\"0.00000\"},{\"price\":\"63955.7\",\"size\":\"3.11277\"}],\"offset\":3902776,\"nonce\":36956926,\"last_updated_at\":1785276549971382,\"begin_nonce\":36956922},\"timestamp\":1785276549984,\"type\":\"update/order_book\"}"
        "raw": "{\"channel\":\"order_book:1\",\"last_updated_at\":1785276550125986,\"offset\":3902777,\"order_book\":{\"code\":0,\"asks\":[],\"bids\":[{\"price\":\"62966.5\",\"size\":\"0.00000\"}],\"offset\":3902777,\"nonce\":36956928,\"last_updated_at\":1785276550125986,\"begin_nonce\":36956926},\"timestamp\":1785276550134,\"type\":\"update/order_book\"}"
        "raw": "{\"channel\":\"order_book:1\",\"last_updated_at\":1785276550507631,\"offset\":3902778,\"order_book\":{\"code\":0,\"asks\":[{\"price\":\"64054.0\",\"size\":\"0.00032\"}],\"bids\":[],\"offset\":3902778,\"nonce\":36956930,\"last_updated_at\":1785276550507631,\"begin_nonce\":36956928},\"timestamp\":1785276550534,\"type\":\"update/order_book\"}"
        "raw": "{\"channel\":\"order_book:1\",\"last_updated_at\":1785276550576776,\"offset\":3902779,\"order_book\":{\"code\":0,\"asks\":[],\"bids\":[{\"price\":\"63955.8\",\"size\":\"3.11277\"},{\"price\":\"63955.7\",\"size\":\"0.00000\"}],\"offset\":3902779,\"nonce\":36956931,\"last_updated_at\":1785276550576776,\"begin_nonce\":36956930},\"timestamp\":1785276550584,\"type\":\"update/order_book\"}"
        "raw": "{\"channel\":\"order_book:1\",\"last_updated_at\":1785276550637129,\"offset\":3902780,\"order_book\":{\"code\":0,\"asks\":[{\"price\":\"64054.0\",\"size\":\"0.00064\"}],\"bids\":[],\"offset\":3902780,\"nonce\":36956932,\"last_updated_at\":1785276550637129,\"begin_nonce\":36956931},\"timestamp\":1785276550683,\"type\":\"update/order_book\"}"
        "raw": "{\"channel\":\"order_book:1\",\"last_updated_at\":1785276550798552,\"offset\":3902781,\"order_book\":{\"code\":0,\"asks\":[{\"price\":\"64020.0\",\"size\":\"0.00096\"}],\"bids\":[],\"offset\":3902781,\"nonce\":36956934,\"last_updated_at\":1785276550798552,\"begin_nonce\":36956932},\"timestamp\":1785276550834,\"type\":\"update/order_book\"}"
        "raw": "{\"channel\":\"order_book:1\",\"last_updated_at\":1785276551146598,\"offset\":3902782,\"order_book\":{\"code\":0,\"asks\":[{\"price\":\"64022.8\",\"size\":\"0.00000\"},{\"price\":\"64022.9\",\"size\":\"3.12552\"}],\"bids\":[{\"price\":\"63955.8\",\"size\":\"0.00000\"},{\"price\":\"63955.7\",\"size\":\"3.11277\"}],\"offset\":3902782,\"nonce\":36956935,\"last_updated_at\":1785276551146598,\"begin_nonce\":36956934},\"timestamp\":1785276551185,\"type\":\"update/order_book\"}"
        "raw": "{\"channel\":\"order_book:1\",\"last_updated_at\":1785276551333004,\"offset\":3902783,\"order_book\":{\"code\":0,\"asks\":[{\"price\":\"64054.0\",\"size\":\"0.00096\"}],\"bids\":[],\"offset\":3902783,\"nonce\":36956939,\"last_updated_at\":1785276551333004,\"begin_nonce\":36956935},\"timestamp\":1785276551333,\"type\":\"update/order_book\"}"
        "raw": "{\"channel\":\"order_book:1\",\"last_updated_at\":1785276551701050,\"offset\":3902784,\"order_book\":{\"code\":0,\"asks\":[{\"price\":\"64022.7\",\"size\":\"3.12552\"},{\"price\":\"64022.9\",\"size\":\"0.00000\"}],\"bids\":[{\"price\":\"63955.9\",\"size\":\"3.11277\"},{\"price\":\"63955.7\",\"size\":\"0.00000\"}],\"offset\":3902784,\"nonce\":36956943,\"last_updated_at\":1785276551701050,\"begin_nonce\":36956939},\"timestamp\":1785276551734,\"type\":\"update/order_book\"}"
        "raw": "{\"channel\":\"order_book:1\",\"last_updated_at\":1785276552229116,\"offset\":3902786,\"order_book\":{\"code\":0,\"asks\":[{\"price\":\"64022.7\",\"size\":\"0.00000\"},{\"price\":\"64022.9\",\"size\":\"3.12552\"}],\"bids\":[{\"price\":\"63955.9\",\"size\":\"0.00000\"},{\"price\":\"63955.6\",\"size\":\"3.11277\"}],\"offset\":3902786,\"nonce\":36956946,\"last_updated_at\":1785276552229116,\"begin_nonce\":36956943},\"timestamp\":1785276552234,\"type\":\"update/order_book\"}"
        "raw": "{\"channel\":\"order_book:1\",\"last_updated_at\":1785276552758007,\"offset\":3902787,\"order_book\":{\"code\":0,\"asks\":[{\"price\":\"64022.8\",\"size\":\"3.12552\"},{\"price\":\"64022.9\",\"size\":\"0.00000\"}],\"bids\":[{\"price\":\"63955.8\",\"size\":\"3.11277\"},{\"price\":\"63955.6\",\"size\":\"0.00000\"}],\"offset\":3902787,\"nonce\":36956949,\"last_updated_at\":1785276552758007,\"begin_nonce\":36956946},\"timestamp\":1785276552783,\"type\":\"update/order_book\"}"
        "raw": "{\"channel\":\"order_book:1\",\"last_updated_at\":1785276553408480,\"offset\":3902789,\"order_book\":{\"code\":0,\"asks\":[{\"price\":\"64022.7\",\"size\":\"3.12552\"},{\"price\":\"64022.8\",\"size\":\"0.00000\"}],\"bids\":[{\"price\":\"63955.9\",\"size\":\"3.11277\"},{\"price\":\"63955.8\",\"size\":\"0.00000\"}],\"offset\":3902789,\"nonce\":36956953,\"last_updated_at\":1785276553408480,\"begin_nonce\":36956949},\"timestamp\":1785276553433,\"type\":\"update/order_book\"}"
        "raw": "{\"channel\":\"order_book:1\",\"last_updated_at\":1785276553753165,\"offset\":3902790,\"order_book\":{\"code\":0,\"asks\":[{\"price\":\"64022.7\",\"size\":\"0.00000\"},{\"price\":\"64022.8\",\"size\":\"3.12554\"}],\"bids\":[{\"price\":\"63955.9\",\"size\":\"0.00000\"},{\"price\":\"63955.0\",\"size\":\"3.11279\"}],\"offset\":3902790,\"nonce\":36956956,\"last_updated_at\":1785276553753165,\"begin_nonce\":36956953},\"timestamp\":1785276553783,\"type\":\"update/order_book\"}"
        "raw": "{\"channel\":\"order_book:1\",\"last_updated_at\":1785276553885783,\"offset\":3902791,\"order_book\":{\"code\":0,\"asks\":[{\"price\":\"64021.7\",\"size\":\"3.12559\"},{\"price\":\"64022.8\",\"size\":\"0.00000\"}],\"bids\":[{\"price\":\"63955.0\",\"size\":\"0.00000\"},{\"price\":\"63953.3\",\"size\":\"3.11284\"}],\"offset\":3902791,\"nonce\":36956957,\"last_updated_at\":1785276553885783,\"begin_nonce\":36956956},\"timestamp\":1785276553933,\"type\":\"update/order_book\"}"
        "raw": "{\"channel\":\"order_book:1\",\"last_updated_at\":1785276554389959,\"offset\":3902792,\"order_book\":{\"code\":0,\"asks\":[{\"price\":\"64021.3\",\"size\":\"3.12559\"},{\"price\":\"64021.7\",\"size\":\"0.00000\"}],\"bids\":[{\"price\":\"63953.7\",\"size\":\"3.11284\"},{\"price\":\"63953.3\",\"size\":\"0.00000\"}],\"offset\":3902792,\"nonce\":36956962,\"last_updated_at\":1785276554389959,\"begin_nonce\":36956957},\"timestamp\":1785276554433,\"type\":\"update/order_book\"}"
        "raw": "{\"channel\":\"order_book:1\",\"last_updated_at\":1785276554918783,\"offset\":3902793,\"order_book\":{\"code\":0,\"asks\":[{\"price\":\"64021.3\",\"size\":\"0.00000\"},{\"price\":\"64021.4\",\"size\":\"3.12559\"}],\"bids\":[{\"price\":\"63953.7\",\"size\":\"0.00000\"},{\"price\":\"63953.6\",\"size\":\"3.11284\"}],\"offset\":3902793,\"nonce\":36956966,\"last_updated_at\":1785276554918783,\"begin_nonce\":36956962},\"timestamp\":1785276554934,\"type\":\"update/order_book\"}"
        "raw": "{\"channel\":\"order_book:1\",\"last_updated_at\":1785276555420860,\"offset\":3902794,\"order_book\":{\"code\":0,\"asks\":[{\"price\":\"64020.6\",\"size\":\"3.12566\"},{\"price\":\"64021.4\",\"size\":\"0.00000\"}],\"bids\":[{\"price\":\"63953.6\",\"size\":\"0.00000\"},{\"price\":\"63951.0\",\"size\":\"3.11291\"}],\"offset\":3902794,\"nonce\":36956976,\"last_updated_at\":1785276555420860,\"begin_nonce\":36956966},\"timestamp\":1785276555433,\"type\":\"update/order_book\"}"
        "raw": "{\"channel\":\"order_book:1\",\"last_updated_at\":1785276555481785,\"offset\":3902795,\"order_book\":{\"code\":0,\"asks\":[],\"bids\":[{\"price\":\"63916.8\",\"size\":\"0.00000\"},{\"price\":\"63772.8\",\"size\":\"15.60567\"}],\"offset\":3902795,\"nonce\":36956983,\"last_updated_at\":1785276555481785,\"begin_nonce\":36956976},\"timestamp\":1785276555485,\"type\":\"update/order_book\"}"
        "raw": "{\"channel\":\"order_book:1\",\"last_updated_at\":1785276555727385,\"offset\":3902806,\"order_book\":{\"code\":0,\"asks\":[{\"price\":\"64013.8\",\"size\":\"3.12596\"},{\"price\":\"64020.6\",\"size\":\"0.00000\"}],\"bids\":[{\"price\":\"63951.0\",\"size\":\"0.00000\"},{\"price\":\"63942.2\",\"size\":\"3.11322\"},{\"price\":\"63907.2\",\"size\":\"14.09190\"},{\"price\":\"63897.6\",\"size\":\"14.09190\"},{\"price\":\"63888.0\",\"size\":\"14.24219\"},{\"price\":\"63878.4\",\"size\":\"14.24219\"},{\"price\":\"63868.8\",\"size\":\"14.09190\"},{\"price\":\"63859.2\",\"size\":\"14.24219\"},{\"price\":\"63849.6\",\"size\":\"14.24219\"},{\"price\":\"63840.0\",\"size\":\"14.24311\"},{\"price\":\"63830.4\",\"size\":\"14.24219\"},{\"price\":\"63820.8\",\"size\":\"14.24219\"},{\"price\":\"63811.2\",\"size\":\"14.24219\"},{\"price\":\"63801.6\",\"size\":\"14.24219\"},{\"price\":\"63792.0\",\"size\":\"14.24219\"},{\"price\":\"63782.4\",\"size\":\"14.24219\"},{\"price\":\"63772.8\",\"size\":\"14.24219\"}],\"offset\":3902806,\"nonce\":36957017,\"last_updated_at\":1785276555727385,\"begin_nonce\":36956983},\"timestamp\":1785276555736,\"type\":\"update/order_book\"}"
        "raw": "{\"channel\":\"order_book:1\",\"last_updated_at\":1785276555781568,\"offset\":3902810,\"order_book\":{\"code\":0,\"asks\":[],\"bids\":[{\"price\":\"63907.2\",\"size\":\"14.24219\"},{\"price\":\"63897.6\",\"size\":\"14.24219\"},{\"price\":\"63868.8\",\"size\":\"14.24219\"},{\"price\":\"63859.2\",\"size\":\"12.91816\"},{\"price\":\"63849.6\",\"size\":\"12.91816\"},{\"price\":\"63840.0\",\"size\":\"12.91908\"},{\"price\":\"63830.4\",\"size\":\"12.91816\"},{\"price\":\"63820.8\",\"size\":\"12.91816\"},{\"price\":\"63811.2\",\"size\":\"12.91816\"},{\"price\":\"63801.6\",\"size\":\"12.91816\"},{\"price\":\"63792.0\",\"size\":\"12.91816\"},{\"price\":\"63782.4\",\"size\":\"12.91816\"},{\"price\":\"63772.8\",\"size\":\"12.91816\"}],\"offset\":3902810,\"nonce\":36957023,\"last_updated_at\":1785276555781568,\"begin_nonce\":36957017},\"timestamp\":1785276555784,\"type\":\"update/order_book\"}"
        "raw": "{\"channel\":\"order_book:1\",\"last_updated_at\":1785276555811370,\"offset\":3902817,\"order_book\":{\"code\":0,\"asks\":[],\"bids\":[{\"price\":\"63907.2\",\"size\":\"13.05442\"},{\"price\":\"63897.6\",\"size\":\"13.05442\"},{\"price\":\"63888.0\",\"size\":\"13.05442\"},{\"price\":\"63878.4\",\"size\":\"13.05442\"},{\"price\":\"63868.8\",\"size\":\"13.05442\"},{\"price\":\"63859.2\",\"size\":\"13.05442\"},{\"price\":\"63849.6\",\"size\":\"13.05442\"},{\"price\":\"63840.0\",\"size\":\"13.05534\"},{\"price\":\"63830.4\",\"size\":\"13.05442\"},{\"price\":\"63820.8\",\"size\":\"13.05442\"},{\"price\":\"63811.2\",\"size\":\"13.05442\"},{\"price\":\"63801.6\",\"size\":\"13.05442\"},{\"price\":\"63792.0\",\"size\":\"13.05442\"},{\"price\":\"63782.4\",\"size\":\"13.05442\"},{\"price\":\"63772.8\",\"size\":\"13.05442\"}],\"offset\":3902817,\"nonce\":36957039,\"last_updated_at\":1785276555811370,\"begin_nonce\":36957023},\"timestamp\":1785276555838,\"type\":\"update/order_book\"}"
        "raw": "{\"channel\":\"order_book:1\",\"last_updated_at\":1785276555883824,\"offset\":3902820,\"order_book\":{\"code\":0,\"asks\":[{\"price\":\"64013.8\",\"size\":\"0.00000\"},{\"price\":\"64021.7\",\"size\":\"3.12615\"}],\"bids\":[{\"price\":\"63942.2\",\"size\":\"0.00000\"},{\"price\":\"63936.6\",\"size\":\"2.63609\"},{\"price\":\"63931.8\",\"size\":\"5.27218\"},{\"price\":\"63931.2\",\"size\":\"0.00000\"}],\"offset\":3902820,\"nonce\":36957046,\"last_updated_at\":1785276555883824,\"begin_nonce\":36957039},\"timestamp\":1785276555898,\"type\":\"update/order_book\"}"
        "raw": "{\"channel\":\"order_book:1\",\"last_updated_at\":1785276555940894,\"offset\":3902821,\"order_book\":{\"code\":0,\"asks\":[{\"price\":\"64026.6\",\"size\":\"6.25229\"},{\"price\":\"64033.8\",\"size\":\"0.00000\"}],\"bids\":[{\"price\":\"63927.0\",\"size\":\"7.90826\"},{\"price\":\"63926.4\",\"size\":\"0.00000\"},{\"price\":\"63888.0\",\"size\":\"13.21994\"},{\"price\":\"63859.2\",\"size\":\"13.21994\"},{\"price\":\"63830.4\",\"size\":\"13.21994\"},{\"price\":\"63801.6\",\"size\":\"13.21994\"},{\"price\":\"63772.8\",\"size\":\"13.21994\"}],\"offset\":3902821,\"nonce\":36957047,\"last_updated_at\":1785276555940894,\"begin_nonce\":36957046},\"timestamp\":1785276555984,\"type\":\"update/order_book\"}"
        "raw": "{\"channel\":\"order_book:1\",\"last_updated_at\":1785276556023910,\"offset\":3902829,\"order_book\":{\"code\":0,\"asks\":[{\"price\":\"64016.9\",\"size\":\"0.00163\"},{\"price\":\"64031.4\",\"size\":\"9.37843\"},{\"price\":\"64036.2\",\"size\":\"12.50457\"},{\"price\":\"64038.6\",\"size\":\"0.00000\"},{\"price\":\"64043.4\",\"size\":\"0.00000\"}],\"bids\":[{\"price\":\"63932.2\",\"size\":\"0.00149\"},{\"price\":\"63922.2\",\"size\":\"10.54435\"},{\"price\":\"63921.6\",\"size\":\"0.00000\"},{\"price\":\"63907.2\",\"size\":\"13.36701\"},{\"price\":\"63897.6\",\"size\":\"13.21994\"},{\"price\":\"63878.4\",\"size\":\"13.36701\"},{\"price\":\"63868.8\",\"size\":\"13.36701\"},{\"price\":\"63859.2\",\"size\":\"13.36701\"},{\"price\":\"63849.6\",\"size\":\"13.36701\"},{\"price\":\"63840.0\",\"size\":\"13.36793\"},{\"price\":\"63830.4\",\"size\":\"13.36701\"},{\"price\":\"63820.8\",\"size\":\"13.36701\"},{\"price\":\"63811.2\",\"size\":\"13.36701\"},{\"price\":\"63801.6\",\"size\":\"13.36701\"},{\"price\":\"63792.0\",\"size\":\"13.36701\"},{\"price\":\"63782.4\",\"size\":\"13.36701\"},{\"price\":\"63772.8\",\"size\":\"13.36701\"}],\"offset\":3902829,\"nonce\":36957056,\"last_updated_at\":1785276556023910,\"begin_nonce\":36957047},\"timestamp\":1785276556034,\"type\":\"update/order_book\"}"
        "raw": "{\"channel\":\"order_book:1\",\"last_updated_at\":1785276556129873,\"offset\":3902837,\"order_book\":{\"code\":0,\"asks\":[],\"bids\":[{\"price\":\"63897.6\",\"size\":\"13.54263\"},{\"price\":\"63888.0\",\"size\":\"13.36701\"},{\"price\":\"63878.4\",\"size\":\"13.54263\"},{\"price\":\"63859.2\",\"size\":\"13.54263\"},{\"price\":\"63849.6\",\"size\":\"13.54263\"},{\"price\":\"63840.0\",\"size\":\"13.54355\"},{\"price\":\"63830.4\",\"size\":\"13.54263\"},{\"price\":\"63820.8\",\"size\":\"13.54263\"},{\"price\":\"63811.2\",\"size\":\"13.54263\"},{\"price\":\"63801.6\",\"size\":\"13.54263\"},{\"price\":\"63792.0\",\"size\":\"13.54263\"},{\"price\":\"63782.4\",\"size\":\"13.54263\"},{\"price\":\"63772.8\",\"size\":\"13.54263\"}],\"offset\":3902837,\"nonce\":36957070,\"last_updated_at\":1785276556129873,\"begin_nonce\":36957056},\"timestamp\":1785276556134,\"type\":\"update/order_book\"}"
        "raw": "{\"channel\":\"order_book:1\",\"last_updated_at\":1785276556142750,\"offset\":3902839,\"order_book\":{\"code\":0,\"asks\":[],\"bids\":[{\"price\":\"63907.2\",\"size\":\"13.54263\"},{\"price\":\"63888.0\",\"size\":\"13.54263\"},{\"price\":\"63868.8\",\"size\":\"13.54263\"}],\"offset\":3902839,\"nonce\":36957075,\"last_updated_at\":1785276556142750,\"begin_nonce\":36957070},\"timestamp\":1785276556184,\"type\":\"update/order_book\"}"
        "raw": "{\"channel\":\"order_book:1\",\"last_updated_at\":1785276556223985,\"offset\":3902848,\"order_book\":{\"code\":0,\"asks\":[{\"price\":\"64016.9\",\"size\":\"0.00000\"},{\"price\":\"64020.0\",\"size\":\"0.00259\"}],\"bids\":[{\"price\":\"63897.6\",\"size\":\"13.70853\"},{\"price\":\"63888.0\",\"size\":\"13.70853\"},{\"price\":\"63878.4\",\"size\":\"13.70853\"},{\"price\":\"63868.8\",\"size\":\"13.70853\"},{\"price\":\"63859.2\",\"size\":\"13.70853\"},{\"price\":\"63849.6\",\"size\":\"13.70853\"},{\"price\":\"63840.0\",\"size\":\"13.70945\"},{\"price\":\"63820.8\",\"size\":\"13.70853\"},{\"price\":\"63811.2\",\"size\":\"13.70853\"},{\"price\":\"63801.6\",\"size\":\"13.70853\"},{\"price\":\"63792.0\",\"size\":\"13.70853\"},{\"price\":\"63782.4\",\"size\":\"13.70853\"},{\"price\":\"63772.8\",\"size\":\"13.70853\"}],\"offset\":3902848,\"nonce\":36957090,\"last_updated_at\":1785276556223985,\"begin_nonce\":36957075},\"timestamp\":1785276556234,\"type\":\"update/order_book\"}"
        "raw": "{\"channel\":\"order_book:1\",\"last_updated_at\":1785276556287731,\"offset\":3902854,\"order_book\":{\"code\":0,\"asks\":[],\"bids\":[{\"price\":\"63907.2\",\"size\":\"0.00000\"},{\"price\":\"63830.4\",\"size\":\"13.70853\"},{\"price\":\"63820.8\",\"size\":\"13.87078\"},{\"price\":\"63801.6\",\"size\":\"13.87078\"},{\"price\":\"63792.0\",\"size\":\"13.87078\"},{\"price\":\"63772.8\",\"size\":\"13.87078\"},{\"price\":\"63763.2\",\"size\":\"13.87078\"}],\"offset\":3902854,\"nonce\":36957099,\"last_updated_at\":1785276556287731,\"begin_nonce\":36957090},\"timestamp\":1785276556292,\"type\":\"update/order_book\"}"
        "raw": "{\"channel\":\"order_book:1\",\"last_updated_at\":1785276556325871,\"offset\":3902865,\"order_book\":{\"code\":0,\"asks\":[],\"bids\":[{\"price\":\"63897.6\",\"size\":\"13.87078\"},{\"price\":\"63888.0\",\"size\":\"14.10222\"},{\"price\":\"63878.4\",\"size\":\"14.10222\"},{\"price\":\"63868.8\",\"size\":\"13.87078\"},{\"price\":\"63859.2\",\"size\":\"14.10222\"},{\"price\":\"63849.6\",\"size\":\"14.10222\"},{\"price\":\"63840.0\",\"size\":\"14.10314\"},{\"price\":\"63830.4\",\"size\":\"14.10222\"},{\"price\":\"63820.8\",\"size\":\"14.10222\"},{\"price\":\"63811.2\",\"size\":\"14.10222\"},{\"price\":\"63801.6\",\"size\":\"14.10222\"},{\"price\":\"63792.0\",\"size\":\"14.10222\"},{\"price\":\"63782.4\",\"size\":\"14.10222\"},{\"price\":\"63772.8\",\"size\":\"14.10222\"},{\"price\":\"63763.2\",\"size\":\"14.10222\"}],\"offset\":3902865,\"nonce\":36957111,\"last_updated_at\":1785276556325871,\"begin_nonce\":36957099},\"timestamp\":1785276556334,\"type\":\"update/order_book\"}"
        "raw": "{\"channel\":\"order_book:1\",\"last_updated_at\":1785276556340128,\"offset\":3902867,\"order_book\":{\"code\":0,\"asks\":[],\"bids\":[{\"price\":\"63897.6\",\"size\":\"14.10222\"},{\"price\":\"63868.8\",\"size\":\"14.10222\"}],\"offset\":3902867,\"nonce\":36957117,\"last_updated_at\":1785276556340128,\"begin_nonce\":36957111},\"timestamp\":1785276556384,\"type\":\"update/order_book\"}"
        "raw": "{\"channel\":\"order_book:1\",\"last_updated_at\":1785276556528812,\"offset\":3902876,\"order_book\":{\"code\":0,\"asks\":[{\"price\":\"64021.7\",\"size\":\"0.00000\"},{\"price\":\"64022.5\",\"size\":\"3.12615\"}],\"bids\":[],\"offset\":3902876,\"nonce\":36957137,\"last_updated_at\":1785276556528812,\"begin_nonce\":36957134},\"timestamp\":1785276556534,\"type\":\"update/order_book\"}"
        "raw": "{\"channel\":\"order_book:1\",\"last_updated_at\":1785276556583609,\"offset\":3902878,\"order_book\":{\"code\":0,\"asks\":[{\"price\":\"64026.6\",\"size\":\"0.00000\"},{\"price\":\"64027.3\",\"size\":\"6.25229\"}],\"bids\":[{\"price\":\"63936.6\",\"size\":\"0.00000\"},{\"price\":\"63936.2\",\"size\":\"2.91458\"},{\"price\":\"63801.6\",\"size\":\"14.61328\"},{\"price\":\"63772.8\",\"size\":\"14.61328\"}],\"offset\":3902878,\"nonce\":36957141,\"last_updated_at\":1785276556583609,\"begin_nonce\":36957137},\"timestamp\":1785276556584,\"type\":\"update/order_book\"}"
        "raw": "{\"channel\":\"order_book:1\",\"last_updated_at\":1785276556633052,\"offset\":3902892,\"order_book\":{\"code\":0,\"asks\":[{\"price\":\"64017.0\",\"size\":\"0.00000\"},{\"price\":\"64020.0\",\"size\":\"0.00259\"},{\"price\":\"64031.4\",\"size\":\"0.00000\"},{\"price\":\"64032.1\",\"size\":\"9.37843\"},{\"price\":\"64036.2\",\"size\":\"0.00000\"},{\"price\":\"64036.9\",\"size\":\"12.50457\"}],\"bids\":[{\"price\":\"63931.8\",\"size\":\"0.00000\"},{\"price\":\"63931.4\",\"size\":\"5.82915\"},{\"price\":\"63927.0\",\"size\":\"0.00000\"},{\"price\":\"63926.6\",\"size\":\"8.74373\"},{\"price\":\"63922.2\",\"size\":\"0.00000\"},{\"price\":\"63921.8\",\"size\":\"11.65830\"},{\"price\":\"63897.6\",\"size\":\"14.83477\"},{\"price\":\"63888.0\",\"size\":\"14.61328\"},{\"price\":\"63878.4\",\"size\":\"14.83477\"},{\"price\":\"63868.8\",\"size\":\"14.83477\"},{\"price\":\"63859.2\",\"size\":\"14.83477\"},{\"price\":\"63849.6\",\"size\":\"14.83477\"},{\"price\":\"63840.0\",\"size\":\"14.83569\"},{\"price\":\"63830.4\",\"size\":\"14.83477\"},{\"price\":\"63820.8\",\"size\":\"14.83477\"},{\"price\":\"63811.2\",\"size\":\"15.03771\"},{\"price\":\"63801.6\",\"size\":\"14.83477\"},{\"price\":\"63792.0\",\"size\":\"15.03771\"},{\"price\":\"63782.4\",\"size\":\"15.03771\"},{\"price\":\"63772.8\",\"size\":\"14.83477\"},{\"price\":\"63763.2\",\"size\":\"15.03771\"}],\"offset\":3902892,\"nonce\":36957158,\"last_updated_at\":1785276556633052,\"begin_nonce\":36957141},\"timestamp\":1785276556634,\"type\":\"update/order_book\"}"
        "raw": "{\"channel\":\"order_book:1\",\"last_updated_at\":1785276556681193,\"offset\":3902895,\"order_book\":{\"code\":0,\"asks\":[],\"bids\":[{\"price\":\"63888.0\",\"size\":\"14.83477\"},{\"price\":\"63868.8\",\"size\":\"15.03771\"},{\"price\":\"63840.0\",\"size\":\"15.03863\"},{\"price\":\"63820.8\",\"size\":\"15.03771\"}],\"offset\":3902895,\"nonce\":36957163,\"last_updated_at\":1785276556681193,\"begin_nonce\":36957158},\"timestamp\":1785276556684,\"type\":\"update/order_book\"}"
        "raw": "{\"channel\":\"order_book:1\",\"last_updated_at\":1785276556731908,\"offset\":3902906,\"order_book\":{\"code\":0,\"asks\":[],\"bids\":[{\"price\":\"63960.0\",\"size\":\"0.00094\"},{\"price\":\"63897.6\",\"size\":\"15.22075\"},{\"price\":\"63888.0\",\"size\":\"15.03771\"},{\"price\":\"63878.4\",\"size\":\"15.03771\"},{\"price\":\"63868.8\",\"size\":\"15.22075\"},{\"price\":\"63859.2\",\"size\":\"15.22075\"},{\"price\":\"63849.6\",\"size\":\"15.03771\"},{\"price\":\"63840.0\",\"size\":\"15.22167\"},{\"price\":\"63830.4\",\"size\":\"15.22075\"},{\"price\":\"63811.2\",\"size\":\"15.22075\"},{\"price\":\"63801.6\",\"size\":\"15.22075\"},{\"price\":\"63782.4\",\"size\":\"15.22075\"},{\"price\":\"63772.8\",\"size\":\"15.22075\"}],\"offset\":3902906,\"nonce\":36957179,\"last_updated_at\":1785276556731908,\"begin_nonce\":36957163},\"timestamp\":1785276556734,\"type\":\"update/order_book\"}"
        "raw": "{\"channel\":\"order_book:1\",\"last_updated_at\":1785276556780095,\"offset\":3902909,\"order_book\":{\"code\":0,\"asks\":[],\"bids\":[{\"price\":\"63888.0\",\"size\":\"15.22075\"},{\"price\":\"63878.4\",\"size\":\"15.22075\"},{\"price\":\"63849.6\",\"size\":\"15.22075\"},{\"price\":\"63820.8\",\"size\":\"15.22075\"},{\"price\":\"63792.0\",\"size\":\"15.22075\"},{\"price\":\"63763.2\",\"size\":\"15.22075\"}],\"offset\":3902909,\"nonce\":36957184,\"last_updated_at\":1785276556780095,\"begin_nonce\":36957179},\"timestamp\":1785276556783,\"type\":\"update/order_book\"}"
        "raw": "{\"channel\":\"order_book:1\",\"last_updated_at\":1785276556831562,\"offset\":3902920,\"order_book\":{\"code\":0,\"asks\":[{\"price\":\"64020.0\",\"size\":\"0.00096\"},{\"price\":\"64022.4\",\"size\":\"3.12615\"},{\"price\":\"64022.5\",\"size\":\"0.00000\"}],\"bids\":[{\"price\":\"63931.4\",\"size\":\"0.00000\"},{\"price\":\"63925.2\",\"size\":\"6.21440\"},{\"price\":\"63897.6\",\"size\":\"15.52476\"},{\"price\":\"63888.0\",\"size\":\"15.52476\"},{\"price\":\"63868.8\",\"size\":\"15.52476\"},{\"price\":\"63859.2\",\"size\":\"15.52476\"},{\"price\":\"63840.0\",\"size\":\"15.52568\"},{\"price\":\"63830.4\",\"size\":\"15.52476\"},{\"price\":\"63820.8\",\"size\":\"15.52476\"},{\"price\":\"63811.2\",\"size\":\"15.52476\"},{\"price\":\"63801.6\",\"size\":\"15.52476\"},{\"price\":\"63792.0\",\"size\":\"15.52476\"},{\"price\":\"63782.4\",\"size\":\"15.52476\"},{\"price\":\"63772.8\",\"size\":\"15.52476\"},{\"price\":\"63763.2\",\"size\":\"15.52476\"}],\"offset\":3902920,\"nonce\":36957201,\"last_updated_at\":1785276556831562,\"begin_nonce\":36957184},\"timestamp\":1785276556833,\"type\":\"update/order_book\"}"
        "raw": "{\"channel\":\"order_book:1\",\"last_updated_at\":1785276556882458,\"offset\":3902924,\"order_book\":{\"code\":0,\"asks\":[{\"price\":\"64017.0\",\"size\":\"0.00163\"}],\"bids\":[{\"price\":\"63936.2\",\"size\":\"0.00000\"},{\"price\":\"63930.0\",\"size\":\"3.10720\"},{\"price\":\"63878.4\",\"size\":\"15.52476\"},{\"price\":\"63849.6\",\"size\":\"15.52476\"}],\"offset\":3902924,\"nonce\":36957205,\"last_updated_at\":1785276556882458,\"begin_nonce\":36957201},\"timestamp\":1785276556884,\"type\":\"update/order_book\"}"
        "raw": "{\"channel\":\"order_book:1\",\"last_updated_at\":1785276556932286,\"offset\":3902926,\"order_book\":{\"code\":0,\"asks\":[{\"price\":\"64027.2\",\"size\":\"6.25229\"},{\"price\":\"64027.3\",\"size\":\"0.00000\"},{\"price\":\"64036.8\",\"size\":\"12.50457\"},{\"price\":\"64036.9\",\"size\":\"0.00000\"}],\"bids\":[{\"price\":\"63926.6\",\"size\":\"0.00000\"},{\"price\":\"63920.4\",\"size\":\"9.32160\"}],\"offset\":3902926,\"nonce\":36957210,\"last_updated_at\":1785276556932286,\"begin_nonce\":36957205},\"timestamp\":1785276556933,\"type\":\"update/order_book\"}"
        "raw": "{\"channel\":\"order_book:1\",\"last_updated_at\":1785276556981849,\"offset\":3902928,\"order_book\":{\"code\":0,\"asks\":[{\"price\":\"64017.0\",\"size\":\"0.00000\"},{\"price\":\"64032.0\",\"size\":\"9.37843\"},{\"price\":\"64032.1\",\"size\":\"0.00000\"}],\"bids\":[{\"price\":\"63921.8\",\"size\":\"0.00000\"},{\"price\":\"63915.6\",\"size\":\"12.42880\"}],\"offset\":3902928,\"nonce\":36957213,\"last_updated_at\":1785276556981849,\"begin_nonce\":36957210},\"timestamp\":1785276556986,\"type\":\"update/order_book\"}"
        "raw": "{\"channel\":\"order_book:1\",\"last_updated_at\":1785276557001998,\"offset\":3902933,\"order_book\":{\"code\":0,\"asks\":[{\"price\":\"64020.0\",\"size\":\"0.00259\"}],\"bids\":[{\"price\":\"63932.2\",\"size\":\"0.00000\"},{\"price\":\"63929.4\",\"size\":\"0.00149\"}],\"offset\":3902933,\"nonce\":36957222,\"last_updated_at\":1785276557001998,\"begin_nonce\":36957213},\"timestamp\":1785276557033,\"type\":\"update/order_book\"}"
        "raw": "{\"channel\":\"order_book:1\",\"last_updated_at\":1785276557131386,\"offset\":3902939,\"order_book\":{\"code\":0,\"asks\":[{\"price\":\"64022.4\",\"size\":\"0.00000\"},{\"price\":\"64027.2\",\"size\":\"0.00000\"},{\"price\":\"64032.0\",\"size\":\"0.00000\"},{\"price\":\"64032.8\",\"size\":\"6.25229\"},{\"price\":\"64035.1\",\"size\":\"3.12615\"},{\"price\":\"64036.8\",\"size\":\"0.00000\"},{\"price\":\"64037.6\",\"size\":\"9.37843\"},{\"price\":\"64042.4\",\"size\":\"12.50457\"},{\"price\":\"64060.8\",\"size\":\"0.00000\"},{\"price\":\"64204.8\",\"size\":\"15.61784\"}],\"bids\":[{\"price\":\"63930.0\",\"size\":\"0.00000\"},{\"price\":\"63925.2\",\"size\":\"0.00000\"},{\"price\":\"63920.4\",\"size\":\"0.00000\"},{\"price\":\"63917.3\",\"size\":\"3.11340\"},{\"price\":\"63914.8\",\"size\":\"9.34019\"},{\"price\":\"63912.5\",\"size\":\"6.22680\"},{\"price\":\"63897.6\",\"size\":\"0.00000\"},{\"price\":\"63753.6\",\"size\":\"15.61084\"}],\"offset\":3902939,\"nonce\":36957236,\"last_updated_at\":1785276557131386,\"begin_nonce\":36957222},\"timestamp\":1785276557134,\"type\":\"update/order_book\"}"
        "raw": "{\"channel\":\"order_book:1\",\"last_updated_at\":1785276557181737,\"offset\":3902941,\"order_book\":{\"code\":0,\"asks\":[{\"price\":\"64020.0\",\"size\":\"0.00096\"}],\"bids\":[{\"price\":\"63915.6\",\"size\":\"0.00000\"},{\"price\":\"63910.0\",\"size\":\"12.45359\"}],\"offset\":3902941,\"nonce\":36957241,\"last_updated_at\":1785276557181737,\"begin_nonce\":36957236},\"timestamp\":1785276557183,\"type\":\"update/order_book\"}"
        "raw": "{\"channel\":\"order_book:1\",\"last_updated_at\":1785276557236042,\"offset\":3902943,\"order_book\":{\"code\":0,\"asks\":[{\"price\":\"64032.8\",\"size\":\"0.00000\"},{\"price\":\"64039.9\",\"size\":\"6.25229\"},{\"price\":\"64042.4\",\"size\":\"0.00000\"},{\"price\":\"64049.5\",\"size\":\"12.50457\"}],\"bids\":[{\"price\":\"63910.0\",\"size\":\"0.00000\"},{\"price\":\"63902.9\",\"size\":\"12.45359\"}],\"offset\":3902943,\"nonce\":36957247,\"last_updated_at\":1785276557236042,\"begin_nonce\":36957241},\"timestamp\":1785276557283,\"type\":\"update/order_book\"}"
        "raw": "{\"channel\":\"order_book:1\",\"last_updated_at\":1785276557313889,\"offset\":3902947,\"order_book\":{\"code\":0,\"asks\":[{\"price\":\"64035.1\",\"size\":\"0.00000\"},{\"price\":\"64037.6\",\"size\":\"0.00000\"},{\"price\":\"64038.5\",\"size\":\"3.12614\"},{\"price\":\"64044.7\",\"size\":\"9.37843\"}],\"bids\":[{\"price\":\"63917.3\",\"size\":\"0.00000\"},{\"price\":\"63914.8\",\"size\":\"0.00000\"},{\"price\":\"63914.0\",\"size\":\"3.11340\"},{\"price\":\"63907.7\",\"size\":\"9.34019\"},{\"price\":\"63888.0\",\"size\":\"0.00000\"},{\"price\":\"63744.0\",\"size\":\"15.61273\"}],\"offset\":3902947,\"nonce\":36957262,\"last_updated_at\":1785276557313889,\"begin_nonce\":36957247},\"timestamp\":1785276557334,\"type\":\"update/order_book\"}"
        "raw": "{\"channel\":\"order_book:1\",\"last_updated_at\":1785276557428568,\"offset\":3902949,\"order_book\":{\"code\":0,\"asks\":[{\"price\":\"64039.9\",\"size\":\"0.00000\"},{\"price\":\"64047.6\",\"size\":\"6.25228\"},{\"price\":\"64070.4\",\"size\":\"0.00000\"},{\"price\":\"64214.4\",\"size\":\"15.61542\"}],\"bids\":[{\"price\":\"63907.7\",\"size\":\"0.00000\"},{\"price\":\"63900.0\",\"size\":\"9.34119\"}],\"offset\":3902949,\"nonce\":36957267,\"last_updated_at\":1785276557428568,\"begin_nonce\":36957262},\"timestamp\":1785276557434,\"type\":\"update/order_book\"}"
        "raw": "{\"channel\":\"order_book:1\",\"last_updated_at\":1785276557481695,\"offset\":3902953,\"order_book\":{\"code\":0,\"asks\":[{\"price\":\"64020.0\",\"size\":\"0.00259\"},{\"price\":\"64047.6\",\"size\":\"0.00000\"},{\"price\":\"64052.2\",\"size\":\"6.25243\"}],\"bids\":[{\"price\":\"63914.0\",\"size\":\"0.00000\"},{\"price\":\"63909.6\",\"size\":\"3.11340\"},{\"price\":\"63902.9\",\"size\":\"0.00000\"},{\"price\":\"63900.0\",\"size\":\"0.00100\"},{\"price\":\"63895.3\",\"size\":\"12.45358\"},{\"price\":\"63893.2\",\"size\":\"9.34041\"}],\"offset\":3902953,\"nonce\":36957272,\"last_updated_at\":1785276557481695,\"begin_nonce\":36957267},\"timestamp\":1785276557484,\"type\":\"update/order_book\"}"
        "raw": "{\"channel\":\"order_book:1\",\"last_updated_at\":1785276557520958,\"offset\":3902958,\"order_book\":{\"code\":0,\"asks\":[{\"price\":\"64038.5\",\"size\":\"0.00000\"},{\"price\":\"64044.7\",\"size\":\"0.00000\"},{\"price\":\"64047.4\",\"size\":\"3.12622\"},{\"price\":\"64049.5\",\"size\":\"0.00000\"},{\"price\":\"64057.0\",\"size\":\"9.37864\"},{\"price\":\"64061.8\",\"size\":\"12.50485\"}],\"bids\":[{\"price\":\"63912.5\",\"size\":\"0.00000\"},{\"price\":\"63909.6\",\"size\":\"0.00000\"},{\"price\":\"63902.7\",\"size\":\"3.11347\"},{\"price\":\"63897.9\",\"size\":\"6.22694\"},{\"price\":\"63895.3\",\"size\":\"0.00000\"},{\"price\":\"63888.4\",\"size\":\"12.45387\"},{\"price\":\"63878.4\",\"size\":\"0.00000\"},{\"price\":\"63734.4\",\"size\":\"15.61512\"}],\"offset\":3902958,\"nonce\":36957279,\"last_updated_at\":1785276557520958,\"begin_nonce\":36957272},\"timestamp\":1785276557534,\"type\":\"update/order_book\"}"
        "raw": "{\"channel\":\"order_book:1\",\"last_updated_at\":1785276557533136,\"offset\":3902959,\"order_book\":{\"code\":0,\"asks\":[],\"bids\":[{\"price\":\"63902.7\",\"size\":\"0.00000\"},{\"price\":\"63901.1\",\"size\":\"3.11347\"}],\"offset\":3902959,\"nonce\":36957280,\"last_updated_at\":1785276557533136,\"begin_nonce\":36957279},\"timestamp\":1785276557584,\"type\":\"update/order_book\"}"
        "raw": "{\"channel\":\"order_book:1\",\"last_updated_at\":1785276557624133,\"offset\":3902960,\"order_book\":{\"code\":0,\"asks\":[{\"price\":\"64042.4\",\"size\":\"3.12622\"},{\"price\":\"64047.4\",\"size\":\"0.00000\"}],\"bids\":[{\"price\":\"63901.1\",\"size\":\"0.00000\"},{\"price\":\"63898.2\",\"size\":\"3.11347\"}],\"offset\":3902960,\"nonce\":36957283,\"last_updated_at\":1785276557624133,\"begin_nonce\":36957280},\"timestamp\":1785276557633,\"type\":\"update/order_book\"}"
        "raw": "{\"channel\":\"order_book:1\",\"last_updated_at\":1785276557839506,\"offset\":3902961,\"order_book\":{\"code\":0,\"asks\":[{\"price\":\"64029.7\",\"size\":\"3.12622\"},{\"price\":\"64042.4\",\"size\":\"0.00000\"}],\"bids\":[{\"price\":\"63917.2\",\"size\":\"3.11347\"},{\"price\":\"63898.2\",\"size\":\"0.00000\"}],\"offset\":3902961,\"nonce\":36957295,\"last_updated_at\":1785276557839506,\"begin_nonce\":36957283},\"timestamp\":1785276557884,\"type\":\"update/order_book\"}"
        "raw": "{\"channel\":\"order_book:1\",\"last_updated_at\":1785276557953605,\"offset\":3902963,\"order_book\":{\"code\":0,\"asks\":[{\"price\":\"64051.2\",\"size\":\"15.62059\"},{\"price\":\"64060.8\",\"size\":\"15.62059\"},{\"price\":\"64070.4\",\"size\":\"15.62059\"},{\"price\":\"64195.2\",\"size\":\"0.00000\"},{\"price\":\"64204.8\",\"size\":\"0.00000\"},{\"price\":\"64214.4\",\"size\":\"0.00000\"}],\"bids\":[{\"price\":\"63897.6\",\"size\":\"15.60975\"},{\"price\":\"63888.0\",\"size\":\"15.60975\"},{\"price\":\"63878.4\",\"size\":\"15.60975\"},{\"price\":\"63753.6\",\"size\":\"0.00000\"},{\"price\":\"63744.0\",\"size\":\"0.00000\"},{\"price\":\"63734.4\",\"size\":\"0.00000\"}],\"offset\":3902963,\"nonce\":36957300,\"last_updated_at\":1785276557953605,\"begin_nonce\":36957295},\"timestamp\":1785276557985,\"type\":\"update/order_book\"}"
        "raw": "{\"channel\":\"order_book:1\",\"last_updated_at\":1785276558001557,\"offset\":3902964,\"order_book\":{\"code\":0,\"asks\":[{\"price\":\"64016.3\",\"size\":\"3.12622\"},{\"price\":\"64029.7\",\"size\":\"0.00000\"}],\"bids\":[{\"price\":\"63933.8\",\"size\":\"3.11347\"},{\"price\":\"63917.2\",\"size\":\"0.00000\"}],\"offset\":3902964,\"nonce\":36957301,\"last_updated_at\":1785276558001557,\"begin_nonce\":36957300},\"timestamp\":1785276558033,\"type\":\"update/order_book\"}"
        "raw": "{\"channel\":\"order_book:1\",\"last_updated_at\":1785276558229360,\"offset\":3902965,\"order_book\":{\"code\":0,\"asks\":[{\"price\":\"64010.0\",\"size\":\"3.12622\"},{\"price\":\"64016.3\",\"size\":\"0.00000\"}],\"bids\":[{\"price\":\"63940.1\",\"size\":\"3.11347\"},{\"price\":\"63933.8\",\"size\":\"0.00000\"}],\"offset\":3902965,\"nonce\":36957307,\"last_updated_at\":1785276558229360,\"begin_nonce\":36957301},\"timestamp\":1785276558233,\"type\":\"update/order_book\"}"
        "raw": "{\"channel\":\"order_book:1\",\"last_updated_at\":1785276558303894,\"offset\":3902967,\"order_book\":{\"code\":0,\"asks\":[{\"price\":\"64016.3\",\"size\":\"0.00163\"},{\"price\":\"64020.0\",\"size\":\"0.00096\"}],\"bids\":[],\"offset\":3902967,\"nonce\":36957309,\"last_updated_at\":1785276558303894,\"begin_nonce\":36957307},\"timestamp\":1785276558334,\"type\":\"update/order_book\"}"
        "raw": "{\"channel\":\"order_book:1\",\"last_updated_at\":1785276558378605,\"offset\":3902969,\"order_book\":{\"code\":0,\"asks\":[],\"bids\":[{\"price\":\"63929.5\",\"size\":\"0.00149\"},{\"price\":\"63929.4\",\"size\":\"0.00000\"}],\"offset\":3902969,\"nonce\":36957312,\"last_updated_at\":1785276558378605,\"begin_nonce\":36957309},\"timestamp\":1785276558384,\"type\":\"update/order_book\"}"
        "raw": "{\"channel\":\"order_book:1\",\"last_updated_at\":1785276558483065,\"offset\":3902970,\"order_book\":{\"code\":0,\"asks\":[{\"price\":\"64009.3\",\"size\":\"3.12622\"},{\"price\":\"64010.0\",\"size\":\"0.00000\"}],\"bids\":[{\"price\":\"63940.8\",\"size\":\"3.11347\"},{\"price\":\"63940.1\",\"size\":\"0.00000\"}],\"offset\":3902970,\"nonce\":36957313,\"last_updated_at\":1785276558483065,\"begin_nonce\":36957312},\"timestamp\":1785276558485,\"type\":\"update/order_book\"}"
        "raw": "{\"channel\":\"order_book:1\",\"last_updated_at\":1785276558532684,\"offset\":3902971,\"order_book\":{\"code\":0,\"asks\":[{\"price\":\"64014.6\",\"size\":\"0.00163\"},{\"price\":\"64016.3\",\"size\":\"0.00000\"}],\"bids\":[],\"offset\":3902971,\"nonce\":36957315,\"last_updated_at\":1785276558532684,\"begin_nonce\":36957313},\"timestamp\":1785276558533,\"type\":\"update/order_book\"}"
        "raw": "{\"channel\":\"order_book:1\",\"last_updated_at\":1785276558601510,\"offset\":3902972,\"order_book\":{\"code\":0,\"asks\":[{\"price\":\"64014.6\",\"size\":\"0.00000\"},{\"price\":\"64014.7\",\"size\":\"0.00163\"}],\"bids\":[],\"offset\":3902972,\"nonce\":36957317,\"last_updated_at\":1785276558601510,\"begin_nonce\":36957315},\"timestamp\":1785276558634,\"type\":\"update/order_book\"}"
        "raw": "{\"channel\":\"order_book:1\",\"last_updated_at\":1785276558730216,\"offset\":3902973,\"order_book\":{\"code\":0,\"asks\":[{\"price\":\"64009.3\",\"size\":\"0.00000\"},{\"price\":\"64010.3\",\"size\":\"3.12622\"}],\"bids\":[{\"price\":\"63940.8\",\"size\":\"0.00000\"},{\"price\":\"63939.1\",\"size\":\"3.11347\"}],\"offset\":3902973,\"nonce\":36957319,\"last_updated_at\":1785276558730216,\"begin_nonce\":36957317},\"timestamp\":1785276558734,\"type\":\"update/order_book\"}"
        "raw": "{\"channel\":\"order_book:1\",\"last_updated_at\":1785276558930757,\"offset\":3902974,\"order_book\":{\"code\":0,\"asks\":[{\"price\":\"64008.7\",\"size\":\"3.12622\"},{\"price\":\"64010.3\",\"size\":\"0.00000\"}],\"bids\":[],\"offset\":3902974,\"nonce\":36957323,\"last_updated_at\":1785276558930757,\"begin_nonce\":36957319},\"timestamp\":1785276558934,\"type\":\"update/order_book\"}"
        "raw": "{\"channel\":\"order_book:1\",\"last_updated_at\":1785276559147556,\"offset\":3902975,\"order_book\":{\"code\":0,\"asks\":[{\"price\":\"64008.7\",\"size\":\"0.00000\"},{\"price\":\"64009.5\",\"size\":\"3.12622\"}],\"bids\":[{\"price\":\"63940.0\",\"size\":\"3.11444\"},{\"price\":\"63939.1\",\"size\":\"0.00000\"}],\"offset\":3902975,\"nonce\":36957329,\"last_updated_at\":1785276559147556,\"begin_nonce\":36957323},\"timestamp\":1785276559183,\"type\":\"update/order_book\"}"
        "raw": "{\"channel\":\"order_book:1\",\"last_updated_at\":1785276559394828,\"offset\":3902976,\"order_book\":{\"code\":0,\"asks\":[{\"price\":\"64008.6\",\"size\":\"3.12622\"},{\"price\":\"64009.5\",\"size\":\"0.00000\"}],\"bids\":[{\"price\":\"63941.5\",\"size\":\"3.11347\"},{\"price\":\"63940.0\",\"size\":\"0.00097\"}],\"offset\":3902976,\"nonce\":36957332,\"last_updated_at\":1785276559394828,\"begin_nonce\":36957329},\"timestamp\":1785276559433,\"type\":\"update/order_book\"}"
        "raw": "{\"channel\":\"order_book:1\",\"last_updated_at\":1785276559663201,\"offset\":3902978,\"order_book\":{\"code\":0,\"asks\":[{\"price\":\"64014.7\",\"size\":\"0.00000\"},{\"price\":\"64014.8\",\"size\":\"0.00163\"}],\"bids\":[],\"offset\":3902978,\"nonce\":36957337,\"last_updated_at\":1785276559663201,\"begin_nonce\":36957332},\"timestamp\":1785276559683,\"type\":\"update/order_book\"}"
        "raw": "{\"channel\":\"order_book:1\",\"last_updated_at\":1785276560743253,\"offset\":3902980,\"order_book\":{\"code\":0,\"asks\":[{\"price\":\"64014.8\",\"size\":\"0.00000\"},{\"price\":\"64014.9\",\"size\":\"0.00163\"}],\"bids\":[],\"offset\":3902980,\"nonce\":36957342,\"last_updated_at\":1785276560743253,\"begin_nonce\":36957337},\"timestamp\":1785276560783,\"type\":\"update/order_book\"}"
        "raw": "{\"channel\":\"order_book:1\",\"last_updated_at\":1785276561481844,\"offset\":3902981,\"order_book\":{\"code\":0,\"asks\":[{\"price\":\"64008.5\",\"size\":\"3.12622\"},{\"price\":\"64008.6\",\"size\":\"0.00000\"}],\"bids\":[{\"price\":\"63941.6\",\"size\":\"3.11347\"},{\"price\":\"63941.5\",\"size\":\"0.00000\"}],\"offset\":3902981,\"nonce\":36957346,\"last_updated_at\":1785276561481844,\"begin_nonce\":36957342},\"timestamp\":1785276561484,\"type\":\"update/order_book\"}"
        "raw": "{\"channel\":\"order_book:1\",\"last_updated_at\":1785276561991730,\"offset\":3902982,\"order_book\":{\"code\":0,\"asks\":[{\"price\":\"64008.5\",\"size\":\"0.00000\"},{\"price\":\"64008.6\",\"size\":\"3.12622\"}],\"bids\":[{\"price\":\"63941.6\",\"size\":\"0.00000\"},{\"price\":\"63941.5\",\"size\":\"3.11347\"}],\"offset\":3902982,\"nonce\":36957350,\"last_updated_at\":1785276561991730,\"begin_nonce\":36957346},\"timestamp\":1785276562034,\"type\":\"update/order_book\"}"
        "raw": "{\"channel\":\"order_book:1\",\"last_updated_at\":1785276562037145,\"offset\":3902983,\"order_book\":{\"code\":0,\"asks\":[{\"price\":\"64008.6\",\"size\":\"3.12621\"}],\"bids\":[],\"offset\":3902983,\"nonce\":36957351,\"last_updated_at\":1785276562037145,\"begin_nonce\":36957350},\"timestamp\":1785276562084,\"type\":\"update/order_book\"}"
        "raw": "{\"channel\":\"order_book:1\",\"last_updated_at\":1785276562273887,\"offset\":3902984,\"order_book\":{\"code\":0,\"asks\":[{\"price\":\"64014.9\",\"size\":\"0.00000\"},{\"price\":\"64015.0\",\"size\":\"0.00163\"}],\"bids\":[],\"offset\":3902984,\"nonce\":36957354,\"last_updated_at\":1785276562273887,\"begin_nonce\":36957351},\"timestamp\":1785276562284,\"type\":\"update/order_book\"}"
        "raw": "{\"channel\":\"order_book:1\",\"last_updated_at\":1785276562375125,\"offset\":3902986,\"order_book\":{\"code\":0,\"asks\":[{\"price\":\"64014.9\",\"size\":\"0.00163\"},{\"price\":\"64015.0\",\"size\":\"0.00000\"}],\"bids\":[],\"offset\":3902986,\"nonce\":36957356,\"last_updated_at\":1785276562375125,\"begin_nonce\":36957354},\"timestamp\":1785276562384,\"type\":\"update/order_book\"}"
        "raw": "{\"channel\":\"order_book:1\",\"last_updated_at\":1785276562513347,\"offset\":3902987,\"order_book\":{\"code\":0,\"asks\":[{\"price\":\"64014.9\",\"size\":\"0.00000\"},{\"price\":\"64015.0\",\"size\":\"0.00163\"}],\"bids\":[],\"offset\":3902987,\"nonce\":36957357,\"last_updated_at\":1785276562513347,\"begin_nonce\":36957356},\"timestamp\":1785276562533,\"type\":\"update/order_book\"}"
        "raw": "{\"channel\":\"order_book:1\",\"last_updated_at\":1785276563413496,\"offset\":3902988,\"order_book\":{\"code\":0,\"asks\":[{\"price\":\"64014.9\",\"size\":\"0.00163\"},{\"price\":\"64015.0\",\"size\":\"0.00000\"}],\"bids\":[],\"offset\":3902988,\"nonce\":36957360,\"last_updated_at\":1785276563413496,\"begin_nonce\":36957357},\"timestamp\":1785276563434,\"type\":\"update/order_book\"}"
        "raw": "{\"channel\":\"order_book:1\",\"last_updated_at\":1785276564119123,\"offset\":3902989,\"order_book\":{\"code\":0,\"asks\":[{\"price\":\"64008.6\",\"size\":\"0.00000\"},{\"price\":\"64008.7\",\"size\":\"3.12621\"}],\"bids\":[{\"price\":\"63941.5\",\"size\":\"0.00000\"},{\"price\":\"63941.4\",\"size\":\"3.11347\"}],\"offset\":3902989,\"nonce\":36957365,\"last_updated_at\":1785276564119123,\"begin_nonce\":36957360},\"timestamp\":1785276564134,\"type\":\"update/order_book\"}"
        "raw": "{\"channel\":\"order_book:1\",\"last_updated_at\":1785276564394335,\"offset\":3902991,\"order_book\":{\"code\":0,\"asks\":[],\"bids\":[{\"price\":\"63929.6\",\"size\":\"0.00149\"},{\"price\":\"63929.5\",\"size\":\"0.00000\"}],\"offset\":3902991,\"nonce\":36957370,\"last_updated_at\":1785276564394335,\"begin_nonce\":36957365},\"timestamp\":1785276564434,\"type\":\"update/order_book\"}"
        "raw": "{\"channel\":\"order_book:1\",\"last_updated_at\":1785276564553669,\"offset\":3902992,\"order_book\":{\"code\":0,\"asks\":[{\"price\":\"64014.8\",\"size\":\"0.00163\"},{\"price\":\"64014.9\",\"size\":\"0.00000\"}],\"bids\":[],\"offset\":3902992,\"nonce\":36957371,\"last_updated_at\":1785276564553669,\"begin_nonce\":36957370},\"timestamp\":1785276564584,\"type\":\"update/order_book\"}"
        "raw": "{\"channel\":\"order_book:1\",\"last_updated_at\":1785276564652999,\"offset\":3902993,\"order_book\":{\"code\":0,\"asks\":[{\"price\":\"64008.5\",\"size\":\"3.12621\"},{\"price\":\"64008.7\",\"size\":\"0.00000\"}],\"bids\":[{\"price\":\"63941.6\",\"size\":\"3.11347\"},{\"price\":\"63941.4\",\"size\":\"0.00000\"}],\"offset\":3902993,\"nonce\":36957373,\"last_updated_at\":1785276564652999,\"begin_nonce\":36957371},\"timestamp\":1785276564684,\"type\":\"update/order_book\"}"
        "raw": "{\"channel\":\"order_book:1\",\"last_updated_at\":1785276565015129,\"offset\":3902995,\"order_book\":{\"code\":0,\"asks\":[],\"bids\":[{\"price\":\"63929.7\",\"size\":\"0.00149\"},{\"price\":\"63929.6\",\"size\":\"0.00000\"}],\"offset\":3902995,\"nonce\":36957377,\"last_updated_at\":1785276565015129,\"begin_nonce\":36957373},\"timestamp\":1785276565034,\"type\":\"update/order_book\"}"
        "raw": "{\"channel\":\"order_book:1\",\"last_updated_at\":1785276565180969,\"offset\":3902997,\"order_book\":{\"code\":0,\"asks\":[{\"price\":\"64008.5\",\"size\":\"0.00000\"},{\"price\":\"64008.6\",\"size\":\"3.12621\"}],\"bids\":[{\"price\":\"63941.6\",\"size\":\"0.00000\"},{\"price\":\"63941.5\",\"size\":\"3.11347\"}],\"offset\":3902997,\"nonce\":36957379,\"last_updated_at\":1785276565180969,\"begin_nonce\":36957377},\"timestamp\":1785276565184,\"type\":\"update/order_book\"}"
        "raw": "{\"channel\":\"order_book:1\",\"last_updated_at\":1785276565590808,\"offset\":3902998,\"order_book\":{\"code\":0,\"asks\":[],\"bids\":[{\"price\":\"63929.8\",\"size\":\"0.00149\"},{\"price\":\"63929.7\",\"size\":\"0.00000\"}],\"offset\":3902998,\"nonce\":36957382,\"last_updated_at\":1785276565590808,\"begin_nonce\":36957379},\"timestamp\":1785276565633,\"type\":\"update/order_book\"}"
        "raw": "{\"channel\":\"order_book:1\",\"last_updated_at\":1785276565723465,\"offset\":3903000,\"order_book\":{\"code\":0,\"asks\":[{\"price\":\"64014.7\",\"size\":\"0.00163\"},{\"price\":\"64014.8\",\"size\":\"0.00000\"}],\"bids\":[],\"offset\":3903000,\"nonce\":36957384,\"last_updated_at\":1785276565723465,\"begin_nonce\":36957382},\"timestamp\":1785276565734,\"type\":\"update/order_book\"}"
        "raw": "{\"channel\":\"order_book:1\",\"last_updated_at\":1785276566093078,\"offset\":3903002,\"order_book\":{\"code\":0,\"asks\":[],\"bids\":[{\"price\":\"63929.9\",\"size\":\"0.00149\"},{\"price\":\"63929.8\",\"size\":\"0.00000\"}],\"offset\":3903002,\"nonce\":36957389,\"last_updated_at\":1785276566093078,\"begin_nonce\":36957384},\"timestamp\":1785276566133,\"type\":\"update/order_book\"}"
        "raw": "{\"channel\":\"order_book:1\",\"last_updated_at\":1785276566503184,\"offset\":3903004,\"order_book\":{\"code\":0,\"asks\":[],\"bids\":[{\"price\":\"63930.0\",\"size\":\"0.00149\"},{\"price\":\"63929.9\",\"size\":\"0.00000\"}],\"offset\":3903004,\"nonce\":36957392,\"last_updated_at\":1785276566503184,\"begin_nonce\":36957389},\"timestamp\":1785276566534,\"type\":\"update/order_book\"}"
        "raw": "{\"channel\":\"order_book:1\",\"last_updated_at\":1785276566701499,\"offset\":3903006,\"order_book\":{\"code\":0,\"asks\":[{\"price\":\"64008.5\",\"size\":\"3.12621\"},{\"price\":\"64008.6\",\"size\":\"0.00000\"}],\"bids\":[{\"price\":\"63941.6\",\"size\":\"3.11347\"},{\"price\":\"63941.5\",\"size\":\"0.00000\"}],\"offset\":3903006,\"nonce\":36957395,\"last_updated_at\":1785276566701499,\"begin_nonce\":36957392},\"timestamp\":1785276566734,\"type\":\"update/order_book\"}"
        "raw": "{\"channel\":\"order_book:1\",\"last_updated_at\":1785276566850281,\"offset\":3903007,\"order_book\":{\"code\":0,\"asks\":[],\"bids\":[{\"price\":\"63930.1\",\"size\":\"0.00149\"},{\"price\":\"63930.0\",\"size\":\"0.00000\"}],\"offset\":3903007,\"nonce\":36957396,\"last_updated_at\":1785276566850281,\"begin_nonce\":36957395},\"timestamp\":1785276566883,\"type\":\"update/order_book\"}"
        "raw": "{\"channel\":\"order_book:1\",\"last_updated_at\":1785276567294288,\"offset\":3903009,\"order_book\":{\"code\":0,\"asks\":[],\"bids\":[{\"price\":\"63930.2\",\"size\":\"0.00149\"},{\"price\":\"63930.1\",\"size\":\"0.00000\"}],\"offset\":3903009,\"nonce\":36957401,\"last_updated_at\":1785276567294288,\"begin_nonce\":36957396},\"timestamp\":1785276567334,\"type\":\"update/order_book\"}"
        "raw": "{\"channel\":\"order_book:1\",\"last_updated_at\":1785276567507677,\"offset\":3903013,\"order_book\":{\"code\":0,\"asks\":[{\"price\":\"64014.7\",\"size\":\"0.00000\"},{\"price\":\"64016.4\",\"size\":\"0.00163\"}],\"bids\":[{\"price\":\"63931.9\",\"size\":\"0.00149\"},{\"price\":\"63930.2\",\"size\":\"0.00000\"}],\"offset\":3903013,\"nonce\":36957405,\"last_updated_at\":1785276567507677,\"begin_nonce\":36957401},\"timestamp\":1785276567534,\"type\":\"update/order_book\"}"
        "raw": "{\"channel\":\"order_book:1\",\"last_updated_at\":1785276567600345,\"offset\":3903015,\"order_book\":{\"code\":0,\"asks\":[{\"price\":\"64016.3\",\"size\":\"0.00163\"},{\"price\":\"64016.4\",\"size\":\"0.00000\"}],\"bids\":[],\"offset\":3903015,\"nonce\":36957408,\"last_updated_at\":1785276567600345,\"begin_nonce\":36957405},\"timestamp\":1785276567634,\"type\":\"update/order_book\"}"
        "raw": "{\"channel\":\"order_book:1\",\"last_updated_at\":1785276567762394,\"offset\":3903017,\"order_book\":{\"code\":0,\"asks\":[],\"bids\":[{\"price\":\"63932.0\",\"size\":\"0.00149\"},{\"price\":\"63931.9\",\"size\":\"0.00000\"}],\"offset\":3903017,\"nonce\":36957413,\"last_updated_at\":1785276567762394,\"begin_nonce\":36957408},\"timestamp\":1785276567784,\"type\":\"update/order_book\"}"
        "raw": "{\"channel\":\"order_book:1\",\"last_updated_at\":1785276568212581,\"offset\":3903019,\"order_book\":{\"code\":0,\"asks\":[],\"bids\":[{\"price\":\"63932.1\",\"size\":\"0.00149\"},{\"price\":\"63932.0\",\"size\":\"0.00000\"}],\"offset\":3903019,\"nonce\":36957417,\"last_updated_at\":1785276568212581,\"begin_nonce\":36957413},\"timestamp\":1785276568234,\"type\":\"update/order_book\"}"
        "raw": "{\"channel\":\"order_book:1\",\"last_updated_at\":1785276568470272,\"offset\":3903020,\"order_book\":{\"code\":0,\"asks\":[{\"price\":\"64008.4\",\"size\":\"3.12621\"},{\"price\":\"64008.5\",\"size\":\"0.00000\"}],\"bids\":[{\"price\":\"63941.7\",\"size\":\"3.11347\"},{\"price\":\"63941.6\",\"size\":\"0.00000\"}],\"offset\":3903020,\"nonce\":36957419,\"last_updated_at\":1785276568470272,\"begin_nonce\":36957417},\"timestamp\":1785276568484,\"type\":\"update/order_book\"}"
        "raw": "{\"channel\":\"order_book:1\",\"last_updated_at\":1785276568663971,\"offset\":3903022,\"order_book\":{\"code\":0,\"asks\":[],\"bids\":[{\"price\":\"63932.2\",\"size\":\"0.00149\"},{\"price\":\"63932.1\",\"size\":\"0.00000\"}],\"offset\":3903022,\"nonce\":36957423,\"last_updated_at\":1785276568663971,\"begin_nonce\":36957419},\"timestamp\":1785276568684,\"type\":\"update/order_book\"}"
        "raw": "{\"channel\":\"order_book:1\",\"last_updated_at\":1785276568827928,\"offset\":3903028,\"order_book\":{\"code\":0,\"asks\":[{\"price\":\"64014.6\",\"size\":\"0.00163\"},{\"price\":\"64016.3\",\"size\":\"0.00000\"}],\"bids\":[{\"price\":\"63932.2\",\"size\":\"0.00000\"},{\"price\":\"63930.5\",\"size\":\"0.00149\"}],\"offset\":3903028,\"nonce\":36957431,\"last_updated_at\":1785276568827928,\"begin_nonce\":36957423},\"timestamp\":1785276568833,\"type\":\"update/order_book\"}"
        "raw": "{\"channel\":\"order_book:1\",\"last_updated_at\":1785276568995390,\"offset\":3903030,\"order_book\":{\"code\":0,\"asks\":[{\"price\":\"64008.4\",\"size\":\"0.00000\"},{\"price\":\"64008.5\",\"size\":\"3.12621\"}],\"bids\":[{\"price\":\"63941.7\",\"size\":\"0.00000\"},{\"price\":\"63941.5\",\"size\":\"3.11347\"}],\"offset\":3903030,\"nonce\":36957441,\"last_updated_at\":1785276568995390,\"begin_nonce\":36957431},\"timestamp\":1785276569033,\"type\":\"update/order_book\"}"
        "raw": "{\"channel\":\"order_book:1\",\"last_updated_at\":1785276569124352,\"offset\":3903032,\"order_book\":{\"code\":0,\"asks\":[],\"bids\":[{\"price\":\"63930.6\",\"size\":\"0.00149\"},{\"price\":\"63930.5\",\"size\":\"0.00000\"}],\"offset\":3903032,\"nonce\":36957444,\"last_updated_at\":1785276569124352,\"begin_nonce\":36957441},\"timestamp\":1785276569134,\"type\":\"update/order_book\"}"
        "raw": "{\"channel\":\"order_book:1\",\"last_updated_at\":1785276569530078,\"offset\":3903033,\"order_book\":{\"code\":0,\"asks\":[{\"price\":\"64008.5\",\"size\":\"0.00000\"},{\"price\":\"64008.7\",\"size\":\"3.12621\"}],\"bids\":[{\"price\":\"63941.5\",\"size\":\"0.00000\"},{\"price\":\"63941.2\",\"size\":\"3.11347\"}],\"offset\":3903033,\"nonce\":36957447,\"last_updated_at\":1785276569530078,\"begin_nonce\":36957444},\"timestamp\":1785276569533,\"type\":\"update/order_book\"}"
        "raw": "{\"channel\":\"order_book:1\",\"last_updated_at\":1785276569583943,\"offset\":3903035,\"order_book\":{\"code\":0,\"asks\":[],\"bids\":[{\"price\":\"63930.7\",\"size\":\"0.00149\"},{\"price\":\"63930.6\",\"size\":\"0.00000\"}],\"offset\":3903035,\"nonce\":36957449,\"last_updated_at\":1785276569583943,\"begin_nonce\":36957447},\"timestamp\":1785276569584,\"type\":\"update/order_book\"}"
        "raw": "{\"channel\":\"order_book:1\",\"last_updated_at\":1785276569818554,\"offset\":3903039,\"order_book\":{\"code\":0,\"asks\":[{\"price\":\"64008.7\",\"size\":\"0.00000\"},{\"price\":\"64009.1\",\"size\":\"3.12628\"},{\"price\":\"64014.6\",\"size\":\"0.00000\"},{\"price\":\"64014.7\",\"size\":\"0.00163\"}],\"bids\":[{\"price\":\"63941.2\",\"size\":\"0.00000\"},{\"price\":\"63938.7\",\"size\":\"3.11354\"}],\"offset\":3903039,\"nonce\":36957457,\"last_updated_at\":1785276569818554,\"begin_nonce\":36957449},\"timestamp\":1785276569834,\"type\":\"update/order_book\"}"
        "raw": "{\"channel\":\"order_book:1\",\"last_updated_at\":1785276569919554,\"offset\":3903045,\"order_book\":{\"code\":0,\"asks\":[{\"price\":\"64009.0\",\"size\":\"3.12641\"},{\"price\":\"64009.1\",\"size\":\"0.00000\"},{\"price\":\"64011.5\",\"size\":\"0.00163\"},{\"price\":\"64014.7\",\"size\":\"0.00000\"}],\"bids\":[{\"price\":\"63938.7\",\"size\":\"0.00000\"},{\"price\":\"63935.0\",\"size\":\"3.11367\"},{\"price\":\"63930.7\",\"size\":\"0.00000\"},{\"price\":\"63927.5\",\"size\":\"0.00149\"}],\"offset\":3903045,\"nonce\":36957463,\"last_updated_at\":1785276569919554,\"begin_nonce\":36957457},\"timestamp\":1785276569933,\"type\":\"update/order_book\"}"
        "raw": "{\"channel\":\"order_book:1\",\"last_updated_at\":1785276570063890,\"offset\":3903047,\"order_book\":{\"code\":0,\"asks\":[],\"bids\":[{\"price\":\"63927.6\",\"size\":\"0.00149\"},{\"price\":\"63927.5\",\"size\":\"0.00000\"}],\"offset\":3903047,\"nonce\":36957466,\"last_updated_at\":1785276570063890,\"begin_nonce\":36957463},\"timestamp\":1785276570084,\"type\":\"update/order_book\"}"
        "raw": "{\"channel\":\"order_book:1\",\"last_updated_at\":1785276570436302,\"offset\":3903048,\"order_book\":{\"code\":0,\"asks\":[{\"price\":\"64008.5\",\"size\":\"3.12641\"},{\"price\":\"64009.0\",\"size\":\"0.00000\"}],\"bids\":[{\"price\":\"63935.6\",\"size\":\"3.11367\"},{\"price\":\"63935.0\",\"size\":\"0.00000\"}],\"offset\":3903048,\"nonce\":36957472,\"last_updated_at\":1785276570436302,\"begin_nonce\":36957466},\"timestamp\":1785276570484,\"type\":\"update/order_book\"}"
        "raw": "{\"channel\":\"order_book:1\",\"last_updated_at\":1785276570582439,\"offset\":3903050,\"order_book\":{\"code\":0,\"asks\":[],\"bids\":[{\"price\":\"63927.7\",\"size\":\"0.00149\"},{\"price\":\"63927.6\",\"size\":\"0.00000\"}],\"offset\":3903050,\"nonce\":36957478,\"last_updated_at\":1785276570582439,\"begin_nonce\":36957472},\"timestamp\":1785276570584,\"type\":\"update/order_book\"}"
        "raw": "{\"channel\":\"order_book:1\",\"last_updated_at\":1785276570952253,\"offset\":3903051,\"order_book\":{\"code\":0,\"asks\":[],\"bids\":[{\"price\":\"63927.8\",\"size\":\"0.00149\"},{\"price\":\"63927.7\",\"size\":\"0.00000\"}],\"offset\":3903051,\"nonce\":36957486,\"last_updated_at\":1785276570952253,\"begin_nonce\":36957478},\"timestamp\":1785276570984,\"type\":\"update/order_book\"}"
        "raw": "{\"channel\":\"order_book:1\",\"last_updated_at\":1785276571161609,\"offset\":3903052,\"order_book\":{\"code\":0,\"asks\":[{\"price\":\"64008.5\",\"size\":\"3.12640\"}],\"bids\":[],\"offset\":3903052,\"nonce\":36957488,\"last_updated_at\":1785276571161609,\"begin_nonce\":36957486},\"timestamp\":1785276571183,\"type\":\"update/order_book\"}"
        "raw": "{\"channel\":\"order_book:1\",\"last_updated_at\":1785276571263604,\"offset\":3903054,\"order_book\":{\"code\":0,\"asks\":[],\"bids\":[{\"price\":\"63927.9\",\"size\":\"0.00149\"},{\"price\":\"63927.8\",\"size\":\"0.00000\"}],\"offset\":3903054,\"nonce\":36957491,\"last_updated_at\":1785276571263604,\"begin_nonce\":36957488},\"timestamp\":1785276571284,\"type\":\"update/order_book\"}"
        "raw": "{\"channel\":\"order_book:1\",\"last_updated_at\":1785276571572476,\"offset\":3903056,\"order_book\":{\"code\":0,\"asks\":[],\"bids\":[{\"price\":\"63928.0\",\"size\":\"0.00149\"},{\"price\":\"63927.9\",\"size\":\"0.00000\"}],\"offset\":3903056,\"nonce\":36957495,\"last_updated_at\":1785276571572476,\"begin_nonce\":36957491},\"timestamp\":1785276571583,\"type\":\"update/order_book\"}"
        "raw": "{\"channel\":\"order_book:1\",\"last_updated_at\":1785276571873566,\"offset\":3903061,\"order_book\":{\"code\":0,\"asks\":[{\"price\":\"64004.6\",\"size\":\"3.12640\"},{\"price\":\"64008.5\",\"size\":\"0.00000\"},{\"price\":\"64011.5\",\"size\":\"0.00000\"},{\"price\":\"64011.6\",\"size\":\"0.00163\"}],\"bids\":[{\"price\":\"63937.5\",\"size\":\"3.11367\"},{\"price\":\"63935.6\",\"size\":\"0.00000\"},{\"price\":\"63928.1\",\"size\":\"0.00149\"},{\"price\":\"63928.0\",\"size\":\"0.00000\"}],\"offset\":3903061,\"nonce\":36957501,\"last_updated_at\":1785276571873566,\"begin_nonce\":36957495},\"timestamp\":1785276571883,\"type\":\"update/order_book\"}"
        "raw": "{\"channel\":\"order_book:1\",\"last_updated_at\":1785276572190423,\"offset\":3903063,\"order_book\":{\"code\":0,\"asks\":[],\"bids\":[{\"price\":\"63928.2\",\"size\":\"0.00149\"},{\"price\":\"63928.1\",\"size\":\"0.00000\"}],\"offset\":3903063,\"nonce\":36957506,\"last_updated_at\":1785276572190423,\"begin_nonce\":36957501},\"timestamp\":1785276572233,\"type\":\"update/order_book\"}"
        "raw": "{\"channel\":\"order_book:1\",\"last_updated_at\":1785276572256101,\"offset\":3903064,\"order_book\":{\"code\":0,\"asks\":[{\"price\":\"64003.6\",\"size\":\"3.12644\"},{\"price\":\"64004.6\",\"size\":\"0.00000\"}],\"bids\":[{\"price\":\"63937.5\",\"size\":\"0.00000\"},{\"price\":\"63936.2\",\"size\":\"3.11371\"}],\"offset\":3903064,\"nonce\":36957508,\"last_updated_at\":1785276572256101,\"begin_nonce\":36957506},\"timestamp\":1785276572283,\"type\":\"update/order_book\"}"
        "raw": "{\"channel\":\"order_book:1\",\"last_updated_at\":1785276572529371,\"offset\":3903065,\"order_book\":{\"code\":0,\"asks\":[{\"price\":\"64003.6\",\"size\":\"0.00000\"},{\"price\":\"64004.4\",\"size\":\"3.12644\"}],\"bids\":[{\"price\":\"63936.3\",\"size\":\"3.11371\"},{\"price\":\"63936.2\",\"size\":\"0.00000\"}],\"offset\":3903065,\"nonce\":36957513,\"last_updated_at\":1785276572529371,\"begin_nonce\":36957508},\"timestamp\":1785276572533,\"type\":\"update/order_book\"}"
        "raw": "{\"channel\":\"order_book:1\",\"last_updated_at\":1785276572669990,\"offset\":3903066,\"order_book\":{\"code\":0,\"asks\":[],\"bids\":[{\"price\":\"63928.3\",\"size\":\"0.00149\"},{\"price\":\"63928.2\",\"size\":\"0.00000\"}],\"offset\":3903066,\"nonce\":36957516,\"last_updated_at\":1785276572669990,\"begin_nonce\":36957513},\"timestamp\":1785276572684,\"type\":\"update/order_book\"}"
        "raw": "{\"channel\":\"order_book:1\",\"last_updated_at\":1785276572832955,\"offset\":3903075,\"order_book\":{\"code\":0,\"asks\":[{\"price\":\"64011.6\",\"size\":\"0.00000\"}],\"bids\":[{\"price\":\"63928.3\",\"size\":\"0.00000\"}],\"offset\":3903075,\"nonce\":36957526,\"last_updated_at\":1785276572832955,\"begin_nonce\":36957516},\"timestamp\":1785276572833,\"type\":\"update/order_book\"}"
        "raw": "{\"channel\":\"order_book:1\",\"last_updated_at\":1785276572928590,\"offset\":3903077,\"order_book\":{\"code\":0,\"asks\":[{\"price\":\"64004.4\",\"size\":\"0.00000\"},{\"price\":\"64004.5\",\"size\":\"3.12644\"}],\"bids\":[{\"price\":\"63936.3\",\"size\":\"0.00000\"},{\"price\":\"63935.2\",\"size\":\"3.11371\"}],\"offset\":3903077,\"nonce\":36957531,\"last_updated_at\":1785276572928590,\"begin_nonce\":36957529},\"timestamp\":1785276572933,\"type\":\"update/order_book\"}"
        "raw": "{\"channel\":\"order_book:1\",\"last_updated_at\":1785276573032177,\"offset\":3903078,\"order_book\":{\"code\":0,\"asks\":[{\"price\":\"64008.4\",\"size\":\"0.00000\"}],\"bids\":[{\"price\":\"63925.1\",\"size\":\"0.00000\"}],\"offset\":3903078,\"nonce\":36957532,\"last_updated_at\":1785276573032177,\"begin_nonce\":36957531},\"timestamp\":1785276573033,\"type\":\"update/order_book\"}"
        "raw": "{\"channel\":\"order_book:1\",\"last_updated_at\":1785276573082794,\"offset\":3903085,\"order_book\":{\"code\":0,\"asks\":[{\"price\":\"64004.5\",\"size\":\"3.12667\"}],\"bids\":[{\"price\":\"63935.2\",\"size\":\"0.00000\"},{\"price\":\"63929.4\",\"size\":\"3.11394\"}],\"offset\":3903085,\"nonce\":36957540,\"last_updated_at\":1785276573082794,\"begin_nonce\":36957532},\"timestamp\":1785276573083,\"type\":\"update/order_book\"}"
        "raw": "{\"channel\":\"order_book:1\",\"last_updated_at\":1785276573279753,\"offset\":3903091,\"order_book\":{\"code\":0,\"asks\":[{\"price\":\"64002.3\",\"size\":\"3.12667\"},{\"price\":\"64004.5\",\"size\":\"0.00000\"}],\"bids\":[{\"price\":\"63929.4\",\"size\":\"0.00000\"},{\"price\":\"63927.7\",\"size\":\"3.11394\"}],\"offset\":3903091,\"nonce\":36957550,\"last_updated_at\":1785276573279753,\"begin_nonce\":36957547},\"timestamp\":1785276573284,\"type\":\"update/order_book\"}"
        "raw": "{\"channel\":\"order_book:1\",\"last_updated_at\":1785276573339912,\"offset\":3903092,\"order_book\":{\"code\":0,\"asks\":[],\"bids\":[{\"price\":\"63897.6\",\"size\":\"0.00000\"},{\"price\":\"63753.6\",\"size\":\"15.61039\"}],\"offset\":3903092,\"nonce\":36957554,\"last_updated_at\":1785276573339912,\"begin_nonce\":36957550},\"timestamp\":1785276573384,\"type\":\"update/order_book\"}"
        "raw": "{\"channel\":\"order_book:1\",\"last_updated_at\":1785276573430666,\"offset\":3903094,\"order_book\":{\"code\":0,\"asks\":[{\"price\":\"63999.0\",\"size\":\"3.12667\"},{\"price\":\"64002.3\",\"size\":\"0.00000\"}],\"bids\":[{\"price\":\"63927.7\",\"size\":\"0.00000\"},{\"price\":\"63926.2\",\"size\":\"3.11394\"}],\"offset\":3903094,\"nonce\":36957557,\"last_updated_at\":1785276573430666,\"begin_nonce\":36957554},\"timestamp\":1785276573433,\"type\":\"update/order_book\"}"
        "raw": "{\"channel\":\"order_book:1\",\"last_updated_at\":1785276573690715,\"offset\":3903095,\"order_book\":{\"code\":0,\"asks\":[{\"price\":\"64004.6\",\"size\":\"0.00000\"},{\"price\":\"64004.7\",\"size\":\"0.00163\"}],\"bids\":[],\"offset\":3903095,\"nonce\":36957562,\"last_updated_at\":1785276573690715,\"begin_nonce\":36957557},\"timestamp\":1785276573734,\"type\":\"update/order_book\"}"
        "raw": "{\"channel\":\"order_book:1\",\"last_updated_at\":1785276573936526,\"offset\":3903096,\"order_book\":{\"code\":0,\"asks\":[],\"bids\":[{\"price\":\"63926.3\",\"size\":\"3.11393\"},{\"price\":\"63926.2\",\"size\":\"0.00000\"}],\"offset\":3903096,\"nonce\":36957564,\"last_updated_at\":1785276573936526,\"begin_nonce\":36957562},\"timestamp\":1785276573983,\"type\":\"update/order_book\"}"
        "raw": "{\"channel\":\"order_book:1\",\"last_updated_at\":1785276574182256,\"offset\":3903097,\"order_book\":{\"code\":0,\"asks\":[],\"bids\":[{\"price\":\"63921.3\",\"size\":\"0.00000\"},{\"price\":\"63921.2\",\"size\":\"0.00149\"}],\"offset\":3903097,\"nonce\":36957567,\"last_updated_at\":1785276574182256,\"begin_nonce\":36957564},\"timestamp\":1785276574184,\"type\":\"update/order_book\"}"
        "raw": "{\"channel\":\"order_book:1\",\"last_updated_at\":1785276574459054,\"offset\":3903098,\"order_book\":{\"code\":0,\"asks\":[],\"bids\":[{\"price\":\"63926.3\",\"size\":\"0.00000\"},{\"price\":\"63925.9\",\"size\":\"3.11393\"}],\"offset\":3903098,\"nonce\":36957574,\"last_updated_at\":1785276574459054,\"begin_nonce\":36957567},\"timestamp\":1785276574484,\"type\":\"update/order_book\"}"
        "raw": "{\"channel\":\"order_book:1\",\"last_updated_at\":1785276574671913,\"offset\":3903099,\"order_book\":{\"code\":0,\"asks\":[],\"bids\":[{\"price\":\"63928.1\",\"size\":\"3.11393\"},{\"price\":\"63925.9\",\"size\":\"0.00000\"}],\"offset\":3903099,\"nonce\":36957576,\"last_updated_at\":1785276574671913,\"begin_nonce\":36957574},\"timestamp\":1785276574683,\"type\":\"update/order_book\"}"
        "raw": "{\"channel\":\"order_book:1\",\"last_updated_at\":1785276574921622,\"offset\":3903100,\"order_book\":{\"code\":0,\"asks\":[{\"price\":\"63999.0\",\"size\":\"0.00000\"},{\"price\":\"63999.1\",\"size\":\"3.12667\"}],\"bids\":[{\"price\":\"63928.1\",\"size\":\"0.00000\"},{\"price\":\"63925.8\",\"size\":\"3.11393\"}],\"offset\":3903100,\"nonce\":36957582,\"last_updated_at\":1785276574921622,\"begin_nonce\":36957576},\"timestamp\":1785276574934,\"type\":\"update/order_book\"}"
        "raw": "{\"channel\":\"order_book:1\",\"last_updated_at\":1785276575223584,\"offset\":3903102,\"order_book\":{\"code\":0,\"asks\":[],\"bids\":[{\"price\":\"63921.2\",\"size\":\"0.00000\"},{\"price\":\"63921.1\",\"size\":\"0.00149\"}],\"offset\":3903102,\"nonce\":36957585,\"last_updated_at\":1785276575223584,\"begin_nonce\":36957582},\"timestamp\":1785276575234,\"type\":\"update/order_book\"}"
        "raw": "{\"channel\":\"order_book:1\",\"last_updated_at\":1785276575233495,\"offset\":3903103,\"order_book\":{\"code\":0,\"asks\":[{\"price\":\"63999.1\",\"size\":\"3.12666\"}],\"bids\":[{\"price\":\"63932.2\",\"size\":\"3.11393\"},{\"price\":\"63925.8\",\"size\":\"0.00000\"}],\"offset\":3903103,\"nonce\":36957587,\"last_updated_at\":1785276575233495,\"begin_nonce\":36957585},\"timestamp\":1785276575284,\"type\":\"update/order_book\"}"
        "raw": "{\"channel\":\"order_book:1\",\"last_updated_at\":1785276575418420,\"offset\":3903104,\"order_book\":{\"code\":0,\"asks\":[],\"bids\":[{\"price\":\"63960.0\",\"size\":\"0.00093\"}],\"offset\":3903104,\"nonce\":36957592,\"last_updated_at\":1785276575418420,\"begin_nonce\":36957587},\"timestamp\":1785276575434,\"type\":\"update/order_book\"}"
        "raw": "{\"channel\":\"order_book:1\",\"last_updated_at\":1785276575445805,\"offset\":3903105,\"order_book\":{\"code\":0,\"asks\":[{\"price\":\"63999.1\",\"size\":\"0.00000\"},{\"price\":\"63999.2\",\"size\":\"3.12690\"}],\"bids\":[{\"price\":\"63932.2\",\"size\":\"0.00000\"},{\"price\":\"63924.8\",\"size\":\"3.11417\"}],\"offset\":3903105,\"nonce\":36957593,\"last_updated_at\":1785276575445805,\"begin_nonce\":36957592},\"timestamp\":1785276575483,\"type\":\"update/order_book\"}"
        "raw": "{\"channel\":\"order_book:1\",\"last_updated_at\":1785276575487703,\"offset\":3903108,\"order_book\":{\"code\":0,\"asks\":[{\"price\":\"64002.1\",\"size\":\"0.00163\"},{\"price\":\"64004.7\",\"size\":\"0.00000\"}],\"bids\":[{\"price\":\"63921.1\",\"size\":\"0.00000\"},{\"price\":\"63918.5\",\"size\":\"0.00149\"}],\"offset\":3903108,\"nonce\":36957597,\"last_updated_at\":1785276575487703,\"begin_nonce\":36957593},\"timestamp\":1785276575533,\"type\":\"update/order_book\"}"
        "raw": "{\"channel\":\"order_book:1\",\"last_updated_at\":1785276575583491,\"offset\":3903111,\"order_book\":{\"code\":0,\"asks\":[{\"price\":\"64001.8\",\"size\":\"0.00163\"},{\"price\":\"64002.1\",\"size\":\"0.00000\"}],\"bids\":[{\"price\":\"63918.5\",\"size\":\"0.00000\"}],\"offset\":3903111,\"nonce\":36957600,\"last_updated_at\":1785276575583491,\"begin_nonce\":36957597},\"timestamp\":1785276575584,\"type\":\"update/order_book\"}"
        "raw": "{\"channel\":\"order_book:1\",\"last_updated_at\":1785276575623102,\"offset\":3903116,\"order_book\":{\"code\":0,\"asks\":[{\"price\":\"63999.0\",\"size\":\"3.12698\"},{\"price\":\"63999.2\",\"size\":\"0.00000\"},{\"price\":\"64000.9\",\"size\":\"0.00163\"},{\"price\":\"64001.8\",\"size\":\"0.00000\"}],\"bids\":[{\"price\":\"63924.8\",\"size\":\"0.00000\"},{\"price\":\"63922.5\",\"size\":\"3.11425\"},{\"price\":\"63917.3\",\"size\":\"0.00149\"}],\"offset\":3903116,\"nonce\":36957605,\"last_updated_at\":1785276575623102,\"begin_nonce\":36957600},\"timestamp\":1785276575634,\"type\":\"update/order_book\"}"
        "raw": "{\"channel\":\"order_book:1\",\"last_updated_at\":1785276575754713,\"offset\":3903117,\"order_book\":{\"code\":0,\"asks\":[{\"price\":\"63999.0\",\"size\":\"0.00000\"},{\"price\":\"64000.7\",\"size\":\"3.12698\"}],\"bids\":[{\"price\":\"63922.5\",\"size\":\"0.00000\"},{\"price\":\"63920.9\",\"size\":\"3.11425\"}],\"offset\":3903117,\"nonce\":36957612,\"last_updated_at\":1785276575754713,\"begin_nonce\":36957605},\"timestamp\":1785276575783,\"type\":\"update/order_book\"}"
        "raw": "{\"channel\":\"order_book:1\",\"last_updated_at\":1785276575923752,\"offset\":3903119,\"order_book\":{\"code\":0,\"asks\":[],\"bids\":[{\"price\":\"63917.3\",\"size\":\"0.00000\"},{\"price\":\"63917.2\",\"size\":\"0.00149\"}],\"offset\":3903119,\"nonce\":36957615,\"last_updated_at\":1785276575923752,\"begin_nonce\":36957612},\"timestamp\":1785276575944,\"type\":\"update/order_book\"}"
        "raw": "{\"channel\":\"order_book:1\",\"last_updated_at\":1785276575934863,\"offset\":3903120,\"order_book\":{\"code\":0,\"asks\":[{\"price\":\"63996.6\",\"size\":\"3.12698\"},{\"price\":\"64000.7\",\"size\":\"0.00000\"}],\"bids\":[{\"price\":\"63922.2\",\"size\":\"3.11425\"},{\"price\":\"63920.9\",\"size\":\"0.00000\"}],\"offset\":3903120,\"nonce\":36957618,\"last_updated_at\":1785276575934863,\"begin_nonce\":36957615},\"timestamp\":1785276575983,\"type\":\"update/order_book\"}"
        "raw": "{\"channel\":\"order_book:1\",\"last_updated_at\":1785276576183573,\"offset\":3903122,\"order_book\":{\"code\":0,\"asks\":[{\"price\":\"64000.9\",\"size\":\"0.00000\"},{\"price\":\"64001.0\",\"size\":\"0.00163\"}],\"bids\":[],\"offset\":3903122,\"nonce\":36957622,\"last_updated_at\":1785276576183573,\"begin_nonce\":36957618},\"timestamp\":1785276576184,\"type\":\"update/order_book\"}"
        "raw": "{\"channel\":\"order_book:1\",\"last_updated_at\":1785276576195899,\"offset\":3903123,\"order_book\":{\"code\":0,\"asks\":[{\"price\":\"63996.6\",\"size\":\"0.00000\"},{\"price\":\"63997.2\",\"size\":\"3.12698\"}],\"bids\":[{\"price\":\"63922.2\",\"size\":\"0.00000\"},{\"price\":\"63921.6\",\"size\":\"3.11425\"}],\"offset\":3903123,\"nonce\":36957626,\"last_updated_at\":1785276576195899,\"begin_nonce\":36957622},\"timestamp\":1785276576234,\"type\":\"update/order_book\"}"
        "raw": "{\"channel\":\"order_book:1\",\"last_updated_at\":1785276576420354,\"offset\":3903124,\"order_book\":{\"code\":0,\"asks\":[{\"price\":\"63996.7\",\"size\":\"3.12698\"},{\"price\":\"63997.2\",\"size\":\"0.00000\"}],\"bids\":[{\"price\":\"63922.3\",\"size\":\"3.11424\"},{\"price\":\"63921.6\",\"size\":\"0.00000\"}],\"offset\":3903124,\"nonce\":36957631,\"last_updated_at\":1785276576420354,\"begin_nonce\":36957626},\"timestamp\":1785276576434,\"type\":\"update/order_book\"}"
        "raw": "{\"channel\":\"order_book:1\",\"last_updated_at\":1785276576510666,\"offset\":3903125,\"order_book\":{\"code\":0,\"asks\":[],\"bids\":[{\"price\":\"63917.2\",\"size\":\"0.00000\"},{\"price\":\"63917.1\",\"size\":\"0.00149\"}],\"offset\":3903125,\"nonce\":36957634,\"last_updated_at\":1785276576510666,\"begin_nonce\":36957631},\"timestamp\":1785276576534,\"type\":\"update/order_book\"}"
        "raw": "{\"channel\":\"order_book:1\",\"last_updated_at\":1785276576681530,\"offset\":3903126,\"order_book\":{\"code\":0,\"asks\":[],\"bids\":[{\"price\":\"63960.0\",\"size\":\"0.00000\"}],\"offset\":3903126,\"nonce\":36957637,\"last_updated_at\":1785276576681530,\"begin_nonce\":36957634},\"timestamp\":1785276576683,\"type\":\"update/order_book\"}"
        "raw": "{\"channel\":\"order_book:1\",\"last_updated_at\":1785276576930284,\"offset\":3903127,\"order_book\":{\"code\":0,\"asks\":[{\"price\":\"63996.4\",\"size\":\"3.12698\"},{\"price\":\"63996.7\",\"size\":\"0.00000\"}],\"bids\":[{\"price\":\"63922.5\",\"size\":\"3.11424\"},{\"price\":\"63922.3\",\"size\":\"0.00000\"}],\"offset\":3903127,\"nonce\":36957639,\"last_updated_at\":1785276576930284,\"begin_nonce\":36957637},\"timestamp\":1785276576933,\"type\":\"update/order_book\"}"
        "raw": "{\"channel\":\"order_book:1\",\"last_updated_at\":1785276577137031,\"offset\":3903128,\"order_book\":{\"code\":0,\"asks\":[{\"price\":\"64020.0\",\"size\":\"0.00000\"}],\"bids\":[],\"offset\":3903128,\"nonce\":36957641,\"last_updated_at\":1785276577137031,\"begin_nonce\":36957639},\"timestamp\":1785276577183,\"type\":\"update/order_book\"}"
        "raw": "{\"channel\":\"order_book:1\",\"last_updated_at\":1785276577332279,\"offset\":3903131,\"order_book\":{\"code\":0,\"asks\":[{\"price\":\"63993.4\",\"size\":\"3.12698\"},{\"price\":\"63996.4\",\"size\":\"0.00000\"},{\"price\":\"64022.4\",\"size\":\"15.62740\"},{\"price\":\"64032.0\",\"size\":\"15.62740\"},{\"price\":\"64041.6\",\"size\":\"15.62740\"},{\"price\":\"64166.4\",\"size\":\"0.00000\"},{\"price\":\"64176.0\",\"size\":\"0.00000\"},{\"price\":\"64185.6\",\"size\":\"0.00000\"}],\"bids\":[{\"price\":\"63923.5\",\"size\":\"3.11424\"},{\"price\":\"63922.5\",\"size\":\"0.00000\"}],\"offset\":3903131,\"nonce\":36957645,\"last_updated_at\":1785276577332279,\"begin_nonce\":36957641},\"timestamp\":1785276577334,\"type\":\"update/order_book\"}"
        "raw": "{\"channel\":\"order_book:1\",\"last_updated_at\":1785276577443393,\"offset\":3903133,\"order_book\":{\"code\":0,\"asks\":[{\"price\":\"64001.0\",\"size\":\"0.00000\"},{\"price\":\"64001.1\",\"size\":\"0.00163\"}],\"bids\":[],\"offset\":3903133,\"nonce\":36957648,\"last_updated_at\":1785276577443393,\"begin_nonce\":36957645},\"timestamp\":1785276577484,\"type\":\"update/order_book\"}"
        "raw": "{\"channel\":\"order_book:1\",\"last_updated_at\":1785276577545429,\"offset\":3903134,\"order_book\":{\"code\":0,\"asks\":[{\"price\":\"63992.6\",\"size\":\"3.12698\"},{\"price\":\"63993.4\",\"size\":\"0.00000\"}],\"bids\":[{\"price\":\"63923.5\",\"size\":\"0.00000\"},{\"price\":\"63922.6\",\"size\":\"3.11424\"}],\"offset\":3903134,\"nonce\":36957650,\"last_updated_at\":1785276577545429,\"begin_nonce\":36957648},\"timestamp\":1785276577584,\"type\":\"update/order_book\"}"
        "raw": "{\"channel\":\"order_book:1\",\"last_updated_at\":1785276577720357,\"offset\":3903135,\"order_book\":{\"code\":0,\"asks\":[],\"bids\":[{\"price\":\"63925.8\",\"size\":\"3.11424\"},{\"price\":\"63922.6\",\"size\":\"0.00000\"}],\"offset\":3903135,\"nonce\":36957651,\"last_updated_at\":1785276577720357,\"begin_nonce\":36957650},\"timestamp\":1785276577734,\"type\":\"update/order_book\"}"
        "raw": "{\"channel\":\"order_book:1\",\"last_updated_at\":1785276578014822,\"offset\":3903137,\"order_book\":{\"code\":0,\"asks\":[],\"bids\":[{\"price\":\"63917.2\",\"size\":\"0.00149\"},{\"price\":\"63917.1\",\"size\":\"0.00000\"}],\"offset\":3903137,\"nonce\":36957653,\"last_updated_at\":1785276578014822,\"begin_nonce\":36957651},\"timestamp\":1785276578034,\"type\":\"update/order_book\"}"
        "raw": "{\"channel\":\"order_book:1\",\"last_updated_at\":1785276578284247,\"offset\":3903138,\"order_book\":{\"code\":0,\"asks\":[{\"price\":\"63992.6\",\"size\":\"0.00000\"},{\"price\":\"63992.8\",\"size\":\"3.12698\"}],\"bids\":[{\"price\":\"63925.8\",\"size\":\"0.00000\"},{\"price\":\"63925.7\",\"size\":\"3.11424\"}],\"offset\":3903138,\"nonce\":36957654,\"last_updated_at\":1785276578284247,\"begin_nonce\":36957653},\"timestamp\":1785276578333,\"type\":\"update/order_book\"}"
        "raw": "{\"channel\":\"order_book:1\",\"last_updated_at\":1785276578562695,\"offset\":3903139,\"order_book\":{\"code\":0,\"asks\":[],\"bids\":[{\"price\":\"63580.0\",\"size\":\"0.00100\"}],\"offset\":3903139,\"nonce\":36957655,\"last_updated_at\":1785276578562695,\"begin_nonce\":36957654},\"timestamp\":1785276578584,\"type\":\"update/order_book\"}"
        "raw": "{\"channel\":\"order_book:1\",\"last_updated_at\":1785276578787668,\"offset\":3903140,\"order_book\":{\"code\":0,\"asks\":[{\"price\":\"63992.6\",\"size\":\"3.12698\"},{\"price\":\"63992.8\",\"size\":\"0.00000\"}],\"bids\":[{\"price\":\"63925.8\",\"size\":\"3.11424\"},{\"price\":\"63925.7\",\"size\":\"0.00000\"}],\"offset\":3903140,\"nonce\":36957657,\"last_updated_at\":1785276578787668,\"begin_nonce\":36957655},\"timestamp\":1785276578834,\"type\":\"update/order_book\"}"
        "raw": "{\"channel\":\"order_book:1\",\"last_updated_at\":1785276578961439,\"offset\":3903142,\"order_book\":{\"code\":0,\"asks\":[{\"price\":\"64001.1\",\"size\":\"0.00000\"},{\"price\":\"64001.2\",\"size\":\"0.00163\"}],\"bids\":[],\"offset\":3903142,\"nonce\":36957659,\"last_updated_at\":1785276578961439,\"begin_nonce\":36957657},\"timestamp\":1785276578984,\"type\":\"update/order_book\"}"
        "raw": "{\"channel\":\"order_book:1\",\"last_updated_at\":1785276579027871,\"offset\":3903143,\"order_book\":{\"code\":0,\"asks\":[{\"price\":\"64000.0\",\"size\":\"0.00100\"}],\"bids\":[],\"offset\":3903143,\"nonce\":36957660,\"last_updated_at\":1785276579027871,\"begin_nonce\":36957659},\"timestamp\":1785276579034,\"type\":\"update/order_book\"}"
        "raw": "{\"channel\":\"order_book:1\",\"last_updated_at\":1785276579142042,\"offset\":3903145,\"order_book\":{\"code\":0,\"asks\":[],\"bids\":[{\"price\":\"63917.3\",\"size\":\"0.00149\"},{\"price\":\"63917.2\",\"size\":\"0.00000\"}],\"offset\":3903145,\"nonce\":36957662,\"last_updated_at\":1785276579142042,\"begin_nonce\":36957660},\"timestamp\":1785276579184,\"type\":\"update/order_book\"}"
        "raw": "{\"channel\":\"order_book:1\",\"last_updated_at\":1785276579306607,\"offset\":3903146,\"order_book\":{\"code\":0,\"asks\":[{\"price\":\"63992.6\",\"size\":\"0.00000\"},{\"price\":\"63992.8\",\"size\":\"3.12698\"}],\"bids\":[{\"price\":\"63925.8\",\"size\":\"0.00000\"},{\"price\":\"63925.7\",\"size\":\"3.11424\"}],\"offset\":3903146,\"nonce\":36957664,\"last_updated_at\":1785276579306607,\"begin_nonce\":36957662},\"timestamp\":1785276579333,\"type\":\"update/order_book\"}"
        "raw": "{\"channel\":\"order_book:1\",\"last_updated_at\":1785276579864904,\"offset\":3903147,\"order_book\":{\"code\":0,\"asks\":[{\"price\":\"63992.7\",\"size\":\"3.12698\"},{\"price\":\"63992.8\",\"size\":\"0.00000\"}],\"bids\":[{\"price\":\"63925.8\",\"size\":\"3.11424\"},{\"price\":\"63925.7\",\"size\":\"0.00000\"}],\"offset\":3903147,\"nonce\":36957666,\"last_updated_at\":1785276579864904,\"begin_nonce\":36957664},\"timestamp\":1785276579884,\"type\":\"update/order_book\"}"
        "raw": "{\"channel\":\"order_book:1\",\"last_updated_at\":1785276580242055,\"offset\":3903149,\"order_book\":{\"code\":0,\"asks\":[],\"bids\":[{\"price\":\"63917.4\",\"size\":\"0.00149\"},{\"price\":\"63917.3\",\"size\":\"0.00000\"}],\"offset\":3903149,\"nonce\":36957669,\"last_updated_at\":1785276580242055,\"begin_nonce\":36957666},\"timestamp\":1785276580284,\"type\":\"update/order_book\"}"
        "raw": "{\"channel\":\"order_book:1\",\"last_updated_at\":1785276580372237,\"offset\":3903150,\"order_book\":{\"code\":0,\"asks\":[{\"price\":\"63992.6\",\"size\":\"3.12698\"},{\"price\":\"63992.7\",\"size\":\"0.00000\"}],\"bids\":[{\"price\":\"63925.9\",\"size\":\"3.11424\"},{\"price\":\"63925.8\",\"size\":\"0.00000\"}],\"offset\":3903150,\"nonce\":36957670,\"last_updated_at\":1785276580372237,\"begin_nonce\":36957669},\"timestamp\":1785276580383,\"type\":\"update/order_book\"}"
        "raw": "{\"channel\":\"order_book:1\",\"last_updated_at\":1785276580876990,\"offset\":3903153,\"order_book\":{\"code\":0,\"asks\":[{\"price\":\"63992.6\",\"size\":\"0.00000\"},{\"price\":\"63992.7\",\"size\":\"3.12698\"},{\"price\":\"64000.3\",\"size\":\"0.00163\"},{\"price\":\"64001.2\",\"size\":\"0.00000\"}],\"bids\":[{\"price\":\"63925.9\",\"size\":\"0.00000\"},{\"price\":\"63925.7\",\"size\":\"3.11425\"},{\"price\":\"63917.4\",\"size\":\"0.00000\"},{\"price\":\"63916.5\",\"size\":\"0.00149\"}],\"offset\":3903153,\"nonce\":36957674,\"last_updated_at\":1785276580876990,\"begin_nonce\":36957670},\"timestamp\":1785276580884,\"type\":\"update/order_book\"}"
        "raw": "{\"channel\":\"order_book:1\",\"last_updated_at\":1785276581001455,\"offset\":3903155,\"order_book\":{\"code\":0,\"asks\":[{\"price\":\"64000.3\",\"size\":\"0.00000\"},{\"price\":\"64000.4\",\"size\":\"0.00163\"}],\"bids\":[],\"offset\":3903155,\"nonce\":36957678,\"last_updated_at\":1785276581001455,\"begin_nonce\":36957674},\"timestamp\":1785276581033,\"type\":\"update/order_book\"}"
        "raw": "{\"channel\":\"order_book:1\",\"last_updated_at\":1785276581382613,\"offset\":3903156,\"order_book\":{\"code\":0,\"asks\":[{\"price\":\"63992.6\",\"size\":\"3.12698\"},{\"price\":\"63992.7\",\"size\":\"0.00000\"}],\"bids\":[{\"price\":\"63925.8\",\"size\":\"3.11425\"},{\"price\":\"63925.7\",\"size\":\"0.00000\"}],\"offset\":3903156,\"nonce\":36957681,\"last_updated_at\":1785276581382613,\"begin_nonce\":36957678},\"timestamp\":1785276581383,\"type\":\"update/order_book\"}"
        "raw": "{\"channel\":\"order_book:1\",\"last_updated_at\":1785276581473473,\"offset\":3903158,\"order_book\":{\"code\":0,\"asks\":[],\"bids\":[{\"price\":\"63916.6\",\"size\":\"0.00149\"},{\"price\":\"63916.5\",\"size\":\"0.00000\"}],\"offset\":3903158,\"nonce\":36957684,\"last_updated_at\":1785276581473473,\"begin_nonce\":36957681},\"timestamp\":1785276581483,\"type\":\"update/order_book\"}"
        "raw": "{\"channel\":\"order_book:1\",\"last_updated_at\":1785276581935028,\"offset\":3903159,\"order_book\":{\"code\":0,\"asks\":[{\"price\":\"63992.6\",\"size\":\"0.00000\"},{\"price\":\"63992.7\",\"size\":\"3.12698\"}],\"bids\":[{\"price\":\"63925.8\",\"size\":\"3.11424\"}],\"offset\":3903159,\"nonce\":36957689,\"last_updated_at\":1785276581935028,\"begin_nonce\":36957684},\"timestamp\":1785276581984,\"type\":\"update/order_book\"}"
        "raw": "{\"channel\":\"order_book:1\",\"last_updated_at\":1785276582447742,\"offset\":3903161,\"order_book\":{\"code\":0,\"asks\":[],\"bids\":[{\"price\":\"63940.0\",\"size\":\"0.00096\"},{\"price\":\"63925.8\",\"size\":\"0.00000\"},{\"price\":\"63925.7\",\"size\":\"3.11424\"}],\"offset\":3903161,\"nonce\":36957693,\"last_updated_at\":1785276582447742,\"begin_nonce\":36957689},\"timestamp\":1785276582484,\"type\":\"update/order_book\"}"
        "raw": "{\"channel\":\"order_book:1\",\"last_updated_at\":1785276582955026,\"offset\":3903162,\"order_book\":{\"code\":0,\"asks\":[],\"bids\":[{\"price\":\"63925.7\",\"size\":\"3.11425\"}],\"offset\":3903162,\"nonce\":36957699,\"last_updated_at\":1785276582955026,\"begin_nonce\":36957693},\"timestamp\":1785276582984,\"type\":\"update/order_book\"}"
        "raw": "{\"channel\":\"order_book:1\",\"last_updated_at\":1785276583117273,\"offset\":3903164,\"order_book\":{\"code\":0,\"asks\":[{\"price\":\"64000.4\",\"size\":\"0.00000\"},{\"price\":\"64000.5\",\"size\":\"0.00163\"}],\"bids\":[],\"offset\":3903164,\"nonce\":36957702,\"last_updated_at\":1785276583117273,\"begin_nonce\":36957699},\"timestamp\":1785276583133,\"type\":\"update/order_book\"}"
        "raw": "{\"channel\":\"order_book:1\",\"last_updated_at\":1785276583230584,\"offset\":3903165,\"order_book\":{\"code\":0,\"asks\":[],\"bids\":[{\"price\":\"63916.6\",\"size\":\"0.00000\"}],\"offset\":3903165,\"nonce\":36957704,\"last_updated_at\":1785276583230584,\"begin_nonce\":36957702},\"timestamp\":1785276583234,\"type\":\"update/order_book\"}"
        "raw": "{\"channel\":\"order_book:1\",\"last_updated_at\":1785276583281302,\"offset\":3903168,\"order_book\":{\"code\":0,\"asks\":[{\"price\":\"64000.5\",\"size\":\"0.00000\"}],\"bids\":[],\"offset\":3903168,\"nonce\":36957707,\"last_updated_at\":1785276583281302,\"begin_nonce\":36957704},\"timestamp\":1785276583284,\"type\":\"update/order_book\"}"
        "raw": "{\"channel\":\"order_book:1\",\"last_updated_at\":1785276583468790,\"offset\":3903171,\"order_book\":{\"code\":0,\"asks\":[{\"price\":\"63992.6\",\"size\":\"3.12698\"},{\"price\":\"63992.7\",\"size\":\"0.00000\"}],\"bids\":[{\"price\":\"63925.8\",\"size\":\"3.11425\"},{\"price\":\"63925.7\",\"size\":\"0.00000\"}],\"offset\":3903171,\"nonce\":36957713,\"last_updated_at\":1785276583468790,\"begin_nonce\":36957710},\"timestamp\":1785276583483,\"type\":\"update/order_book\"}"
        "raw": "{\"channel\":\"order_book:1\",\"last_updated_at\":1785276583984146,\"offset\":3903172,\"order_book\":{\"code\":0,\"asks\":[{\"price\":\"63992.6\",\"size\":\"0.00000\"},{\"price\":\"63992.7\",\"size\":\"3.12699\"}],\"bids\":[{\"price\":\"63925.8\",\"size\":\"0.00000\"},{\"price\":\"63925.7\",\"size\":\"3.11425\"}],\"offset\":3903172,\"nonce\":36957718,\"last_updated_at\":1785276583984146,\"begin_nonce\":36957713},\"timestamp\":1785276583987,\"type\":\"update/order_book\"}"
        "raw": "{\"channel\":\"order_book:1\",\"last_updated_at\":1785276584229929,\"offset\":3903173,\"order_book\":{\"code\":0,\"asks\":[{\"price\":\"63992.3\",\"size\":\"3.12701\"},{\"price\":\"63992.7\",\"size\":\"0.00000\"}],\"bids\":[{\"price\":\"63925.7\",\"size\":\"0.00000\"},{\"price\":\"63924.9\",\"size\":\"3.11427\"}],\"offset\":3903173,\"nonce\":36957720,\"last_updated_at\":1785276584229929,\"begin_nonce\":36957718},\"timestamp\":1785276584234,\"type\":\"update/order_book\"}"
        "raw": "{\"channel\":\"order_book:1\",\"last_updated_at\":1785276584301385,\"offset\":3903175,\"order_book\":{\"code\":0,\"asks\":[],\"bids\":[{\"price\":\"63916.3\",\"size\":\"0.00149\"},{\"price\":\"63916.2\",\"size\":\"0.00000\"}],\"offset\":3903175,\"nonce\":36957723,\"last_updated_at\":1785276584301385,\"begin_nonce\":36957720},\"timestamp\":1785276584333,\"type\":\"update/order_book\"}"
        "raw": "{\"channel\":\"order_book:1\",\"last_updated_at\":1785276584445923,\"offset\":3903176,\"order_book\":{\"code\":0,\"asks\":[{\"price\":\"63990.6\",\"size\":\"3.12709\"},{\"price\":\"63992.3\",\"size\":\"0.00000\"}],\"bids\":[{\"price\":\"63924.9\",\"size\":\"0.00000\"},{\"price\":\"63922.6\",\"size\":\"3.11435\"}],\"offset\":3903176,\"nonce\":36957725,\"last_updated_at\":1785276584445923,\"begin_nonce\":36957723},\"timestamp\":1785276584484,\"type\":\"update/order_book\"}"
        "raw": "{\"channel\":\"order_book:1\",\"last_updated_at\":1785276584582939,\"offset\":3903185,\"order_book\":{\"code\":0,\"asks\":[{\"price\":\"63988.8\",\"size\":\"3.12717\"},{\"price\":\"63990.6\",\"size\":\"0.00000\"},{\"price\":\"63996.8\",\"size\":\"0.00163\"},{\"price\":\"64000.0\",\"size\":\"0.00100\"}],\"bids\":[{\"price\":\"63922.6\",\"size\":\"0.00000\"},{\"price\":\"63920.1\",\"size\":\"3.11443\"},{\"price\":\"63916.3\",\"size\":\"0.00000\"}],\"offset\":3903185,\"nonce\":36957735,\"last_updated_at\":1785276584582939,\"begin_nonce\":36957725},\"timestamp\":1785276584583,\"type\":\"update/order_book\"}"
        "raw": "{\"channel\":\"order_book:1\",\"last_updated_at\":1785276584597221,\"offset\":3903189,\"order_book\":{\"code\":0,\"asks\":[{\"price\":\"63995.8\",\"size\":\"0.00163\"},{\"price\":\"63996.8\",\"size\":\"0.00000\"}],\"bids\":[{\"price\":\"63912.1\",\"size\":\"0.00149\"}],\"offset\":3903189,\"nonce\":36957739,\"last_updated_at\":1785276584597221,\"begin_nonce\":36957735},\"timestamp\":1785276584634,\"type\":\"update/order_book\"}"
        "raw": "{\"channel\":\"order_book:1\",\"last_updated_at\":1785276584751796,\"offset\":3903191,\"order_book\":{\"code\":0,\"asks\":[{\"price\":\"63988.8\",\"size\":\"0.00000\"},{\"price\":\"63992.6\",\"size\":\"3.12717\"}],\"bids\":[],\"offset\":3903191,\"nonce\":36957743,\"last_updated_at\":1785276584751796,\"begin_nonce\":36957739},\"timestamp\":1785276584783,\"type\":\"update/order_book\"}"
        "raw": "{\"channel\":\"order_book:1\",\"last_updated_at\":1785276585303661,\"offset\":3903193,\"order_book\":{\"code\":0,\"asks\":[{\"price\":\"63992.6\",\"size\":\"0.00000\"},{\"price\":\"63993.0\",\"size\":\"3.12717\"}],\"bids\":[{\"price\":\"63920.1\",\"size\":\"0.00000\"},{\"price\":\"63919.8\",\"size\":\"3.11443\"}],\"offset\":3903193,\"nonce\":36957752,\"last_updated_at\":1785276585303661,\"begin_nonce\":36957743},\"timestamp\":1785276585333,\"type\":\"update/order_book\"}"
        "raw": "{\"channel\":\"order_book:1\",\"last_updated_at\":1785276585472929,\"offset\":3903194,\"order_book\":{\"code\":0,\"asks\":[{\"price\":\"63991.6\",\"size\":\"3.12717\"},{\"price\":\"63993.0\",\"size\":\"0.00000\"}],\"bids\":[{\"price\":\"63920.0\",\"size\":\"3.11543\"},{\"price\":\"63919.8\",\"size\":\"0.00000\"}],\"offset\":3903194,\"nonce\":36957754,\"last_updated_at\":1785276585472929,\"begin_nonce\":36957752},\"timestamp\":1785276585483,\"type\":\"update/order_book\"}"
        "raw": "{\"channel\":\"order_book:1\",\"last_updated_at\":1785276585568351,\"offset\":3903195,\"order_book\":{\"code\":0,\"asks\":[],\"bids\":[{\"price\":\"63888.0\",\"size\":\"0.00000\"},{\"price\":\"63744.0\",\"size\":\"15.61303\"}],\"offset\":3903195,\"nonce\":36957757,\"last_updated_at\":1785276585568351,\"begin_nonce\":36957754},\"timestamp\":1785276585583,\"type\":\"update/order_book\"}"
        "raw": "{\"channel\":\"order_book:1\",\"last_updated_at\":1785276585648498,\"offset\":3903196,\"order_book\":{\"code\":0,\"asks\":[{\"price\":\"63991.5\",\"size\":\"3.12732\"},{\"price\":\"63991.6\",\"size\":\"0.00000\"}],\"bids\":[{\"price\":\"63920.0\",\"size\":\"0.00100\"},{\"price\":\"63915.5\",\"size\":\"3.11458\"}],\"offset\":3903196,\"nonce\":36957758,\"last_updated_at\":1785276585648498,\"begin_nonce\":36957757},\"timestamp\":1785276585683,\"type\":\"update/order_book\"}"
        "raw": "{\"channel\":\"order_book:1\",\"last_updated_at\":1785276586158576,\"offset\":3903197,\"order_book\":{\"code\":0,\"asks\":[{\"price\":\"63991.5\",\"size\":\"0.00000\"},{\"price\":\"63991.9\",\"size\":\"3.12732\"}],\"bids\":[{\"price\":\"63915.5\",\"size\":\"0.00000\"},{\"price\":\"63915.1\",\"size\":\"3.11458\"}],\"offset\":3903197,\"nonce\":36957765,\"last_updated_at\":1785276586158576,\"begin_nonce\":36957758},\"timestamp\":1785276586183,\"type\":\"update/order_book\"}"
        "raw": "{\"channel\":\"order_book:1\",\"last_updated_at\":1785276586396317,\"offset\":3903198,\"order_book\":{\"code\":0,\"asks\":[{\"price\":\"63991.0\",\"size\":\"3.12732\"},{\"price\":\"63991.9\",\"size\":\"0.00000\"}],\"bids\":[{\"price\":\"63915.8\",\"size\":\"3.11458\"},{\"price\":\"63915.1\",\"size\":\"0.00000\"}],\"offset\":3903198,\"nonce\":36957767,\"last_updated_at\":1785276586396317,\"begin_nonce\":36957765},\"timestamp\":1785276586434,\"type\":\"update/order_book\"}"
        "raw": "{\"channel\":\"order_book:1\",\"last_updated_at\":1785276586452461,\"offset\":3903199,\"order_book\":{\"code\":0,\"asks\":[{\"price\":\"63995.8\",\"size\":\"0.00000\"},{\"price\":\"63995.9\",\"size\":\"0.00163\"}],\"bids\":[],\"offset\":3903199,\"nonce\":36957769,\"last_updated_at\":1785276586452461,\"begin_nonce\":36957767},\"timestamp\":1785276586484,\"type\":\"update/order_book\"}"
        "raw": "{\"channel\":\"order_book:1\",\"last_updated_at\":1785276586519214,\"offset\":3903200,\"order_book\":{\"code\":0,\"asks\":[{\"price\":\"63987.7\",\"size\":\"3.12732\"},{\"price\":\"63991.0\",\"size\":\"0.00000\"}],\"bids\":[{\"price\":\"63916.3\",\"size\":\"3.11458\"},{\"price\":\"63915.8\",\"size\":\"0.00000\"}],\"offset\":3903200,\"nonce\":36957770,\"last_updated_at\":1785276586519214,\"begin_nonce\":36957769},\"timestamp\":1785276586533,\"type\":\"update/order_book\"}"
        "raw": "{\"channel\":\"order_book:1\",\"last_updated_at\":1785276586695527,\"offset\":3903202,\"order_book\":{\"code\":0,\"asks\":[],\"bids\":[{\"price\":\"63912.2\",\"size\":\"0.00149\"},{\"price\":\"63912.1\",\"size\":\"0.00000\"}],\"offset\":3903202,\"nonce\":36957774,\"last_updated_at\":1785276586695527,\"begin_nonce\":36957770},\"timestamp\":1785276586734,\"type\":\"update/order_book\"}"
        "raw": "{\"channel\":\"order_book:1\",\"last_updated_at\":1785276586734976,\"offset\":3903203,\"order_book\":{\"code\":0,\"asks\":[{\"price\":\"63987.7\",\"size\":\"0.00000\"},{\"price\":\"63988.9\",\"size\":\"3.12732\"}],\"bids\":[{\"price\":\"63917.4\",\"size\":\"3.11458\"},{\"price\":\"63916.3\",\"size\":\"0.00000\"}],\"offset\":3903203,\"nonce\":36957775,\"last_updated_at\":1785276586734976,\"begin_nonce\":36957774},\"timestamp\":1785276586784,\"type\":\"update/order_book\"}"
        "raw": "{\"channel\":\"order_book:1\",\"last_updated_at\":1785276587559663,\"offset\":3903204,\"order_book\":{\"code\":0,\"asks\":[{\"price\":\"63985.7\",\"size\":\"3.12732\"},{\"price\":\"63988.9\",\"size\":\"0.00000\"}],\"bids\":[{\"price\":\"63919.0\",\"size\":\"3.11458\"},{\"price\":\"63917.4\",\"size\":\"0.00000\"}],\"offset\":3903204,\"nonce\":36957783,\"last_updated_at\":1785276587559663,\"begin_nonce\":36957775},\"timestamp\":1785276587584,\"type\":\"update/order_book\"}"
        "raw": "{\"channel\":\"order_book:1\",\"last_updated_at\":1785276588066941,\"offset\":3903205,\"order_book\":{\"code\":0,\"asks\":[{\"price\":\"63985.7\",\"size\":\"0.00000\"},{\"price\":\"63985.8\",\"size\":\"3.12732\"}],\"bids\":[{\"price\":\"63919.0\",\"size\":\"0.00000\"},{\"price\":\"63918.9\",\"size\":\"3.11458\"}],\"offset\":3903205,\"nonce\":36957791,\"last_updated_at\":1785276588066941,\"begin_nonce\":36957783},\"timestamp\":1785276588084,\"type\":\"update/order_book\"}"
        "raw": "{\"channel\":\"order_book:1\",\"last_updated_at\":1785276588231754,\"offset\":3903206,\"order_book\":{\"code\":0,\"asks\":[{\"price\":\"63995.8\",\"size\":\"0.00163\"},{\"price\":\"63995.9\",\"size\":\"0.00000\"}],\"bids\":[],\"offset\":3903206,\"nonce\":36957792,\"last_updated_at\":1785276588231754,\"begin_nonce\":36957791},\"timestamp\":1785276588233,\"type\":\"update/order_book\"}"
        "raw": "{\"channel\":\"order_book:1\",\"last_updated_at\":1785276588589457,\"offset\":3903207,\"order_book\":{\"code\":0,\"asks\":[{\"price\":\"63985.8\",\"size\":\"0.00000\"},{\"price\":\"63985.9\",\"size\":\"3.12732\"}],\"bids\":[],\"offset\":3903207,\"nonce\":36957796,\"last_updated_at\":1785276588589457,\"begin_nonce\":36957792},\"timestamp\":1785276588633,\"type\":\"update/order_book\"}"
        "raw": "{\"channel\":\"order_book:1\",\"last_updated_at\":1785276589362565,\"offset\":3903209,\"order_book\":{\"code\":0,\"asks\":[],\"bids\":[{\"price\":\"63912.3\",\"size\":\"0.00149\"},{\"price\":\"63912.2\",\"size\":\"0.00000\"}],\"offset\":3903209,\"nonce\":36957800,\"last_updated_at\":1785276589362565,\"begin_nonce\":36957796},\"timestamp\":1785276589384,\"type\":\"update/order_book\"}"
        "raw": "{\"channel\":\"order_book:1\",\"last_updated_at\":1785276589632675,\"offset\":3903210,\"order_book\":{\"code\":0,\"asks\":[{\"price\":\"63985.8\",\"size\":\"3.12732\"},{\"price\":\"63985.9\",\"size\":\"0.00000\"}],\"bids\":[{\"price\":\"63919.0\",\"size\":\"3.11458\"},{\"price\":\"63918.9\",\"size\":\"0.00000\"}],\"offset\":3903210,\"nonce\":36957801,\"last_updated_at\":1785276589632675,\"begin_nonce\":36957800},\"timestamp\":1785276589633,\"type\":\"update/order_book\"}"
        "raw": "{\"channel\":\"order_book:1\",\"last_updated_at\":1785276590722658,\"offset\":3903212,\"order_book\":{\"code\":0,\"asks\":[{\"price\":\"63995.7\",\"size\":\"0.00163\"},{\"price\":\"63995.8\",\"size\":\"0.00000\"}],\"bids\":[],\"offset\":3903212,\"nonce\":36957805,\"last_updated_at\":1785276590722658,\"begin_nonce\":36957801},\"timestamp\":1785276590734,\"type\":\"update/order_book\"}"
        "raw": "{\"channel\":\"order_book:1\",\"last_updated_at\":1785276590924046,\"offset\":3903214,\"order_book\":{\"code\":0,\"asks\":[{\"price\":\"63985.8\",\"size\":\"0.00000\"},{\"price\":\"63985.9\",\"size\":\"3.12732\"}],\"bids\":[{\"price\":\"63940.0\",\"size\":\"0.00095\"},{\"price\":\"63919.0\",\"size\":\"0.00000\"},{\"price\":\"63918.9\",\"size\":\"3.11458\"}],\"offset\":3903214,\"nonce\":36957808,\"last_updated_at\":1785276590924046,\"begin_nonce\":36957805},\"timestamp\":1785276590933,\"type\":\"update/order_book\"}"
        "raw": "{\"channel\":\"order_book:1\",\"last_updated_at\":1785276591460225,\"offset\":3903215,\"order_book\":{\"code\":0,\"asks\":[],\"bids\":[{\"price\":\"63918.9\",\"size\":\"0.00000\"},{\"price\":\"63918.8\",\"size\":\"3.11458\"}],\"offset\":3903215,\"nonce\":36957809,\"last_updated_at\":1785276591460225,\"begin_nonce\":36957808},\"timestamp\":1785276591483,\"type\":\"update/order_book\"}"
        "raw": "{\"channel\":\"order_book:1\",\"last_updated_at\":1785276591732399,\"offset\":3903216,\"order_book\":{\"code\":0,\"asks\":[],\"bids\":[{\"price\":\"63912.4\",\"size\":\"0.00149\"},{\"price\":\"63912.3\",\"size\":\"0.00000\"}],\"offset\":3903216,\"nonce\":36957812,\"last_updated_at\":1785276591732399,\"begin_nonce\":36957809},\"timestamp\":1785276591733,\"type\":\"update/order_book\"}"
        "raw": "{\"channel\":\"order_book:1\",\"last_updated_at\":1785276591972486,\"offset\":3903217,\"order_book\":{\"code\":0,\"asks\":[{\"price\":\"63985.9\",\"size\":\"0.00000\"},{\"price\":\"63986.0\",\"size\":\"3.12732\"}],\"bids\":[],\"offset\":3903217,\"nonce\":36957813,\"last_updated_at\":1785276591972486,\"begin_nonce\":36957812},\"timestamp\":1785276591984,\"type\":\"update/order_book\"}"
        "raw": "{\"channel\":\"order_book:1\",\"last_updated_at\":1785276592495804,\"offset\":3903218,\"order_book\":{\"code\":0,\"asks\":[{\"price\":\"63985.9\",\"size\":\"3.12732\"},{\"price\":\"63986.0\",\"size\":\"0.00000\"}],\"bids\":[{\"price\":\"63918.9\",\"size\":\"3.11458\"},{\"price\":\"63918.8\",\"size\":\"0.00000\"}],\"offset\":3903218,\"nonce\":36957818,\"last_updated_at\":1785276592495804,\"begin_nonce\":36957813},\"timestamp\":1785276592534,\"type\":\"update/order_book\"}"
        "raw": "{\"channel\":\"order_book:1\",\"last_updated_at\":1785276593046960,\"offset\":3903219,\"order_book\":{\"code\":0,\"asks\":[{\"price\":\"63985.8\",\"size\":\"3.12732\"},{\"price\":\"63985.9\",\"size\":\"0.00000\"}],\"bids\":[],\"offset\":3903219,\"nonce\":36957822,\"last_updated_at\":1785276593046960,\"begin_nonce\":36957818},\"timestamp\":1785276593083,\"type\":\"update/order_book\"}"
        "raw": "{\"channel\":\"order_book:1\",\"last_updated_at\":1785276593548241,\"offset\":3903220,\"order_book\":{\"code\":0,\"asks\":[{\"price\":\"63985.7\",\"size\":\"3.12732\"},{\"price\":\"63985.8\",\"size\":\"0.00000\"}],\"bids\":[{\"price\":\"63919.0\",\"size\":\"3.11458\"},{\"price\":\"63918.9\",\"size\":\"0.00000\"}],\"offset\":3903220,\"nonce\":36957827,\"last_updated_at\":1785276593548241,\"begin_nonce\":36957822},\"timestamp\":1785276593583,\"type\":\"update/order_book\"}"
        "raw": "{\"channel\":\"order_book:1\",\"last_updated_at\":1785276593781705,\"offset\":3903222,\"order_book\":{\"code\":0,\"asks\":[{\"price\":\"63995.6\",\"size\":\"0.00163\"},{\"price\":\"63995.7\",\"size\":\"0.00000\"}],\"bids\":[],\"offset\":3903222,\"nonce\":36957831,\"last_updated_at\":1785276593781705,\"begin_nonce\":36957827},\"timestamp\":1785276593783,\"type\":\"update/order_book\"}"
        "raw": "{\"channel\":\"order_book:1\",\"last_updated_at\":1785276594072629,\"offset\":3903223,\"order_book\":{\"code\":0,\"asks\":[{\"price\":\"63985.7\",\"size\":\"0.00000\"},{\"price\":\"63985.9\",\"size\":\"3.12732\"}],\"bids\":[{\"price\":\"63919.0\",\"size\":\"0.00000\"},{\"price\":\"63918.8\",\"size\":\"3.11458\"}],\"offset\":3903223,\"nonce\":36957833,\"last_updated_at\":1785276594072629,\"begin_nonce\":36957831},\"timestamp\":1785276594084,\"type\":\"update/order_book\"}"
        "raw": "{\"channel\":\"order_book:1\",\"last_updated_at\":1785276594272960,\"offset\":3903225,\"order_book\":{\"code\":0,\"asks\":[],\"bids\":[{\"price\":\"63912.5\",\"size\":\"0.00149\"},{\"price\":\"63912.4\",\"size\":\"0.00000\"}],\"offset\":3903225,\"nonce\":36957836,\"last_updated_at\":1785276594272960,\"begin_nonce\":36957833},\"timestamp\":1785276594284,\"type\":\"update/order_book\"}"
        "raw": "{\"channel\":\"order_book:1\",\"last_updated_at\":1785276594613928,\"offset\":3903226,\"order_book\":{\"code\":0,\"asks\":[{\"price\":\"63985.9\",\"size\":\"0.00000\"},{\"price\":\"63986.0\",\"size\":\"3.12732\"}],\"bids\":[],\"offset\":3903226,\"nonce\":36957841,\"last_updated_at\":1785276594613928,\"begin_nonce\":36957836},\"timestamp\":1785276594633,\"type\":\"update/order_book\"}"
        "raw": "{\"channel\":\"order_book:1\",\"last_updated_at\":1785276594882467,\"offset\":3903228,\"order_book\":{\"code\":0,\"asks\":[{\"price\":\"63994.6\",\"size\":\"0.00163\"},{\"price\":\"63995.6\",\"size\":\"0.00000\"}],\"bids\":[{\"price\":\"63912.5\",\"size\":\"0.00000\"}],\"offset\":3903228,\"nonce\":36957844,\"last_updated_at\":1785276594882467,\"begin_nonce\":36957841},\"timestamp\":1785276594884,\"type\":\"update/order_book\"}"
        "raw": "{\"channel\":\"order_book:1\",\"last_updated_at\":1785276594885858,\"offset\":3903229,\"order_book\":{\"code\":0,\"asks\":[],\"bids\":[{\"price\":\"63911.5\",\"size\":\"0.00149\"}],\"offset\":3903229,\"nonce\":36957845,\"last_updated_at\":1785276594885858,\"begin_nonce\":36957844},\"timestamp\":1785276594934,\"type\":\"update/order_book\"}"
        "raw": "{\"channel\":\"order_book:1\",\"last_updated_at\":1785276594999150,\"offset\":3903231,\"order_book\":{\"code\":0,\"asks\":[{\"price\":\"63985.1\",\"size\":\"3.12738\"},{\"price\":\"63986.0\",\"size\":\"0.00000\"}],\"bids\":[{\"price\":\"63918.8\",\"size\":\"0.00000\"},{\"price\":\"63916.6\",\"size\":\"3.11464\"}],\"offset\":3903231,\"nonce\":36957848,\"last_updated_at\":1785276594999150,\"begin_nonce\":36957845},\"timestamp\":1785276595034,\"type\":\"update/order_book\"}"
        "raw": "{\"channel\":\"order_book:1\",\"last_updated_at\":1785276595501756,\"offset\":3903232,\"order_book\":{\"code\":0,\"asks\":[{\"price\":\"63984.6\",\"size\":\"3.12738\"},{\"price\":\"63985.1\",\"size\":\"0.00000\"}],\"bids\":[{\"price\":\"63917.2\",\"size\":\"3.11464\"},{\"price\":\"63916.6\",\"size\":\"0.00000\"}],\"offset\":3903232,\"nonce\":36957853,\"last_updated_at\":1785276595501756,\"begin_nonce\":36957848},\"timestamp\":1785276595534,\"type\":\"update/order_book\"}"
        "raw": "{\"channel\":\"order_book:1\",\"last_updated_at\":1785276596017567,\"offset\":3903233,\"order_book\":{\"code\":0,\"asks\":[{\"price\":\"63984.6\",\"size\":\"0.00000\"},{\"price\":\"63984.7\",\"size\":\"3.12738\"}],\"bids\":[{\"price\":\"63917.2\",\"size\":\"0.00000\"},{\"price\":\"63917.1\",\"size\":\"3.11464\"}],\"offset\":3903233,\"nonce\":36957858,\"last_updated_at\":1785276596017567,\"begin_nonce\":36957853},\"timestamp\":1785276596033,\"type\":\"update/order_book\"}"
        "raw": "{\"channel\":\"order_book:1\",\"last_updated_at\":1785276596343996,\"offset\":3903234,\"order_book\":{\"code\":0,\"asks\":[{\"price\":\"63984.7\",\"size\":\"0.00000\"},{\"price\":\"63986.2\",\"size\":\"3.12733\"}],\"bids\":[{\"price\":\"63918.7\",\"size\":\"3.11459\"},{\"price\":\"63917.1\",\"size\":\"0.00000\"}],\"offset\":3903234,\"nonce\":36957862,\"last_updated_at\":1785276596343996,\"begin_nonce\":36957858},\"timestamp\":1785276596383,\"type\":\"update/order_book\"}"
        "raw": "{\"channel\":\"order_book:1\",\"last_updated_at\":1785276596415166,\"offset\":3903237,\"order_book\":{\"code\":0,\"asks\":[{\"price\":\"63994.6\",\"size\":\"0.00000\"},{\"price\":\"64002.4\",\"size\":\"0.00163\"}],\"bids\":[{\"price\":\"63919.3\",\"size\":\"0.00149\"},{\"price\":\"63911.5\",\"size\":\"0.00000\"}],\"offset\":3903237,\"nonce\":36957866,\"last_updated_at\":1785276596415166,\"begin_nonce\":36957862},\"timestamp\":1785276596433,\"type\":\"update/order_book\"}"
        "raw": "{\"channel\":\"order_book:1\",\"last_updated_at\":1785276596481350,\"offset\":3903239,\"order_book\":{\"code\":0,\"asks\":[{\"price\":\"64002.4\",\"size\":\"0.00000\"}],\"bids\":[{\"price\":\"63919.3\",\"size\":\"0.00000\"}],\"offset\":3903239,\"nonce\":36957869,\"last_updated_at\":1785276596481350,\"begin_nonce\":36957866},\"timestamp\":1785276596484,\"type\":\"update/order_book\"}"
        "raw": "{\"channel\":\"order_book:1\",\"last_updated_at\":1785276596562373,\"offset\":3903244,\"order_book\":{\"code\":0,\"asks\":[{\"price\":\"63986.2\",\"size\":\"0.00000\"},{\"price\":\"63992.2\",\"size\":\"3.12732\"},{\"price\":\"63997.2\",\"size\":\"0.00000\"},{\"price\":\"64000.0\",\"size\":\"0.00263\"}],\"bids\":[{\"price\":\"63919.0\",\"size\":\"3.11458\"},{\"price\":\"63918.7\",\"size\":\"0.00000\"},{\"price\":\"63916.9\",\"size\":\"0.00149\"},{\"price\":\"63914.1\",\"size\":\"0.00000\"}],\"offset\":3903244,\"nonce\":36957875,\"last_updated_at\":1785276596562373,\"begin_nonce\":36957870},\"timestamp\":1785276596584,\"type\":\"update/order_book\"}"
        "raw": "{\"channel\":\"order_book:1\",\"last_updated_at\":1785276596778412,\"offset\":3903245,\"order_book\":{\"code\":0,\"asks\":[{\"price\":\"63990.9\",\"size\":\"3.12732\"},{\"price\":\"63992.2\",\"size\":\"0.00000\"}],\"bids\":[],\"offset\":3903245,\"nonce\":36957881,\"last_updated_at\":1785276596778412,\"begin_nonce\":36957875},\"timestamp\":1785276596784,\"type\":\"update/order_book\"}"
        "raw": "{\"channel\":\"order_book:1\",\"last_updated_at\":1785276596862301,\"offset\":3903247,\"order_book\":{\"code\":0,\"asks\":[],\"bids\":[{\"price\":\"63917.0\",\"size\":\"0.00149\"},{\"price\":\"63916.9\",\"size\":\"0.00000\"}],\"offset\":3903247,\"nonce\":36957884,\"last_updated_at\":1785276596862301,\"begin_nonce\":36957881},\"timestamp\":1785276596884,\"type\":\"update/order_book\"}"
        "raw": "{\"channel\":\"order_book:1\",\"last_updated_at\":1785276596994239,\"offset\":3903248,\"order_book\":{\"code\":0,\"asks\":[{\"price\":\"63989.7\",\"size\":\"3.12732\"},{\"price\":\"63990.9\",\"size\":\"0.00000\"}],\"bids\":[{\"price\":\"63919.0\",\"size\":\"0.00000\"},{\"price\":\"63917.7\",\"size\":\"3.11458\"}],\"offset\":3903248,\"nonce\":36957886,\"last_updated_at\":1785276596994239,\"begin_nonce\":36957884},\"timestamp\":1785276597034,\"type\":\"update/order_book\"}"
        "raw": "{\"channel\":\"order_book:1\",\"last_updated_at\":1785276597258716,\"offset\":3903252,\"order_book\":{\"code\":0,\"asks\":[{\"price\":\"63996.9\",\"size\":\"0.00163\"},{\"price\":\"64000.0\",\"size\":\"0.00100\"}],\"bids\":[{\"price\":\"63917.0\",\"size\":\"0.00000\"},{\"price\":\"63913.9\",\"size\":\"0.00149\"}],\"offset\":3903252,\"nonce\":36957893,\"last_updated_at\":1785276597258716,\"begin_nonce\":36957886},\"timestamp\":1785276597283,\"type\":\"update/order_book\"}"
        "raw": "{\"channel\":\"order_book:1\",\"last_updated_at\":1785276597460383,\"offset\":3903254,\"order_book\":{\"code\":0,\"asks\":[{\"price\":\"63988.2\",\"size\":\"3.12732\"},{\"price\":\"63989.7\",\"size\":\"0.00000\"}],\"bids\":[{\"price\":\"63917.8\",\"size\":\"3.11458\"},{\"price\":\"63917.7\",\"size\":\"0.00000\"}],\"offset\":3903254,\"nonce\":36957898,\"last_updated_at\":1785276597460383,\"begin_nonce\":36957893},\"timestamp\":1785276597484,\"type\":\"update/order_book\"}"
        "raw": "{\"channel\":\"order_book:1\",\"last_updated_at\":1785276597579456,\"offset\":3903255,\"order_book\":{\"code\":0,\"asks\":[],\"bids\":[{\"price\":\"63914.0\",\"size\":\"0.00149\"},{\"price\":\"63913.9\",\"size\":\"0.00000\"}],\"offset\":3903255,\"nonce\":36957900,\"last_updated_at\":1785276597579456,\"begin_nonce\":36957898},\"timestamp\":1785276597584,\"type\":\"update/order_book\"}"
        "raw": "{\"channel\":\"order_book:1\",\"last_updated_at\":1785276597709028,\"offset\":3903256,\"order_book\":{\"code\":0,\"asks\":[],\"bids\":[{\"price\":\"63940.0\",\"size\":\"0.00000\"}],\"offset\":3903256,\"nonce\":36957901,\"last_updated_at\":1785276597709028,\"begin_nonce\":36957900},\"timestamp\":1785276597733,\"type\":\"update/order_book\"}"
        "raw": "{\"channel\":\"order_book:1\",\"last_updated_at\":1785276597889474,\"offset\":3903257,\"order_book\":{\"code\":0,\"asks\":[],\"bids\":[{\"price\":\"63926.0\",\"size\":\"0.00095\"}],\"offset\":3903257,\"nonce\":36957905,\"last_updated_at\":1785276597889474,\"begin_nonce\":36957901},\"timestamp\":1785276597934,\"type\":\"update/order_book\"}"
        "raw": "{\"channel\":\"order_book:1\",\"last_updated_at\":1785276598009471,\"offset\":3903258,\"order_book\":{\"code\":0,\"asks\":[{\"price\":\"63988.2\",\"size\":\"0.00000\"},{\"price\":\"63988.4\",\"size\":\"3.12732\"}],\"bids\":[],\"offset\":3903258,\"nonce\":36957906,\"last_updated_at\":1785276598009471,\"begin_nonce\":36957905},\"timestamp\":1785276598034,\"type\":\"update/order_book\"}"
        "raw": "{\"channel\":\"order_book:1\",\"last_updated_at\":1785276598119836,\"offset\":3903259,\"order_book\":{\"code\":0,\"asks\":[{\"price\":\"64000.0\",\"size\":\"0.00000\"}],\"bids\":[],\"offset\":3903259,\"nonce\":36957907,\"last_updated_at\":1785276598119836,\"begin_nonce\":36957906},\"timestamp\":1785276598134,\"type\":\"update/order_book\"}"
        "raw": "{\"channel\":\"order_book:1\",\"last_updated_at\":1785276598312516,\"offset\":3903260,\"order_book\":{\"code\":0,\"asks\":[{\"price\":\"63988.4\",\"size\":\"0.00000\"},{\"price\":\"63989.1\",\"size\":\"3.12732\"}],\"bids\":[{\"price\":\"63919.0\",\"size\":\"3.11458\"},{\"price\":\"63917.8\",\"size\":\"0.00000\"}],\"offset\":3903260,\"nonce\":36957909,\"last_updated_at\":1785276598312516,\"begin_nonce\":36957907},\"timestamp\":1785276598334,\"type\":\"update/order_book\"}"
        "raw": "{\"channel\":\"order_book:1\",\"last_updated_at\":1785276598410641,\"offset\":3903266,\"order_book\":{\"code\":0,\"asks\":[{\"price\":\"63996.9\",\"size\":\"0.00000\"},{\"price\":\"63998.9\",\"size\":\"0.00163\"}],\"bids\":[{\"price\":\"63915.9\",\"size\":\"0.00149\"},{\"price\":\"63914.0\",\"size\":\"0.00000\"}],\"offset\":3903266,\"nonce\":36957917,\"last_updated_at\":1785276598410641,\"begin_nonce\":36957909},\"timestamp\":1785276598433,\"type\":\"update/order_book\"}"
        "raw": "{\"channel\":\"order_book:1\",\"last_updated_at\":1785276598524910,\"offset\":3903268,\"order_book\":{\"code\":0,\"asks\":[{\"price\":\"63988.4\",\"size\":\"3.12724\"},{\"price\":\"63989.1\",\"size\":\"0.00000\"}],\"bids\":[{\"price\":\"63919.0\",\"size\":\"0.00000\"},{\"price\":\"63918.9\",\"size\":\"3.11450\"}],\"offset\":3903268,\"nonce\":36957919,\"last_updated_at\":1785276598524910,\"begin_nonce\":36957917},\"timestamp\":1785276598534,\"type\":\"update/order_book\"}"
        "raw": "{\"channel\":\"order_book:1\",\"last_updated_at\":1785276598746998,\"offset\":3903269,\"order_book\":{\"code\":0,\"asks\":[{\"price\":\"63988.3\",\"size\":\"3.12724\"},{\"price\":\"63988.4\",\"size\":\"0.00000\"}],\"bids\":[{\"price\":\"63920.0\",\"size\":\"3.11550\"},{\"price\":\"63918.9\",\"size\":\"0.00000\"}],\"offset\":3903269,\"nonce\":36957925,\"last_updated_at\":1785276598746998,\"begin_nonce\":36957919},\"timestamp\":1785276598784,\"type\":\"update/order_book\"}"
        "raw": "{\"channel\":\"order_book:1\",\"last_updated_at\":1785276599524323,\"offset\":3903270,\"order_book\":{\"code\":0,\"asks\":[],\"bids\":[{\"price\":\"63560.0\",\"size\":\"0.00100\"}],\"offset\":3903270,\"nonce\":36957941,\"last_updated_at\":1785276599524323,\"begin_nonce\":36957925},\"timestamp\":1785276599534,\"type\":\"update/order_book\"}"
        "raw": "{\"channel\":\"order_book:1\",\"last_updated_at\":1785276599578754,\"offset\":3903271,\"order_book\":{\"code\":0,\"asks\":[{\"price\":\"63988.3\",\"size\":\"0.00000\"},{\"price\":\"63991.2\",\"size\":\"3.12724\"}],\"bids\":[{\"price\":\"63920.0\",\"size\":\"0.00100\"},{\"price\":\"63916.6\",\"size\":\"3.11450\"}],\"offset\":3903271,\"nonce\":36957942,\"last_updated_at\":1785276599578754,\"begin_nonce\":36957941},\"timestamp\":1785276599583,\"type\":\"update/order_book\"}"
        "raw": "{\"channel\":\"order_book:1\",\"last_updated_at\":1785276599743445,\"offset\":3903272,\"order_book\":{\"code\":0,\"asks\":[{\"price\":\"63988.7\",\"size\":\"3.12724\"},{\"price\":\"63991.2\",\"size\":\"0.00000\"}],\"bids\":[{\"price\":\"63919.2\",\"size\":\"3.11450\"},{\"price\":\"63916.6\",\"size\":\"0.00000\"}],\"offset\":3903272,\"nonce\":36957947,\"last_updated_at\":1785276599743445,\"begin_nonce\":36957942},\"timestamp\":1785276599784,\"type\":\"update/order_book\"}"
        "raw": "{\"channel\":\"order_book:1\",\"last_updated_at\":1785276599980133,\"offset\":3903273,\"order_book\":{\"code\":0,\"asks\":[{\"price\":\"63980.0\",\"size\":\"0.00100\"}],\"bids\":[],\"offset\":3903273,\"nonce\":36957951,\"last_updated_at\":1785276599980133,\"begin_nonce\":36957947},\"timestamp\":1785276599984,\"type\":\"update/order_book\"}"
        "raw": "{\"channel\":\"order_book:1\",\"last_updated_at\":1785276600256150,\"offset\":3903274,\"order_book\":{\"code\":0,\"asks\":[{\"price\":\"63988.3\",\"size\":\"3.12724\"},{\"price\":\"63988.7\",\"size\":\"0.00000\"}],\"bids\":[{\"price\":\"63919.6\",\"size\":\"3.11450\"},{\"price\":\"63919.2\",\"size\":\"0.00000\"}],\"offset\":3903274,\"nonce\":36957953,\"last_updated_at\":1785276600256150,\"begin_nonce\":36957951},\"timestamp\":1785276600283,\"type\":\"update/order_book\"}"
        "raw": "{\"channel\":\"order_book:1\",\"last_updated_at\":1785276600420973,\"offset\":3903275,\"order_book\":{\"code\":0,\"asks\":[{\"price\":\"63987.5\",\"size\":\"3.12724\"},{\"price\":\"63988.3\",\"size\":\"0.00000\"}],\"bids\":[{\"price\":\"63920.6\",\"size\":\"3.11450\"},{\"price\":\"63919.6\",\"size\":\"0.00000\"}],\"offset\":3903275,\"nonce\":36957956,\"last_updated_at\":1785276600420973,\"begin_nonce\":36957953},\"timestamp\":1785276600436,\"type\":\"update/order_book\"}"
        "raw": "{\"channel\":\"order_book:1\",\"last_updated_at\":1785276601413822,\"offset\":3903277,\"order_book\":{\"code\":0,\"asks\":[],\"bids\":[{\"price\":\"63915.9\",\"size\":\"0.00000\"},{\"price\":\"63915.8\",\"size\":\"0.00149\"}],\"offset\":3903277,\"nonce\":36957969,\"last_updated_at\":1785276601413822,\"begin_nonce\":36957956},\"timestamp\":1785276601435,\"type\":\"update/order_book\"}"
        "raw": "{\"channel\":\"order_book:1\",\"last_updated_at\":1785276601575829,\"offset\":3903278,\"order_book\":{\"code\":0,\"asks\":[{\"price\":\"63987.4\",\"size\":\"3.12724\"},{\"price\":\"63987.5\",\"size\":\"0.00000\"}],\"bids\":[],\"offset\":3903278,\"nonce\":36957971,\"last_updated_at\":1785276601575829,\"begin_nonce\":36957969},\"timestamp\":1785276601584,\"type\":\"update/order_book\"}"
        "raw": "{\"channel\":\"order_book:1\",\"last_updated_at\":1785276601696404,\"offset\":3903280,\"order_book\":{\"code\":0,\"asks\":[{\"price\":\"63998.8\",\"size\":\"0.00163\"},{\"price\":\"63998.9\",\"size\":\"0.00000\"}],\"bids\":[],\"offset\":3903280,\"nonce\":36957973,\"last_updated_at\":1785276601696404,\"begin_nonce\":36957971},\"timestamp\":1785276601734,\"type\":\"update/order_book\"}"
        "raw": "{\"channel\":\"order_book:1\",\"last_updated_at\":1785276602110946,\"offset\":3903283,\"order_book\":{\"code\":0,\"asks\":[{\"price\":\"63987.4\",\"size\":\"0.00000\"},{\"price\":\"63988.5\",\"size\":\"3.12724\"}],\"bids\":[{\"price\":\"63920.6\",\"size\":\"0.00000\"},{\"price\":\"63919.5\",\"size\":\"3.11450\"}],\"offset\":3903283,\"nonce\":36957979,\"last_updated_at\":1785276602110946,\"begin_nonce\":36957975},\"timestamp\":1785276602133,\"type\":\"update/order_book\"}"
        "raw": "{\"channel\":\"order_book:1\",\"last_updated_at\":1785276602298984,\"offset\":3903284,\"order_book\":{\"code\":0,\"asks\":[],\"bids\":[{\"price\":\"63926.0\",\"size\":\"0.00032\"}],\"offset\":3903284,\"nonce\":36957983,\"last_updated_at\":1785276602298984,\"begin_nonce\":36957979},\"timestamp\":1785276602334,\"type\":\"update/order_book\"}"
        "raw": "{\"channel\":\"order_book:1\",\"last_updated_at\":1785276602382613,\"offset\":3903285,\"order_book\":{\"code\":0,\"asks\":[{\"price\":\"63987.6\",\"size\":\"3.12724\"},{\"price\":\"63988.5\",\"size\":\"0.00000\"}],\"bids\":[{\"price\":\"63920.4\",\"size\":\"3.11450\"},{\"price\":\"63919.5\",\"size\":\"0.00000\"}],\"offset\":3903285,\"nonce\":36957984,\"last_updated_at\":1785276602382613,\"begin_nonce\":36957983},\"timestamp\":1785276602383,\"type\":\"update/order_book\"}"
        "raw": "{\"channel\":\"order_book:1\",\"last_updated_at\":1785276603001290,\"offset\":3903286,\"order_book\":{\"code\":0,\"asks\":[{\"price\":\"63987.6\",\"size\":\"0.00000\"},{\"price\":\"63987.7\",\"size\":\"3.12724\"}],\"bids\":[],\"offset\":3903286,\"nonce\":36957987,\"last_updated_at\":1785276603001290,\"begin_nonce\":36957984},\"timestamp\":1785276603034,\"type\":\"update/order_book\"}"
        "raw": "{\"channel\":\"order_book:1\",\"last_updated_at\":1785276603144251,\"offset\":3903287,\"order_book\":{\"code\":0,\"asks\":[],\"bids\":[{\"price\":\"63926.0\",\"size\":\"0.00000\"}],\"offset\":3903287,\"nonce\":36957989,\"last_updated_at\":1785276603144251,\"begin_nonce\":36957987},\"timestamp\":1785276603184,\"type\":\"update/order_book\"}"
        "raw": "{\"channel\":\"order_book:1\",\"last_updated_at\":1785276603501363,\"offset\":3903288,\"order_book\":{\"code\":0,\"asks\":[{\"price\":\"63987.6\",\"size\":\"3.12724\"},{\"price\":\"63987.7\",\"size\":\"0.00000\"}],\"bids\":[],\"offset\":3903288,\"nonce\":36957991,\"last_updated_at\":1785276603501363,\"begin_nonce\":36957989},\"timestamp\":1785276603533,\"type\":\"update/order_book\"}"
        "raw": "{\"channel\":\"order_book:1\",\"last_updated_at\":1785276603558238,\"offset\":3903289,\"order_book\":{\"code\":0,\"asks\":[],\"bids\":[{\"price\":\"63920.4\",\"size\":\"3.11449\"}],\"offset\":3903289,\"nonce\":36957992,\"last_updated_at\":1785276603558238,\"begin_nonce\":36957991},\"timestamp\":1785276603583,\"type\":\"update/order_book\"}"
        "raw": "{\"channel\":\"order_book:1\",\"last_updated_at\":1785276603804749,\"offset\":3903291,\"order_book\":{\"code\":0,\"asks\":[],\"bids\":[{\"price\":\"63915.8\",\"size\":\"0.00000\"},{\"price\":\"63915.7\",\"size\":\"0.00149\"}],\"offset\":3903291,\"nonce\":36957996,\"last_updated_at\":1785276603804749,\"begin_nonce\":36957992},\"timestamp\":1785276603834,\"type\":\"update/order_book\"}"
        "raw": "{\"channel\":\"order_book:1\",\"last_updated_at\":1785276604018090,\"offset\":3903292,\"order_book\":{\"code\":0,\"asks\":[{\"price\":\"63987.4\",\"size\":\"3.12724\"},{\"price\":\"63987.6\",\"size\":\"0.00000\"}],\"bids\":[{\"price\":\"63920.7\",\"size\":\"3.11449\"},{\"price\":\"63920.4\",\"size\":\"0.00000\"}],\"offset\":3903292,\"nonce\":36958001,\"last_updated_at\":1785276604018090,\"begin_nonce\":36957996},\"timestamp\":1785276604033,\"type\":\"update/order_book\"}"
        "raw": "{\"channel\":\"order_book:1\",\"last_updated_at\":1785276604042705,\"offset\":3903293,\"order_book\":{\"code\":0,\"asks\":[{\"price\":\"64054.0\",\"size\":\"0.00032\"}],\"bids\":[],\"offset\":3903293,\"nonce\":36958002,\"last_updated_at\":1785276604042705,\"begin_nonce\":36958001},\"timestamp\":1785276604084,\"type\":\"update/order_book\"}"
        "raw": "{\"channel\":\"order_book:1\",\"last_updated_at\":1785276604289212,\"offset\":3903294,\"order_book\":{\"code\":0,\"asks\":[{\"price\":\"63980.0\",\"size\":\"0.00099\"}],\"bids\":[],\"offset\":3903294,\"nonce\":36958003,\"last_updated_at\":1785276604289212,\"begin_nonce\":36958002},\"timestamp\":1785276604333,\"type\":\"update/order_book\"}"
        "raw": "{\"channel\":\"order_book:1\",\"last_updated_at\":1785276604530289,\"offset\":3903296,\"order_book\":{\"code\":0,\"asks\":[{\"price\":\"63987.4\",\"size\":\"0.00000\"},{\"price\":\"63987.5\",\"size\":\"3.12724\"},{\"price\":\"63998.7\",\"size\":\"0.00163\"},{\"price\":\"63998.8\",\"size\":\"0.00000\"}],\"bids\":[{\"price\":\"63920.7\",\"size\":\"0.00000\"},{\"price\":\"63920.6\",\"size\":\"3.11449\"}],\"offset\":3903296,\"nonce\":36958008,\"last_updated_at\":1785276604530289,\"begin_nonce\":36958003},\"timestamp\":1785276604534,\"type\":\"update/order_book\"}"
        "raw": "{\"channel\":\"order_book:1\",\"last_updated_at\":1785276604743679,\"offset\":3903297,\"order_book\":{\"code\":0,\"asks\":[{\"price\":\"64054.0\",\"size\":\"0.00000\"}],\"bids\":[],\"offset\":3903297,\"nonce\":36958009,\"last_updated_at\":1785276604743679,\"begin_nonce\":36958008},\"timestamp\":1785276604784,\"type\":\"update/order_book\"}"
        "raw": "{\"channel\":\"order_book:1\",\"last_updated_at\":1785276604932889,\"offset\":3903298,\"order_book\":{\"code\":0,\"asks\":[],\"bids\":[{\"price\":\"63915.7\",\"size\":\"0.00000\"},{\"price\":\"63915.6\",\"size\":\"0.00149\"}],\"offset\":3903298,\"nonce\":36958010,\"last_updated_at\":1785276604932889,\"begin_nonce\":36958009},\"timestamp\":1785276604933,\"type\":\"update/order_book\"}"
        "raw": "{\"channel\":\"order_book:1\",\"last_updated_at\":1785276605047065,\"offset\":3903299,\"order_book\":{\"code\":0,\"asks\":[{\"price\":\"63987.5\",\"size\":\"0.00000\"},{\"price\":\"63987.6\",\"size\":\"3.12724\"}],\"bids\":[{\"price\":\"63920.6\",\"size\":\"0.00000\"},{\"price\":\"63920.5\",\"size\":\"3.11449\"}],\"offset\":3903299,\"nonce\":36958012,\"last_updated_at\":1785276605047065,\"begin_nonce\":36958010},\"timestamp\":1785276605084,\"type\":\"update/order_book\"}"
        "raw": "{\"channel\":\"order_book:1\",\"last_updated_at\":1785276605743561,\"offset\":3903300,\"order_book\":{\"code\":0,\"asks\":[{\"price\":\"63987.5\",\"size\":\"3.12724\"},{\"price\":\"63987.6\",\"size\":\"0.00000\"}],\"bids\":[{\"price\":\"63920.6\",\"size\":\"3.11449\"},{\"price\":\"63920.5\",\"size\":\"0.00000\"}],\"offset\":3903300,\"nonce\":36958014,\"last_updated_at\":1785276605743561,\"begin_nonce\":36958012},\"timestamp\":1785276605783,\"type\":\"update/order_book\"}"
        "raw": "{\"channel\":\"order_book:1\",\"last_updated_at\":1785276606264403,\"offset\":3903301,\"order_book\":{\"code\":0,\"asks\":[{\"price\":\"63987.5\",\"size\":\"0.00000\"},{\"price\":\"63987.6\",\"size\":\"3.12724\"}],\"bids\":[{\"price\":\"63920.6\",\"size\":\"0.00000\"},{\"price\":\"63920.5\",\"size\":\"3.11449\"}],\"offset\":3903301,\"nonce\":36958015,\"last_updated_at\":1785276606264403,\"begin_nonce\":36958014},\"timestamp\":1785276606283,\"type\":\"update/order_book\"}"
        "raw": "{\"channel\":\"order_book:1\",\"last_updated_at\":1785276606423651,\"offset\":3903302,\"order_book\":{\"code\":0,\"asks\":[],\"bids\":[{\"price\":\"63886.4\",\"size\":\"0.00032\"}],\"offset\":3903302,\"nonce\":36958018,\"last_updated_at\":1785276606423651,\"begin_nonce\":36958015},\"timestamp\":1785276606434,\"type\":\"update/order_book\"}"
        "raw": "{\"channel\":\"order_book:1\",\"last_updated_at\":1785276606452910,\"offset\":3903304,\"order_book\":{\"code\":0,\"asks\":[],\"bids\":[{\"price\":\"63915.6\",\"size\":\"0.00000\"},{\"price\":\"63915.5\",\"size\":\"0.00149\"}],\"offset\":3903304,\"nonce\":36958020,\"last_updated_at\":1785276606452910,\"begin_nonce\":36958018},\"timestamp\":1785276606484,\"type\":\"update/order_book\"}"
        "raw": "{\"channel\":\"order_book:1\",\"last_updated_at\":1785276606606443,\"offset\":3903307,\"order_book\":{\"code\":0,\"asks\":[{\"price\":\"63998.7\",\"size\":\"0.00000\"},{\"price\":\"64000.5\",\"size\":\"0.00163\"}],\"bids\":[{\"price\":\"63917.3\",\"size\":\"0.00149\"},{\"price\":\"63915.5\",\"size\":\"0.00000\"}],\"offset\":3903307,\"nonce\":36958024,\"last_updated_at\":1785276606606443,\"begin_nonce\":36958020},\"timestamp\":1785276606633,\"type\":\"update/order_book\"}"
        "raw": "{\"channel\":\"order_book:1\",\"last_updated_at\":1785276606804186,\"offset\":3903310,\"order_book\":{\"code\":0,\"asks\":[{\"price\":\"63987.5\",\"size\":\"3.12724\"},{\"price\":\"63987.6\",\"size\":\"0.00000\"}],\"bids\":[{\"price\":\"63920.5\",\"size\":\"0.00000\"},{\"price\":\"63920.2\",\"size\":\"3.11449\"},{\"price\":\"63886.3\",\"size\":\"0.00032\"}],\"offset\":3903310,\"nonce\":36958029,\"last_updated_at\":1785276606804186,\"begin_nonce\":36958024},\"timestamp\":1785276606834,\"type\":\"update/order_book\"}"
        "raw": "{\"channel\":\"order_book:1\",\"last_updated_at\":1785276607332696,\"offset\":3903311,\"order_book\":{\"code\":0,\"asks\":[],\"bids\":[{\"price\":\"63920.2\",\"size\":\"0.00000\"},{\"price\":\"63920.1\",\"size\":\"3.11449\"}],\"offset\":3903311,\"nonce\":36958035,\"last_updated_at\":1785276607332696,\"begin_nonce\":36958029},\"timestamp\":1785276607333,\"type\":\"update/order_book\"}"
        "raw": "{\"channel\":\"order_book:1\",\"last_updated_at\":1785276607723415,\"offset\":3903313,\"order_book\":{\"code\":0,\"asks\":[],\"bids\":[{\"price\":\"63917.3\",\"size\":\"0.00000\"},{\"price\":\"63917.2\",\"size\":\"0.00149\"}],\"offset\":3903313,\"nonce\":36958037,\"last_updated_at\":1785276607723415,\"begin_nonce\":36958035},\"timestamp\":1785276607733,\"type\":\"update/order_book\"}"
        "raw": "{\"channel\":\"order_book:1\",\"last_updated_at\":1785276607837716,\"offset\":3903314,\"order_book\":{\"code\":0,\"asks\":[],\"bids\":[{\"price\":\"63920.2\",\"size\":\"3.11449\"},{\"price\":\"63920.1\",\"size\":\"0.00000\"}],\"offset\":3903314,\"nonce\":36958038,\"last_updated_at\":1785276607837716,\"begin_nonce\":36958037},\"timestamp\":1785276607884,\"type\":\"update/order_book\"}"
        "raw": "{\"channel\":\"order_book:1\",\"last_updated_at\":1785276608341225,\"offset\":3903315,\"order_book\":{\"code\":0,\"asks\":[{\"price\":\"63987.5\",\"size\":\"0.00000\"},{\"price\":\"63987.6\",\"size\":\"3.12724\"}],\"bids\":[{\"price\":\"63920.2\",\"size\":\"0.00000\"},{\"price\":\"63920.1\",\"size\":\"3.11449\"}],\"offset\":3903315,\"nonce\":36958043,\"last_updated_at\":1785276608341225,\"begin_nonce\":36958038},\"timestamp\":1785276608383,\"type\":\"update/order_book\"}"
        "raw": "{\"channel\":\"order_book:1\",\"last_updated_at\":1785276608622623,\"offset\":3903316,\"order_book\":{\"code\":0,\"asks\":[{\"price\":\"64014.3\",\"size\":\"0.00032\"}],\"bids\":[],\"offset\":3903316,\"nonce\":36958044,\"last_updated_at\":1785276608622623,\"begin_nonce\":36958043},\"timestamp\":1785276608633,\"type\":\"update/order_book\"}"
        "raw": "{\"channel\":\"order_book:1\",\"last_updated_at\":1785276608640364,\"offset\":3903317,\"order_book\":{\"code\":0,\"asks\":[{\"price\":\"64014.3\",\"size\":\"0.00064\"}],\"bids\":[],\"offset\":3903317,\"nonce\":36958046,\"last_updated_at\":1785276608640364,\"begin_nonce\":36958044},\"timestamp\":1785276608684,\"type\":\"update/order_book\"}"
        "raw": "{\"channel\":\"order_book:1\",\"last_updated_at\":1785276608851139,\"offset\":3903318,\"order_book\":{\"code\":0,\"asks\":[{\"price\":\"63987.4\",\"size\":\"3.12724\"},{\"price\":\"63987.6\",\"size\":\"0.00000\"}],\"bids\":[{\"price\":\"63920.7\",\"size\":\"3.11449\"},{\"price\":\"63920.1\",\"size\":\"0.00000\"}],\"offset\":3903318,\"nonce\":36958048,\"last_updated_at\":1785276608851139,\"begin_nonce\":36958046},\"timestamp\":1785276608884,\"type\":\"update/order_book\"}"
        "raw": "{\"channel\":\"order_book:1\",\"last_updated_at\":1785276608901207,\"offset\":3903319,\"order_book\":{\"code\":0,\"asks\":[],\"bids\":[{\"price\":\"63917.2\",\"size\":\"0.00000\"},{\"price\":\"63917.1\",\"size\":\"0.00149\"}],\"offset\":3903319,\"nonce\":36958049,\"last_updated_at\":1785276608901207,\"begin_nonce\":36958048},\"timestamp\":1785276608933,\"type\":\"update/order_book\"}"
        "raw": "{\"channel\":\"order_book:1\",\"last_updated_at\":1785276609372939,\"offset\":3903321,\"order_book\":{\"code\":0,\"asks\":[{\"price\":\"63987.4\",\"size\":\"0.00000\"},{\"price\":\"63987.5\",\"size\":\"3.12724\"}],\"bids\":[{\"price\":\"63920.7\",\"size\":\"0.00000\"},{\"price\":\"63920.6\",\"size\":\"3.11449\"}],\"offset\":3903321,\"nonce\":36958056,\"last_updated_at\":1785276609372939,\"begin_nonce\":36958049},\"timestamp\":1785276609384,\"type\":\"update/order_book\"}"
        "raw": "{\"channel\":\"order_book:1\",\"last_updated_at\":1785276609663623,\"offset\":3903323,\"order_book\":{\"code\":0,\"asks\":[{\"price\":\"64000.4\",\"size\":\"0.00163\"},{\"price\":\"64000.5\",\"size\":\"0.00000\"}],\"bids\":[],\"offset\":3903323,\"nonce\":36958062,\"last_updated_at\":1785276609663623,\"begin_nonce\":36958056},\"timestamp\":1785276609684,\"type\":\"update/order_book\"}"
        "raw": "{\"channel\":\"order_book:1\",\"last_updated_at\":1785276610048668,\"offset\":3903324,\"order_book\":{\"code\":0,\"asks\":[],\"bids\":[{\"price\":\"63920.6\",\"size\":\"0.00000\"},{\"price\":\"63920.5\",\"size\":\"3.11449\"}],\"offset\":3903324,\"nonce\":36958064,\"last_updated_at\":1785276610048668,\"begin_nonce\":36958062},\"timestamp\":1785276610084,\"type\":\"update/order_book\"}"
        "raw": "{\"channel\":\"order_book:1\",\"last_updated_at\":1785276610567839,\"offset\":3903326,\"order_book\":{\"code\":0,\"asks\":[],\"bids\":[{\"price\":\"63917.1\",\"size\":\"0.00000\"},{\"price\":\"63917.0\",\"size\":\"0.00149\"}],\"offset\":3903326,\"nonce\":36958070,\"last_updated_at\":1785276610567839,\"begin_nonce\":36958064},\"timestamp\":1785276610584,\"type\":\"update/order_book\"}"
        "raw": "{\"channel\":\"order_book:1\",\"last_updated_at\":1785276610678598,\"offset\":3903327,\"order_book\":{\"code\":0,\"asks\":[{\"price\":\"63987.5\",\"size\":\"0.00000\"},{\"price\":\"63987.6\",\"size\":\"3.12724\"}],\"bids\":[],\"offset\":3903327,\"nonce\":36958072,\"last_updated_at\":1785276610678598,\"begin_nonce\":36958070},\"timestamp\":1785276610683,\"type\":\"update/order_book\"}"
        "raw": "{\"channel\":\"order_book:1\",\"last_updated_at\":1785276611303177,\"offset\":3903328,\"order_book\":{\"code\":0,\"asks\":[{\"price\":\"63987.5\",\"size\":\"3.12724\"},{\"price\":\"63987.6\",\"size\":\"0.00000\"}],\"bids\":[{\"price\":\"63920.6\",\"size\":\"3.11449\"},{\"price\":\"63920.5\",\"size\":\"0.00000\"}],\"offset\":3903328,\"nonce\":36958074,\"last_updated_at\":1785276611303177,\"begin_nonce\":36958072},\"timestamp\":1785276611333,\"type\":\"update/order_book\"}"
        "raw": "{\"channel\":\"order_book:1\",\"last_updated_at\":1785276611449071,\"offset\":3903329,\"order_book\":{\"code\":0,\"asks\":[{\"price\":\"63980.0\",\"size\":\"0.00098\"}],\"bids\":[],\"offset\":3903329,\"nonce\":36958075,\"last_updated_at\":1785276611449071,\"begin_nonce\":36958074},\"timestamp\":1785276611484,\"type\":\"update/order_book\"}"
        "raw": "{\"channel\":\"order_book:1\",\"last_updated_at\":1785276611961586,\"offset\":3903331,\"order_book\":{\"code\":0,\"asks\":[{\"price\":\"63987.5\",\"size\":\"0.00000\"},{\"price\":\"63987.6\",\"size\":\"3.12724\"}],\"bids\":[{\"price\":\"63920.6\",\"size\":\"0.00000\"},{\"price\":\"63920.5\",\"size\":\"3.11449\"}],\"offset\":3903331,\"nonce\":36958081,\"last_updated_at\":1785276611961586,\"begin_nonce\":36958075},\"timestamp\":1785276611983,\"type\":\"update/order_book\"}"
        "raw": "{\"channel\":\"order_book:1\",\"last_updated_at\":1785276612226532,\"offset\":3903334,\"order_book\":{\"code\":0,\"asks\":[{\"price\":\"63987.6\",\"size\":\"0.00000\"},{\"price\":\"63988.2\",\"size\":\"3.12724\"}],\"bids\":[{\"price\":\"63920.5\",\"size\":\"0.00000\"},{\"price\":\"63919.8\",\"size\":\"3.11449\"},{\"price\":\"62929.1\",\"size\":\"0.00020\"}],\"offset\":3903334,\"nonce\":36958087,\"last_updated_at\":1785276612226532,\"begin_nonce\":36958081},\"timestamp\":1785276612234,\"type\":\"update/order_book\"}"
        "raw": "{\"channel\":\"order_book:1\",\"last_updated_at\":1785276612271142,\"offset\":3903335,\"order_book\":{\"code\":0,\"asks\":[],\"bids\":[{\"price\":\"63917.0\",\"size\":\"0.00000\"},{\"price\":\"63916.9\",\"size\":\"0.00149\"}],\"offset\":3903335,\"nonce\":36958088,\"last_updated_at\":1785276612271142,\"begin_nonce\":36958087},\"timestamp\":1785276612283,\"type\":\"update/order_book\"}"
        "raw": "{\"channel\":\"order_book:1\",\"last_updated_at\":1785276612444804,\"offset\":3903336,\"order_book\":{\"code\":0,\"asks\":[{\"price\":\"63987.6\",\"size\":\"3.12724\"},{\"price\":\"63988.2\",\"size\":\"0.00000\"}],\"bids\":[{\"price\":\"63920.5\",\"size\":\"3.11449\"},{\"price\":\"63919.8\",\"size\":\"0.00000\"}],\"offset\":3903336,\"nonce\":36958092,\"last_updated_at\":1785276612444804,\"begin_nonce\":36958088},\"timestamp\":1785276612484,\"type\":\"update/order_book\"}"
        "raw": "{\"channel\":\"order_book:1\",\"last_updated_at\":1785276612732350,\"offset\":3903346,\"order_book\":{\"code\":0,\"asks\":[{\"price\":\"63996.9\",\"size\":\"0.00163\"},{\"price\":\"64000.4\",\"size\":\"0.00000\"}],\"bids\":[{\"price\":\"63916.9\",\"size\":\"0.00000\"},{\"price\":\"63913.4\",\"size\":\"0.00149\"}],\"offset\":3903346,\"nonce\":36958105,\"last_updated_at\":1785276612732350,\"begin_nonce\":36958092},\"timestamp\":1785276612734,\"type\":\"update/order_book\"}"
        "raw": "{\"channel\":\"order_book:1\",\"last_updated_at\":1785276612916893,\"offset\":3903350,\"order_book\":{\"code\":0,\"asks\":[{\"price\":\"63987.4\",\"size\":\"3.12725\"},{\"price\":\"63987.6\",\"size\":\"0.00000\"},{\"price\":\"63996.5\",\"size\":\"0.00163\"},{\"price\":\"63996.9\",\"size\":\"0.00000\"}],\"bids\":[{\"price\":\"63920.5\",\"size\":\"0.00000\"},{\"price\":\"63917.6\",\"size\":\"3.11450\"},{\"price\":\"63913.4\",\"size\":\"0.00000\"},{\"price\":\"63913.0\",\"size\":\"0.00149\"}],\"offset\":3903350,\"nonce\":36958115,\"last_updated_at\":1785276612916893,\"begin_nonce\":36958105},\"timestamp\":1785276612934,\"type\":\"update/order_book\"}"
        "raw": "{\"channel\":\"order_book:1\",\"last_updated_at\":1785276613182940,\"offset\":3903351,\"order_book\":{\"code\":0,\"asks\":[],\"bids\":[{\"price\":\"63917.6\",\"size\":\"0.00000\"},{\"price\":\"63913.4\",\"size\":\"3.11450\"}],\"offset\":3903351,\"nonce\":36958123,\"last_updated_at\":1785276613182940,\"begin_nonce\":36958115},\"timestamp\":1785276613183,\"type\":\"update/order_book\"}"
        "raw": "{\"channel\":\"order_book:1\",\"last_updated_at\":1785276613192926,\"offset\":3903352,\"order_book\":{\"code\":0,\"asks\":[{\"price\":\"63987.4\",\"size\":\"0.00000\"},{\"price\":\"63991.0\",\"size\":\"3.12725\"}],\"bids\":[],\"offset\":3903352,\"nonce\":36958125,\"last_updated_at\":1785276613192926,\"begin_nonce\":36958123},\"timestamp\":1785276613235,\"type\":\"update/order_book\"}"
        "raw": "{\"channel\":\"order_book:1\",\"last_updated_at\":1785276613397983,\"offset\":3903353,\"order_book\":{\"code\":0,\"asks\":[{\"price\":\"63991.0\",\"size\":\"0.00000\"},{\"price\":\"63992.5\",\"size\":\"3.12725\"}],\"bids\":[{\"price\":\"63913.4\",\"size\":\"0.00000\"},{\"price\":\"63911.8\",\"size\":\"3.11450\"}],\"offset\":3903353,\"nonce\":36958131,\"last_updated_at\":1785276613397983,\"begin_nonce\":36958125},\"timestamp\":1785276613434,\"type\":\"update/order_book\"}"
        "raw": "{\"channel\":\"order_book:1\",\"last_updated_at\":1785276613615190,\"offset\":3903355,\"order_book\":{\"code\":0,\"asks\":[{\"price\":\"63990.6\",\"size\":\"3.12725\"},{\"price\":\"63992.5\",\"size\":\"0.00000\"}],\"bids\":[{\"price\":\"63913.8\",\"size\":\"3.11450\"},{\"price\":\"63911.8\",\"size\":\"0.00000\"}],\"offset\":3903355,\"nonce\":36958135,\"last_updated_at\":1785276613615190,\"begin_nonce\":36958131},\"timestamp\":1785276613635,\"type\":\"update/order_book\"}"
        "raw": "{\"channel\":\"order_book:1\",\"last_updated_at\":1785276613789015,\"offset\":3903357,\"order_book\":{\"code\":0,\"asks\":[{\"price\":\"63988.6\",\"size\":\"3.12725\"},{\"price\":\"63990.6\",\"size\":\"0.00000\"}],\"bids\":[{\"price\":\"63915.7\",\"size\":\"3.11450\"},{\"price\":\"63913.8\",\"size\":\"0.00000\"}],\"offset\":3903357,\"nonce\":36958140,\"last_updated_at\":1785276613789015,\"begin_nonce\":36958135},\"timestamp\":1785276613833,\"type\":\"update/order_book\"}"
        "raw": "{\"channel\":\"order_book:1\",\"last_updated_at\":1785276613933170,\"offset\":3903358,\"order_book\":{\"code\":0,\"asks\":[],\"bids\":[{\"price\":\"63916.8\",\"size\":\"3.11450\"},{\"price\":\"63915.7\",\"size\":\"0.00000\"}],\"offset\":3903358,\"nonce\":36958143,\"last_updated_at\":1785276613933170,\"begin_nonce\":36958140},\"timestamp\":1785276613934,\"type\":\"update/order_book\"}"
        "raw": "{\"channel\":\"order_book:1\",\"last_updated_at\":1785276613935596,\"offset\":3903359,\"order_book\":{\"code\":0,\"asks\":[{\"price\":\"63987.6\",\"size\":\"3.12724\"},{\"price\":\"63988.6\",\"size\":\"0.00000\"}],\"bids\":[],\"offset\":3903359,\"nonce\":36958144,\"last_updated_at\":1785276613935596,\"begin_nonce\":36958143},\"timestamp\":1785276613983,\"type\":\"update/order_book\"}"
        "raw": "{\"channel\":\"order_book:1\",\"last_updated_at\":1785276614482998,\"offset\":3903360,\"order_book\":{\"code\":0,\"asks\":[{\"price\":\"63987.5\",\"size\":\"3.12725\"},{\"price\":\"63987.6\",\"size\":\"0.00000\"}],\"bids\":[],\"offset\":3903360,\"nonce\":36958152,\"last_updated_at\":1785276614482998,\"begin_nonce\":36958144},\"timestamp\":1785276614483,\"type\":\"update/order_book\"}"
        "raw": "{\"channel\":\"order_book:1\",\"last_updated_at\":1785276614484566,\"offset\":3903361,\"order_book\":{\"code\":0,\"asks\":[],\"bids\":[{\"price\":\"63916.9\",\"size\":\"3.11450\"},{\"price\":\"63916.8\",\"size\":\"0.00000\"}],\"offset\":3903361,\"nonce\":36958153,\"last_updated_at\":1785276614484566,\"begin_nonce\":36958152},\"timestamp\":1785276614534,\"type\":\"update/order_book\"}"
        "raw": "{\"channel\":\"order_book:1\",\"last_updated_at\":1785276614815126,\"offset\":3903362,\"order_book\":{\"code\":0,\"asks\":[{\"price\":\"63987.4\",\"size\":\"3.12725\"},{\"price\":\"63987.5\",\"size\":\"0.00000\"}],\"bids\":[{\"price\":\"63920.6\",\"size\":\"3.11450\"},{\"price\":\"63916.9\",\"size\":\"0.00000\"}],\"offset\":3903362,\"nonce\":36958157,\"last_updated_at\":1785276614815126,\"begin_nonce\":36958153},\"timestamp\":1785276614833,\"type\":\"update/order_book\"}"
        "raw": "{\"channel\":\"order_book:1\",\"last_updated_at\":1785276615355418,\"offset\":3903363,\"order_book\":{\"code\":0,\"asks\":[{\"price\":\"63987.4\",\"size\":\"0.00000\"},{\"price\":\"63987.5\",\"size\":\"3.12725\"}],\"bids\":[{\"price\":\"63920.6\",\"size\":\"0.00000\"},{\"price\":\"63920.5\",\"size\":\"3.11450\"}],\"offset\":3903363,\"nonce\":36958162,\"last_updated_at\":1785276615355418,\"begin_nonce\":36958157},\"timestamp\":1785276615383,\"type\":\"update/order_book\"}"
        "raw": "{\"channel\":\"order_book:1\",\"last_updated_at\":1785276615892017,\"offset\":3903364,\"order_book\":{\"code\":0,\"asks\":[{\"price\":\"63987.5\",\"size\":\"0.00000\"},{\"price\":\"63987.6\",\"size\":\"3.12725\"}],\"bids\":[{\"price\":\"63920.5\",\"size\":\"0.00000\"},{\"price\":\"63920.4\",\"size\":\"3.11450\"}],\"offset\":3903364,\"nonce\":36958168,\"last_updated_at\":1785276615892017,\"begin_nonce\":36958162},\"timestamp\":1785276615934,\"type\":\"update/order_book\"}"
        "raw": "{\"channel\":\"order_book:1\",\"last_updated_at\":1785276616218747,\"offset\":3903365,\"order_book\":{\"code\":0,\"asks\":[],\"bids\":[{\"price\":\"62929.1\",\"size\":\"0.00000\"}],\"offset\":3903365,\"nonce\":36958174,\"last_updated_at\":1785276616218747,\"begin_nonce\":36958168},\"timestamp\":1785276616233,\"type\":\"update/order_book\"}"
        "raw": "{\"channel\":\"order_book:1\",\"last_updated_at\":1785276616317730,\"offset\":3903369,\"order_book\":{\"code\":0,\"asks\":[{\"price\":\"63996.0\",\"size\":\"0.00163\"},{\"price\":\"63996.5\",\"size\":\"0.00000\"}],\"bids\":[{\"price\":\"63913.0\",\"size\":\"0.00000\"},{\"price\":\"63912.5\",\"size\":\"0.00149\"}],\"offset\":3903369,\"nonce\":36958178,\"last_updated_at\":1785276616317730,\"begin_nonce\":36958174},\"timestamp\":1785276616334,\"type\":\"update/order_book\"}"
        "raw": "{\"channel\":\"order_book:1\",\"last_updated_at\":1785276616339369,\"offset\":3903370,\"order_book\":{\"code\":0,\"asks\":[],\"bids\":[{\"price\":\"63920.4\",\"size\":\"0.00000\"},{\"price\":\"63918.4\",\"size\":\"3.11450\"}],\"offset\":3903370,\"nonce\":36958179,\"last_updated_at\":1785276616339369,\"begin_nonce\":36958178},\"timestamp\":1785276616383,\"type\":\"update/order_book\"}"
        "raw": "{\"channel\":\"order_book:1\",\"last_updated_at\":1785276616830854,\"offset\":3903371,\"order_book\":{\"code\":0,\"asks\":[{\"price\":\"63987.4\",\"size\":\"3.12725\"},{\"price\":\"63987.6\",\"size\":\"0.00000\"}],\"bids\":[{\"price\":\"63918.5\",\"size\":\"3.11450\"},{\"price\":\"63918.4\",\"size\":\"0.00000\"}],\"offset\":3903371,\"nonce\":36958183,\"last_updated_at\":1785276616830854,\"begin_nonce\":36958179},\"timestamp\":1785276616833,\"type\":\"update/order_book\"}"
        "raw": "{\"channel\":\"order_book:1\",\"last_updated_at\":1785276617352506,\"offset\":3903372,\"order_book\":{\"code\":0,\"asks\":[],\"bids\":[{\"price\":\"63918.6\",\"size\":\"3.11450\"},{\"price\":\"63918.5\",\"size\":\"0.00000\"}],\"offset\":3903372,\"nonce\":36958188,\"last_updated_at\":1785276617352506,\"begin_nonce\":36958183},\"timestamp\":1785276617385,\"type\":\"update/order_book\"}"
        "raw": "{\"channel\":\"order_book:1\",\"last_updated_at\":1785276617410844,\"offset\":3903376,\"order_book\":{\"code\":0,\"asks\":[{\"price\":\"63994.3\",\"size\":\"0.00163\"},{\"price\":\"63996.0\",\"size\":\"0.00000\"}],\"bids\":[{\"price\":\"63912.5\",\"size\":\"0.00000\"},{\"price\":\"63910.8\",\"size\":\"0.00149\"}],\"offset\":3903376,\"nonce\":36958192,\"last_updated_at\":1785276617410844,\"begin_nonce\":36958188},\"timestamp\":1785276617434,\"type\":\"update/order_book\"}"
        "raw": "{\"channel\":\"order_book:1\",\"last_updated_at\":1785276617583289,\"offset\":3903385,\"order_book\":{\"code\":0,\"asks\":[{\"price\":\"63985.5\",\"size\":\"3.12762\"},{\"price\":\"63987.4\",\"size\":\"0.00000\"},{\"price\":\"63994.3\",\"size\":\"0.00000\"}],\"bids\":[{\"price\":\"63918.6\",\"size\":\"0.00000\"},{\"price\":\"63910.8\",\"size\":\"0.00000\"},{\"price\":\"63909.1\",\"size\":\"3.11487\"},{\"price\":\"63909.0\",\"size\":\"0.00149\"}],\"offset\":3903385,\"nonce\":36958203,\"last_updated_at\":1785276617583289,\"begin_nonce\":36958192},\"timestamp\":1785276617585,\"type\":\"update/order_book\"}"
        "raw": "{\"channel\":\"order_book:1\",\"last_updated_at\":1785276617606041,\"offset\":3903391,\"order_book\":{\"code\":0,\"asks\":[{\"price\":\"63991.0\",\"size\":\"0.00163\"}],\"bids\":[{\"price\":\"63909.0\",\"size\":\"0.00000\"},{\"price\":\"63907.5\",\"size\":\"0.00149\"}],\"offset\":3903391,\"nonce\":36958210,\"last_updated_at\":1785276617606041,\"begin_nonce\":36958203},\"timestamp\":1785276617634,\"type\":\"update/order_book\"}"
        "raw": "{\"channel\":\"order_book:1\",\"last_updated_at\":1785276617713492,\"offset\":3903393,\"order_book\":{\"code\":0,\"asks\":[],\"bids\":[{\"price\":\"63907.5\",\"size\":\"0.00000\"},{\"price\":\"63907.4\",\"size\":\"0.00149\"}],\"offset\":3903393,\"nonce\":36958215,\"last_updated_at\":1785276617713492,\"begin_nonce\":36958210},\"timestamp\":1785276617734,\"type\":\"update/order_book\"}"
        "raw": "{\"channel\":\"order_book:1\",\"last_updated_at\":1785276617782452,\"offset\":3903395,\"order_book\":{\"code\":0,\"asks\":[{\"price\":\"63991.0\",\"size\":\"0.00000\"}],\"bids\":[{\"price\":\"63907.4\",\"size\":\"0.00000\"}],\"offset\":3903395,\"nonce\":36958221,\"last_updated_at\":1785276617782452,\"begin_nonce\":36958215},\"timestamp\":1785276617783,\"type\":\"update/order_book\"}"
        "raw": "{\"channel\":\"order_book:1\",\"last_updated_at\":1785276617829299,\"offset\":3903397,\"order_book\":{\"code\":0,\"asks\":[{\"price\":\"63985.5\",\"size\":\"0.00000\"},{\"price\":\"63987.5\",\"size\":\"3.12766\"}],\"bids\":[{\"price\":\"63909.1\",\"size\":\"0.00000\"},{\"price\":\"63907.9\",\"size\":\"3.11491\"},{\"price\":\"63906.1\",\"size\":\"0.00149\"}],\"offset\":3903397,\"nonce\":36958223,\"last_updated_at\":1785276617829299,\"begin_nonce\":36958221},\"timestamp\":1785276617833,\"type\":\"update/order_book\"}"
        "raw": "{\"channel\":\"order_book:1\",\"last_updated_at\":1785276617838497,\"offset\":3903400,\"order_book\":{\"code\":0,\"asks\":[{\"price\":\"63987.7\",\"size\":\"0.00163\"}],\"bids\":[{\"price\":\"63906.1\",\"size\":\"0.00000\"},{\"price\":\"63904.1\",\"size\":\"0.00149\"}],\"offset\":3903400,\"nonce\":36958230,\"last_updated_at\":1785276617838497,\"begin_nonce\":36958223},\"timestamp\":1785276617883,\"type\":\"update/order_book\"}"
        "raw": "{\"channel\":\"order_book:1\",\"last_updated_at\":1785276618022480,\"offset\":3903401,\"order_book\":{\"code\":0,\"asks\":[{\"price\":\"63985.2\",\"size\":\"3.12766\"},{\"price\":\"63987.5\",\"size\":\"0.00000\"}],\"bids\":[{\"price\":\"63907.9\",\"size\":\"0.00000\"},{\"price\":\"63907.8\",\"size\":\"3.11491\"}],\"offset\":3903401,\"nonce\":36958234,\"last_updated_at\":1785276618022480,\"begin_nonce\":36958230},\"timestamp\":1785276618033,\"type\":\"update/order_book\"}"
        "raw": "{\"channel\":\"order_book:1\",\"last_updated_at\":1785276618339953,\"offset\":3903402,\"order_book\":{\"code\":0,\"asks\":[{\"price\":\"63985.2\",\"size\":\"0.00000\"},{\"price\":\"63986.0\",\"size\":\"3.12766\"}],\"bids\":[],\"offset\":3903402,\"nonce\":36958239,\"last_updated_at\":1785276618339953,\"begin_nonce\":36958234},\"timestamp\":1785276618384,\"type\":\"update/order_book\"}"
        "raw": "{\"channel\":\"order_book:1\",\"last_updated_at\":1785276618902749,\"offset\":3903403,\"order_book\":{\"code\":0,\"asks\":[{\"price\":\"63985.9\",\"size\":\"3.12766\"},{\"price\":\"63986.0\",\"size\":\"0.00000\"}],\"bids\":[{\"price\":\"63907.9\",\"size\":\"3.11491\"},{\"price\":\"63907.8\",\"size\":\"0.00000\"}],\"offset\":3903403,\"nonce\":36958243,\"last_updated_at\":1785276618902749,\"begin_nonce\":36958239},\"timestamp\":1785276618934,\"type\":\"update/order_book\"}"
        "raw": "{\"channel\":\"order_book:1\",\"last_updated_at\":1785276619025300,\"offset\":3903404,\"order_book\":{\"code\":0,\"asks\":[],\"bids\":[{\"price\":\"63878.4\",\"size\":\"0.00000\"},{\"price\":\"63734.4\",\"size\":\"15.61539\"}],\"offset\":3903404,\"nonce\":36958245,\"last_updated_at\":1785276619025300,\"begin_nonce\":36958243},\"timestamp\":1785276619034,\"type\":\"update/order_book\"}"
        "raw": "{\"channel\":\"order_book:1\",\"last_updated_at\":1785276619144847,\"offset\":3903406,\"order_book\":{\"code\":0,\"asks\":[{\"price\":\"63985.9\",\"size\":\"0.00000\"},{\"price\":\"63988.1\",\"size\":\"3.12766\"}],\"bids\":[{\"price\":\"63907.9\",\"size\":\"0.00000\"},{\"price\":\"63905.7\",\"size\":\"3.11491\"}],\"offset\":3903406,\"nonce\":36958250,\"last_updated_at\":1785276619144847,\"begin_nonce\":36958245},\"timestamp\":1785276619184,\"type\":\"update/order_book\"}"
        "raw": "{\"channel\":\"order_book:1\",\"last_updated_at\":1785276619347497,\"offset\":3903407,\"order_book\":{\"code\":0,\"asks\":[{\"price\":\"63986.4\",\"size\":\"3.12766\"},{\"price\":\"63988.1\",\"size\":\"0.00000\"}],\"bids\":[{\"price\":\"63907.4\",\"size\":\"3.11491\"},{\"price\":\"63905.7\",\"size\":\"0.00000\"}],\"offset\":3903407,\"nonce\":36958253,\"last_updated_at\":1785276619347497,\"begin_nonce\":36958250},\"timestamp\":1785276619383,\"type\":\"update/order_book\"}"
        "raw": "{\"channel\":\"order_book:1\",\"last_updated_at\":1785276619516099,\"offset\":3903408,\"order_book\":{\"code\":0,\"asks\":[{\"price\":\"63980.9\",\"size\":\"3.12766\"},{\"price\":\"63986.4\",\"size\":\"0.00000\"}],\"bids\":[{\"price\":\"63908.4\",\"size\":\"3.11491\"},{\"price\":\"63907.4\",\"size\":\"0.00000\"}],\"offset\":3903408,\"nonce\":36958257,\"last_updated_at\":1785276619516099,\"begin_nonce\":36958253},\"timestamp\":1785276619533,\"type\":\"update/order_book\"}"
        "raw": "{\"channel\":\"order_book:1\",\"last_updated_at\":1785276619675614,\"offset\":3903410,\"order_book\":{\"code\":0,\"asks\":[{\"price\":\"63979.9\",\"size\":\"3.12766\"},{\"price\":\"63980.9\",\"size\":\"0.00000\"}],\"bids\":[{\"price\":\"63920.0\",\"size\":\"0.00099\"},{\"price\":\"63910.0\",\"size\":\"3.11491\"},{\"price\":\"63908.4\",\"size\":\"0.00000\"}],\"offset\":3903410,\"nonce\":36958260,\"last_updated_at\":1785276619675614,\"begin_nonce\":36958257},\"timestamp\":1785276619683,\"type\":\"update/order_book\"}"
        "raw": "{\"channel\":\"order_book:1\",\"last_updated_at\":1785276619872643,\"offset\":3903412,\"order_book\":{\"code\":0,\"asks\":[{\"price\":\"63979.1\",\"size\":\"3.12766\"},{\"price\":\"63979.9\",\"size\":\"0.00000\"}],\"bids\":[{\"price\":\"63912.0\",\"size\":\"3.11491\"},{\"price\":\"63910.0\",\"size\":\"0.00000\"}],\"offset\":3903412,\"nonce\":36958268,\"last_updated_at\":1785276619872643,\"begin_nonce\":36958260},\"timestamp\":1785276619883,\"type\":\"update/order_book\"}"
        "raw": "{\"channel\":\"order_book:1\",\"last_updated_at\":1785276620106568,\"offset\":3903416,\"order_book\":{\"code\":0,\"asks\":[{\"price\":\"63979.1\",\"size\":\"0.00000\"},{\"price\":\"63983.2\",\"size\":\"3.12766\"},{\"price\":\"63984.3\",\"size\":\"0.00163\"},{\"price\":\"63987.7\",\"size\":\"0.00000\"}],\"bids\":[{\"price\":\"63912.0\",\"size\":\"0.00000\"},{\"price\":\"63907.9\",\"size\":\"3.11491\"},{\"price\":\"63904.1\",\"size\":\"0.00000\"},{\"price\":\"63900.7\",\"size\":\"0.00149\"}],\"offset\":3903416,\"nonce\":36958275,\"last_updated_at\":1785276620106568,\"begin_nonce\":36958268},\"timestamp\":1785276620134,\"type\":\"update/order_book\"}"
        "raw": "{\"channel\":\"order_book:1\",\"last_updated_at\":1785276620250612,\"offset\":3903418,\"order_book\":{\"code\":0,\"asks\":[{\"price\":\"63981.5\",\"size\":\"3.12775\"},{\"price\":\"63983.2\",\"size\":\"0.00000\"}],\"bids\":[{\"price\":\"63907.9\",\"size\":\"0.00000\"},{\"price\":\"63906.8\",\"size\":\"3.11500\"}],\"offset\":3903418,\"nonce\":36958280,\"last_updated_at\":1785276620250612,\"begin_nonce\":36958275},\"timestamp\":1785276620284,\"type\":\"update/order_book\"}"
        "raw": "{\"channel\":\"order_book:1\",\"last_updated_at\":1785276620310401,\"offset\":3903419,\"order_book\":{\"code\":0,\"asks\":[],\"bids\":[{\"price\":\"63900.8\",\"size\":\"0.00149\"},{\"price\":\"63900.7\",\"size\":\"0.00000\"}],\"offset\":3903419,\"nonce\":36958281,\"last_updated_at\":1785276620310401,\"begin_nonce\":36958280},\"timestamp\":1785276620334,\"type\":\"update/order_book\"}"
        "raw": "{\"channel\":\"order_book:1\",\"last_updated_at\":1785276620409871,\"offset\":3903421,\"order_book\":{\"code\":0,\"asks\":[{\"price\":\"63977.4\",\"size\":\"3.12775\"},{\"price\":\"63981.5\",\"size\":\"0.00000\"}],\"bids\":[{\"price\":\"63908.6\",\"size\":\"3.11500\"},{\"price\":\"63906.8\",\"size\":\"0.00000\"}],\"offset\":3903421,\"nonce\":36958285,\"last_updated_at\":1785276620409871,\"begin_nonce\":36958281},\"timestamp\":1785276620434,\"type\":\"update/order_book\"}"
        "raw": "{\"channel\":\"order_book:1\",\"last_updated_at\":1785276620586901,\"offset\":3903422,\"order_book\":{\"code\":0,\"asks\":[{\"price\":\"63977.4\",\"size\":\"0.00000\"},{\"price\":\"63978.5\",\"size\":\"3.12775\"}],\"bids\":[{\"price\":\"63908.6\",\"size\":\"0.00000\"},{\"price\":\"63907.5\",\"size\":\"3.11500\"}],\"offset\":3903422,\"nonce\":36958288,\"last_updated_at\":1785276620586901,\"begin_nonce\":36958285},\"timestamp\":1785276620634,\"type\":\"update/order_book\"}"
        "raw": "{\"channel\":\"order_book:1\",\"last_updated_at\":1785276620812421,\"offset\":3903423,\"order_book\":{\"code\":0,\"asks\":[{\"price\":\"63977.2\",\"size\":\"3.12775\"},{\"price\":\"63978.5\",\"size\":\"0.00000\"}],\"bids\":[{\"price\":\"63908.8\",\"size\":\"3.11500\"},{\"price\":\"63907.5\",\"size\":\"0.00000\"}],\"offset\":3903423,\"nonce\":36958291,\"last_updated_at\":1785276620812421,\"begin_nonce\":36958288},\"timestamp\":1785276620833,\"type\":\"update/order_book\"}"
        "raw": "{\"channel\":\"order_book:1\",\"last_updated_at\":1785276621315186,\"offset\":3903425,\"order_book\":{\"code\":0,\"asks\":[{\"price\":\"63977.1\",\"size\":\"3.12775\"},{\"price\":\"63977.2\",\"size\":\"0.00000\"}],\"bids\":[{\"price\":\"63908.9\",\"size\":\"3.11500\"},{\"price\":\"63908.8\",\"size\":\"0.00000\"}],\"offset\":3903425,\"nonce\":36958295,\"last_updated_at\":1785276621315186,\"begin_nonce\":36958291},\"timestamp\":1785276621333,\"type\":\"update/order_book\"}"
        "raw": "{\"channel\":\"order_book:1\",\"last_updated_at\":1785276621676752,\"offset\":3903431,\"order_book\":{\"code\":0,\"asks\":[{\"price\":\"63984.3\",\"size\":\"0.00000\"},{\"price\":\"63987.7\",\"size\":\"0.00163\"}],\"bids\":[{\"price\":\"63904.2\",\"size\":\"0.00149\"},{\"price\":\"63900.8\",\"size\":\"0.00000\"}],\"offset\":3903431,\"nonce\":36958304,\"last_updated_at\":1785276621676752,\"begin_nonce\":36958295},\"timestamp\":1785276621683,\"type\":\"update/order_book\"}"
        "raw": "{\"channel\":\"order_book:1\",\"last_updated_at\":1785276621787371,\"offset\":3903432,\"order_book\":{\"code\":0,\"asks\":[{\"price\":\"63977.1\",\"size\":\"0.00000\"},{\"price\":\"63979.0\",\"size\":\"3.12775\"}],\"bids\":[{\"price\":\"63909.0\",\"size\":\"3.11500\"},{\"price\":\"63908.9\",\"size\":\"0.00000\"}],\"offset\":3903432,\"nonce\":36958307,\"last_updated_at\":1785276621787371,\"begin_nonce\":36958304},\"timestamp\":1785276621834,\"type\":\"update/order_book\"}"
        "raw": "{\"channel\":\"order_book:1\",\"last_updated_at\":1785276621978361,\"offset\":3903433,\"order_book\":{\"code\":0,\"asks\":[{\"price\":\"63979.0\",\"size\":\"0.00000\"},{\"price\":\"63981.7\",\"size\":\"3.12775\"}],\"bids\":[],\"offset\":3903433,\"nonce\":36958309,\"last_updated_at\":1785276621978361,\"begin_nonce\":36958307},\"timestamp\":1785276621984,\"type\":\"update/order_book\"}"
        "raw": "{\"channel\":\"order_book:1\",\"last_updated_at\":1785276622140628,\"offset\":3903434,\"order_book\":{\"code\":0,\"asks\":[{\"price\":\"63979.9\",\"size\":\"3.12775\"},{\"price\":\"63981.7\",\"size\":\"0.00000\"}],\"bids\":[{\"price\":\"63910.2\",\"size\":\"3.11500\"},{\"price\":\"63909.0\",\"size\":\"0.00000\"}],\"offset\":3903434,\"nonce\":36958310,\"last_updated_at\":1785276622140628,\"begin_nonce\":36958309},\"timestamp\":1785276622184,\"type\":\"update/order_book\"}"
        "raw": "{\"channel\":\"order_book:1\",\"last_updated_at\":1785276622333115,\"offset\":3903436,\"order_book\":{\"code\":0,\"asks\":[{\"price\":\"63987.7\",\"size\":\"0.00000\"},{\"price\":\"63992.4\",\"size\":\"0.00163\"}],\"bids\":[{\"price\":\"63904.2\",\"size\":\"0.00000\"}],\"offset\":3903436,\"nonce\":36958314,\"last_updated_at\":1785276622333115,\"begin_nonce\":36958310},\"timestamp\":1785276622333,\"type\":\"update/order_book\"}"
        "raw": "{\"channel\":\"order_book:1\",\"last_updated_at\":1785276622335305,\"offset\":3903437,\"order_book\":{\"code\":0,\"asks\":[],\"bids\":[{\"price\":\"63908.9\",\"size\":\"0.00149\"}],\"offset\":3903437,\"nonce\":36958315,\"last_updated_at\":1785276622335305,\"begin_nonce\":36958314},\"timestamp\":1785276622384,\"type\":\"update/order_book\"}"
        "raw": "{\"channel\":\"order_book:1\",\"last_updated_at\":1785276622659576,\"offset\":3903439,\"order_book\":{\"code\":0,\"asks\":[{\"price\":\"63979.9\",\"size\":\"3.12774\"}],\"bids\":[{\"price\":\"63910.3\",\"size\":\"3.11500\"},{\"price\":\"63910.2\",\"size\":\"0.00000\"}],\"offset\":3903439,\"nonce\":36958318,\"last_updated_at\":1785276622659576,\"begin_nonce\":36958315},\"timestamp\":1785276622683,\"type\":\"update/order_book\"}"
        "raw": "{\"channel\":\"order_book:1\",\"last_updated_at\":1785276623679454,\"offset\":3903441,\"order_book\":{\"code\":0,\"asks\":[{\"price\":\"63979.8\",\"size\":\"3.12774\"},{\"price\":\"63979.9\",\"size\":\"0.00000\"}],\"bids\":[{\"price\":\"63910.4\",\"size\":\"3.11500\"},{\"price\":\"63910.3\",\"size\":\"0.00000\"}],\"offset\":3903441,\"nonce\":36958328,\"last_updated_at\":1785276623679454,\"begin_nonce\":36958318},\"timestamp\":1785276623684,\"type\":\"update/order_book\"}"
        "raw": "{\"channel\":\"order_book:1\",\"last_updated_at\":1785276623899326,\"offset\":3903443,\"order_book\":{\"code\":0,\"asks\":[{\"price\":\"63977.7\",\"size\":\"3.12774\"},{\"price\":\"63979.8\",\"size\":\"0.00000\"}],\"bids\":[{\"price\":\"63910.4\",\"size\":\"0.00000\"},{\"price\":\"63910.3\",\"size\":\"3.11500\"}],\"offset\":3903443,\"nonce\":36958332,\"last_updated_at\":1785276623899326,\"begin_nonce\":36958328},\"timestamp\":1785276623934,\"type\":\"update/order_book\"}"
        "raw": "{\"channel\":\"order_book:1\",\"last_updated_at\":1785276624462321,\"offset\":3903445,\"order_book\":{\"code\":0,\"asks\":[{\"price\":\"63977.2\",\"size\":\"3.12774\"},{\"price\":\"63977.7\",\"size\":\"0.00000\"}],\"bids\":[{\"price\":\"63910.4\",\"size\":\"3.11500\"},{\"price\":\"63910.3\",\"size\":\"0.00000\"}],\"offset\":3903445,\"nonce\":36958339,\"last_updated_at\":1785276624462321,\"begin_nonce\":36958332},\"timestamp\":1785276624483,\"type\":\"update/order_book\"}"
        "raw": "{\"channel\":\"order_book:1\",\"last_updated_at\":1785276625012477,\"offset\":3903446,\"order_book\":{\"code\":0,\"asks\":[],\"bids\":[{\"price\":\"63910.4\",\"size\":\"0.00000\"},{\"price\":\"63910.3\",\"size\":\"3.11500\"}],\"offset\":3903446,\"nonce\":36958342,\"last_updated_at\":1785276625012477,\"begin_nonce\":36958339},\"timestamp\":1785276625033,\"type\":\"update/order_book\"}"
        "raw": "{\"channel\":\"order_book:1\",\"last_updated_at\":1785276625228995,\"offset\":3903448,\"order_book\":{\"code\":0,\"asks\":[{\"price\":\"63977.2\",\"size\":\"0.00000\"},{\"price\":\"63978.0\",\"size\":\"3.12774\"}],\"bids\":[{\"price\":\"63910.3\",\"size\":\"0.00000\"},{\"price\":\"63909.5\",\"size\":\"3.11500\"}],\"offset\":3903448,\"nonce\":36958347,\"last_updated_at\":1785276625228995,\"begin_nonce\":36958342},\"timestamp\":1785276625234,\"type\":\"update/order_book\"}"
        "raw": "{\"channel\":\"order_book:1\",\"last_updated_at\":1785276625444087,\"offset\":3903449,\"order_book\":{\"code\":0,\"asks\":[{\"price\":\"63977.2\",\"size\":\"3.12774\"},{\"price\":\"63978.0\",\"size\":\"0.00000\"}],\"bids\":[{\"price\":\"63910.3\",\"size\":\"3.11500\"},{\"price\":\"63909.5\",\"size\":\"0.00000\"}],\"offset\":3903449,\"nonce\":36958350,\"last_updated_at\":1785276625444087,\"begin_nonce\":36958347},\"timestamp\":1785276625484,\"type\":\"update/order_book\"}"
        "raw": "{\"channel\":\"order_book:1\",\"last_updated_at\":1785276626248861,\"offset\":3903453,\"order_book\":{\"code\":0,\"asks\":[{\"price\":\"63989.9\",\"size\":\"0.00163\"},{\"price\":\"63992.4\",\"size\":\"0.00000\"}],\"bids\":[{\"price\":\"63908.9\",\"size\":\"0.00000\"},{\"price\":\"63906.4\",\"size\":\"0.00149\"}],\"offset\":3903453,\"nonce\":36958360,\"last_updated_at\":1785276626248861,\"begin_nonce\":36958350},\"timestamp\":1785276626284,\"type\":\"update/order_book\"}"
        "raw": "{\"channel\":\"order_book:1\",\"last_updated_at\":1785276626521091,\"offset\":3903454,\"order_book\":{\"code\":0,\"asks\":[{\"price\":\"63977.1\",\"size\":\"3.12774\"},{\"price\":\"63977.2\",\"size\":\"0.00000\"}],\"bids\":[],\"offset\":3903454,\"nonce\":36958364,\"last_updated_at\":1785276626521091,\"begin_nonce\":36958360},\"timestamp\":1785276626534,\"type\":\"update/order_book\"}"
        "raw": "{\"channel\":\"order_book:1\",\"last_updated_at\":1785276627657741,\"offset\":3903455,\"order_book\":{\"code\":0,\"asks\":[{\"price\":\"63977.1\",\"size\":\"0.00000\"},{\"price\":\"63977.2\",\"size\":\"3.12774\"}],\"bids\":[{\"price\":\"63910.3\",\"size\":\"0.00000\"},{\"price\":\"63910.2\",\"size\":\"3.11500\"}],\"offset\":3903455,\"nonce\":36958370,\"last_updated_at\":1785276627657741,\"begin_nonce\":36958364},\"timestamp\":1785276627683,\"type\":\"update/order_book\"}"
        "raw": "{\"channel\":\"order_book:1\",\"last_updated_at\":1785276627822744,\"offset\":3903457,\"order_book\":{\"code\":0,\"asks\":[],\"bids\":[{\"price\":\"63906.5\",\"size\":\"0.00149\"},{\"price\":\"63906.4\",\"size\":\"0.00000\"}],\"offset\":3903457,\"nonce\":36958372,\"last_updated_at\":1785276627822744,\"begin_nonce\":36958370},\"timestamp\":1785276627834,\"type\":\"update/order_book\"}"
        "raw": "{\"channel\":\"order_book:1\",\"last_updated_at\":1785276629482154,\"offset\":3903459,\"order_book\":{\"code\":0,\"asks\":[{\"price\":\"63989.9\",\"size\":\"0.00000\"}],\"bids\":[{\"price\":\"63906.5\",\"size\":\"0.00000\"}],\"offset\":3903459,\"nonce\":36958381,\"last_updated_at\":1785276629482154,\"begin_nonce\":36958372},\"timestamp\":1785276629484,\"type\":\"update/order_book\"}"
        "raw": "{\"channel\":\"order_book:1\",\"last_updated_at\":1785276629940613,\"offset\":3903462,\"order_book\":{\"code\":0,\"asks\":[],\"bids\":[{\"price\":\"63910.2\",\"size\":\"0.00000\"},{\"price\":\"63910.1\",\"size\":\"3.11500\"}],\"offset\":3903462,\"nonce\":36958387,\"last_updated_at\":1785276629940613,\"begin_nonce\":36958383},\"timestamp\":1785276629984,\"type\":\"update/order_book\"}"
        "raw": "{\"channel\":\"order_book:1\",\"last_updated_at\":1785276630271559,\"offset\":3903463,\"order_book\":{\"code\":0,\"asks\":[{\"price\":\"63987.9\",\"size\":\"0.00000\"},{\"price\":\"63988.0\",\"size\":\"0.00163\"}],\"bids\":[],\"offset\":3903463,\"nonce\":36958389,\"last_updated_at\":1785276630271559,\"begin_nonce\":36958387},\"timestamp\":1785276630283,\"type\":\"update/order_book\"}"
        "raw": "{\"channel\":\"order_book:1\",\"last_updated_at\":1785276630444833,\"offset\":3903464,\"order_book\":{\"code\":0,\"asks\":[{\"price\":\"63977.1\",\"size\":\"3.12774\"},{\"price\":\"63977.2\",\"size\":\"0.00000\"}],\"bids\":[],\"offset\":3903464,\"nonce\":36958390,\"last_updated_at\":1785276630444833,\"begin_nonce\":36958389},\"timestamp\":1785276630483,\"type\":\"update/order_book\"}"
        "raw": "{\"channel\":\"order_book:1\",\"last_updated_at\":1785276630522790,\"offset\":3903465,\"order_book\":{\"code\":0,\"asks\":[],\"bids\":[{\"price\":\"63904.6\",\"size\":\"0.00149\"},{\"price\":\"63904.5\",\"size\":\"0.00000\"}],\"offset\":3903465,\"nonce\":36958391,\"last_updated_at\":1785276630522790,\"begin_nonce\":36958390},\"timestamp\":1785276630534,\"type\":\"update/order_book\"}"
        "raw": "{\"channel\":\"order_book:1\",\"last_updated_at\":1785276631719709,\"offset\":3903466,\"order_book\":{\"code\":0,\"asks\":[{\"price\":\"63977.1\",\"size\":\"0.00000\"},{\"price\":\"63977.2\",\"size\":\"3.12774\"}],\"bids\":[{\"price\":\"63910.2\",\"size\":\"3.11500\"},{\"price\":\"63910.1\",\"size\":\"0.00000\"}],\"offset\":3903466,\"nonce\":36958397,\"last_updated_at\":1785276631719709,\"begin_nonce\":36958391},\"timestamp\":1785276631734,\"type\":\"update/order_book\"}"
        "raw": "{\"channel\":\"order_book:1\",\"last_updated_at\":1785276632071090,\"offset\":3903467,\"order_book\":{\"code\":0,\"asks\":[],\"bids\":[{\"price\":\"63904.7\",\"size\":\"0.00149\"},{\"price\":\"63904.6\",\"size\":\"0.00000\"}],\"offset\":3903467,\"nonce\":36958401,\"last_updated_at\":1785276632071090,\"begin_nonce\":36958397},\"timestamp\":1785276632084,\"type\":\"update/order_book\"}"
        "raw": "{\"channel\":\"order_book:1\",\"last_updated_at\":1785276632406662,\"offset\":3903468,\"order_book\":{\"code\":0,\"asks\":[{\"price\":\"63977.0\",\"size\":\"3.12774\"},{\"price\":\"63977.2\",\"size\":\"0.00000\"}],\"bids\":[{\"price\":\"63910.4\",\"size\":\"3.11500\"},{\"price\":\"63910.2\",\"size\":\"0.00000\"}],\"offset\":3903468,\"nonce\":36958403,\"last_updated_at\":1785276632406662,\"begin_nonce\":36958401},\"timestamp\":1785276632433,\"type\":\"update/order_book\"}"
        "raw": "{\"channel\":\"order_book:1\",\"last_updated_at\":1785276632511378,\"offset\":3903469,\"order_book\":{\"code\":0,\"asks\":[{\"price\":\"63977.0\",\"size\":\"3.12773\"}],\"bids\":[],\"offset\":3903469,\"nonce\":36958405,\"last_updated_at\":1785276632511378,\"begin_nonce\":36958403},\"timestamp\":1785276632534,\"type\":\"update/order_book\"}"
        "raw": "{\"channel\":\"order_book:1\",\"last_updated_at\":1785276633061189,\"offset\":3903470,\"order_book\":{\"code\":0,\"asks\":[{\"price\":\"63977.0\",\"size\":\"0.00000\"},{\"price\":\"63977.2\",\"size\":\"3.12773\"}],\"bids\":[{\"price\":\"63910.4\",\"size\":\"0.00000\"},{\"price\":\"63910.2\",\"size\":\"3.11500\"}],\"offset\":3903470,\"nonce\":36958408,\"last_updated_at\":1785276633061189,\"begin_nonce\":36958405},\"timestamp\":1785276633084,\"type\":\"update/order_book\"}"
        "raw": "{\"channel\":\"order_book:1\",\"last_updated_at\":1785276633381299,\"offset\":3903472,\"order_book\":{\"code\":0,\"asks\":[],\"bids\":[{\"price\":\"63904.8\",\"size\":\"0.00149\"},{\"price\":\"63904.7\",\"size\":\"0.00000\"}],\"offset\":3903472,\"nonce\":36958411,\"last_updated_at\":1785276633381299,\"begin_nonce\":36958408},\"timestamp\":1785276633384,\"type\":\"update/order_book\"}"
        "raw": "{\"channel\":\"order_book:1\",\"last_updated_at\":1785276633568752,\"offset\":3903473,\"order_book\":{\"code\":0,\"asks\":[{\"price\":\"63977.1\",\"size\":\"3.12774\"},{\"price\":\"63977.2\",\"size\":\"0.00000\"}],\"bids\":[{\"price\":\"63910.4\",\"size\":\"3.11500\"},{\"price\":\"63910.2\",\"size\":\"0.00000\"}],\"offset\":3903473,\"nonce\":36958414,\"last_updated_at\":1785276633568752,\"begin_nonce\":36958411},\"timestamp\":1785276633583,\"type\":\"update/order_book\"}"
        "raw": "{\"channel\":\"order_book:1\",\"last_updated_at\":1785276633942951,\"offset\":3903475,\"order_book\":{\"code\":0,\"asks\":[{\"price\":\"63988.0\",\"size\":\"0.00000\"},{\"price\":\"63988.1\",\"size\":\"0.00163\"}],\"bids\":[],\"offset\":3903475,\"nonce\":36958423,\"last_updated_at\":1785276633942951,\"begin_nonce\":36958414},\"timestamp\":1785276633984,\"type\":\"update/order_book\"}"
        "raw": "{\"channel\":\"order_book:1\",\"last_updated_at\":1785276634146937,\"offset\":3903477,\"order_book\":{\"code\":0,\"asks\":[{\"price\":\"63977.1\",\"size\":\"0.00000\"},{\"price\":\"63981.3\",\"size\":\"3.12774\"}],\"bids\":[{\"price\":\"63910.4\",\"size\":\"0.00000\"},{\"price\":\"63906.1\",\"size\":\"3.11500\"}],\"offset\":3903477,\"nonce\":36958431,\"last_updated_at\":1785276634146937,\"begin_nonce\":36958423},\"timestamp\":1785276634183,\"type\":\"update/order_book\"}"
        "raw": "{\"channel\":\"order_book:1\",\"last_updated_at\":1785276634362729,\"offset\":3903478,\"order_book\":{\"code\":0,\"asks\":[{\"price\":\"63981.3\",\"size\":\"0.00000\"},{\"price\":\"63982.4\",\"size\":\"3.12774\"}],\"bids\":[{\"price\":\"63906.1\",\"size\":\"0.00000\"},{\"price\":\"63905.0\",\"size\":\"3.11500\"}],\"offset\":3903478,\"nonce\":36958435,\"last_updated_at\":1785276634362729,\"begin_nonce\":36958431},\"timestamp\":1785276634383,\"type\":\"update/order_book\"}"
        "raw": "{\"channel\":\"order_book:1\",\"last_updated_at\":1785276634563924,\"offset\":3903479,\"order_book\":{\"code\":0,\"asks\":[{\"price\":\"63980.6\",\"size\":\"3.12774\"},{\"price\":\"63982.4\",\"size\":\"0.00000\"}],\"bids\":[{\"price\":\"63906.8\",\"size\":\"3.11500\"},{\"price\":\"63905.0\",\"size\":\"0.00000\"}],\"offset\":3903479,\"nonce\":36958437,\"last_updated_at\":1785276634563924,\"begin_nonce\":36958435},\"timestamp\":1785276634583,\"type\":\"update/order_book\"}"
        "raw": "{\"channel\":\"order_book:1\",\"last_updated_at\":1785276634702484,\"offset\":3903481,\"order_book\":{\"code\":0,\"asks\":[],\"bids\":[{\"price\":\"63904.9\",\"size\":\"0.00149\"},{\"price\":\"63904.8\",\"size\":\"0.00000\"}],\"offset\":3903481,\"nonce\":36958442,\"last_updated_at\":1785276634702484,\"begin_nonce\":36958437},\"timestamp\":1785276634734,\"type\":\"update/order_book\"}"
        "raw": "{\"channel\":\"order_book:1\",\"last_updated_at\":1785276634921397,\"offset\":3903482,\"order_book\":{\"code\":0,\"asks\":[{\"price\":\"63977.2\",\"size\":\"3.12774\"},{\"price\":\"63980.6\",\"size\":\"0.00000\"}],\"bids\":[{\"price\":\"63910.2\",\"size\":\"3.11500\"},{\"price\":\"63906.8\",\"size\":\"0.00000\"}],\"offset\":3903482,\"nonce\":36958443,\"last_updated_at\":1785276634921397,\"begin_nonce\":36958442},\"timestamp\":1785276634934,\"type\":\"update/order_book\"}"
        "raw": "{\"channel\":\"order_book:1\",\"last_updated_at\":1785276635439902,\"offset\":3903483,\"order_book\":{\"code\":0,\"asks\":[{\"price\":\"63977.2\",\"size\":\"0.00000\"},{\"price\":\"63977.3\",\"size\":\"3.12774\"}],\"bids\":[],\"offset\":3903483,\"nonce\":36958448,\"last_updated_at\":1785276635439902,\"begin_nonce\":36958443},\"timestamp\":1785276635484,\"type\":\"update/order_book\"}"
        "raw": "{\"channel\":\"order_book:1\",\"last_updated_at\":1785276635952394,\"offset\":3903484,\"order_book\":{\"code\":0,\"asks\":[{\"price\":\"63977.2\",\"size\":\"3.12774\"},{\"price\":\"63977.3\",\"size\":\"0.00000\"}],\"bids\":[],\"offset\":3903484,\"nonce\":36958452,\"last_updated_at\":1785276635952394,\"begin_nonce\":36958448},\"timestamp\":1785276635984,\"type\":\"update/order_book\"}"
        "raw": "{\"channel\":\"order_book:1\",\"last_updated_at\":1785276636324117,\"offset\":3903486,\"order_book\":{\"code\":0,\"asks\":[],\"bids\":[{\"price\":\"63905.0\",\"size\":\"0.00149\"},{\"price\":\"63904.9\",\"size\":\"0.00000\"}],\"offset\":3903486,\"nonce\":36958455,\"last_updated_at\":1785276636324117,\"begin_nonce\":36958452},\"timestamp\":1785276636334,\"type\":\"update/order_book\"}"
        "raw": "{\"channel\":\"order_book:1\",\"last_updated_at\":1785276636466405,\"offset\":3903488,\"order_book\":{\"code\":0,\"asks\":[{\"price\":\"63977.1\",\"size\":\"3.12774\"},{\"price\":\"63977.2\",\"size\":\"0.00000\"}],\"bids\":[{\"price\":\"63910.4\",\"size\":\"3.11500\"},{\"price\":\"63910.2\",\"size\":\"0.00000\"}],\"offset\":3903488,\"nonce\":36958457,\"last_updated_at\":1785276636466405,\"begin_nonce\":36958455},\"timestamp\":1785276636484,\"type\":\"update/order_book\"}"
        "raw": "{\"channel\":\"order_book:1\",\"last_updated_at\":1785276637045089,\"offset\":3903489,\"order_book\":{\"code\":0,\"asks\":[{\"price\":\"63977.1\",\"size\":\"0.00000\"},{\"price\":\"63977.3\",\"size\":\"3.12774\"}],\"bids\":[{\"price\":\"63910.4\",\"size\":\"0.00000\"},{\"price\":\"63910.1\",\"size\":\"3.11500\"}],\"offset\":3903489,\"nonce\":36958460,\"last_updated_at\":1785276637045089,\"begin_nonce\":36958457},\"timestamp\":1785276637083,\"type\":\"update/order_book\"}"
        "raw": "{\"channel\":\"order_book:1\",\"last_updated_at\":1785276637563459,\"offset\":3903490,\"order_book\":{\"code\":0,\"asks\":[{\"price\":\"63977.2\",\"size\":\"3.12774\"},{\"price\":\"63977.3\",\"size\":\"0.00000\"}],\"bids\":[{\"price\":\"63910.3\",\"size\":\"3.11500\"},{\"price\":\"63910.1\",\"size\":\"0.00000\"}],\"offset\":3903490,\"nonce\":36958465,\"last_updated_at\":1785276637563459,\"begin_nonce\":36958460},\"timestamp\":1785276637584,\"type\":\"update/order_book\"}"
        "raw": "{\"channel\":\"order_book:1\",\"last_updated_at\":1785276637694145,\"offset\":3903491,\"order_book\":{\"code\":0,\"asks\":[],\"bids\":[{\"price\":\"63920.0\",\"size\":\"0.00098\"}],\"offset\":3903491,\"nonce\":36958467,\"last_updated_at\":1785276637694145,\"begin_nonce\":36958465},\"timestamp\":1785276637734,\"type\":\"update/order_book\"}"
        "raw": "{\"channel\":\"order_book:1\",\"last_updated_at\":1785276637812822,\"offset\":3903493,\"order_book\":{\"code\":0,\"asks\":[{\"price\":\"63988.1\",\"size\":\"0.00000\"},{\"price\":\"63988.2\",\"size\":\"0.00163\"}],\"bids\":[],\"offset\":3903493,\"nonce\":36958469,\"last_updated_at\":1785276637812822,\"begin_nonce\":36958467},\"timestamp\":1785276637834,\"type\":\"update/order_book\"}"
        "raw": "{\"channel\":\"order_book:1\",\"last_updated_at\":1785276638085996,\"offset\":3903494,\"order_book\":{\"code\":0,\"asks\":[{\"price\":\"63977.1\",\"size\":\"3.12774\"},{\"price\":\"63977.2\",\"size\":\"0.00000\"}],\"bids\":[],\"offset\":3903494,\"nonce\":36958473,\"last_updated_at\":1785276638085996,\"begin_nonce\":36958469},\"timestamp\":1785276638134,\"type\":\"update/order_book\"}"
        "raw": "{\"channel\":\"order_book:1\",\"last_updated_at\":1785276638589441,\"offset\":3903495,\"order_book\":{\"code\":0,\"asks\":[{\"price\":\"63977.1\",\"size\":\"0.00000\"},{\"price\":\"63977.2\",\"size\":\"3.12774\"}],\"bids\":[{\"price\":\"63910.3\",\"size\":\"0.00000\"},{\"price\":\"63910.2\",\"size\":\"3.11500\"}],\"offset\":3903495,\"nonce\":36958477,\"last_updated_at\":1785276638589441,\"begin_nonce\":36958473},\"timestamp\":1785276638633,\"type\":\"update/order_book\"}"
        "raw": "{\"channel\":\"order_book:1\",\"last_updated_at\":1785276639115139,\"offset\":3903496,\"order_book\":{\"code\":0,\"asks\":[],\"bids\":[{\"price\":\"63910.3\",\"size\":\"3.11500\"},{\"price\":\"63910.2\",\"size\":\"0.00000\"}],\"offset\":3903496,\"nonce\":36958480,\"last_updated_at\":1785276639115139,\"begin_nonce\":36958477},\"timestamp\":1785276639134,\"type\":\"update/order_book\"}"
        "raw": "{\"channel\":\"order_book:1\",\"last_updated_at\":1785276639619016,\"offset\":3903497,\"order_book\":{\"code\":0,\"asks\":[{\"price\":\"63977.1\",\"size\":\"3.12774\"},{\"price\":\"63977.2\",\"size\":\"0.00000\"}],\"bids\":[],\"offset\":3903497,\"nonce\":36958487,\"last_updated_at\":1785276639619016,\"begin_nonce\":36958480},\"timestamp\":1785276639634,\"type\":\"update/order_book\"}"
        "raw": "{\"channel\":\"order_book:1\",\"last_updated_at\":1785276640011855,\"offset\":3903498,\"order_book\":{\"code\":0,\"asks\":[],\"bids\":[{\"price\":\"63905.1\",\"size\":\"0.00149\"},{\"price\":\"63905.0\",\"size\":\"0.00000\"}],\"offset\":3903498,\"nonce\":36958494,\"last_updated_at\":1785276640011855,\"begin_nonce\":36958487},\"timestamp\":1785276640034,\"type\":\"update/order_book\"}"
        "raw": "{\"channel\":\"order_book:1\",\"last_updated_at\":1785276640172019,\"offset\":3903500,\"order_book\":{\"code\":0,\"asks\":[{\"price\":\"63977.1\",\"size\":\"0.00000\"},{\"price\":\"63981.1\",\"size\":\"3.12774\"}],\"bids\":[{\"price\":\"63910.3\",\"size\":\"0.00000\"},{\"price\":\"63906.3\",\"size\":\"3.11500\"}],\"offset\":3903500,\"nonce\":36958497,\"last_updated_at\":1785276640172019,\"begin_nonce\":36958494},\"timestamp\":1785276640183,\"type\":\"update/order_book\"}"
        "raw": "{\"channel\":\"order_book:1\",\"last_updated_at\":1785276640381113,\"offset\":3903501,\"order_book\":{\"code\":0,\"asks\":[{\"price\":\"63977.6\",\"size\":\"3.12774\"},{\"price\":\"63981.1\",\"size\":\"0.00000\"}],\"bids\":[{\"price\":\"63909.8\",\"size\":\"3.11500\"},{\"price\":\"63906.3\",\"size\":\"0.00000\"}],\"offset\":3903501,\"nonce\":36958500,\"last_updated_at\":1785276640381113,\"begin_nonce\":36958497},\"timestamp\":1785276640383,\"type\":\"update/order_book\"}"
        "raw": "{\"channel\":\"order_book:1\",\"last_updated_at\":1785276641127552,\"offset\":3903502,\"order_book\":{\"code\":0,\"asks\":[{\"price\":\"63977.2\",\"size\":\"3.12774\"},{\"price\":\"63977.6\",\"size\":\"0.00000\"}],\"bids\":[{\"price\":\"63910.2\",\"size\":\"3.11500\"},{\"price\":\"63909.8\",\"size\":\"0.00000\"}],\"offset\":3903502,\"nonce\":36958504,\"last_updated_at\":1785276641127552,\"begin_nonce\":36958500},\"timestamp\":1785276641133,\"type\":\"update/order_book\"}"
        "raw": "{\"channel\":\"order_book:1\",\"last_updated_at\":1785276641577628,\"offset\":3903503,\"order_book\":{\"code\":0,\"asks\":[{\"price\":\"63977.2\",\"size\":\"0.00000\"},{\"price\":\"63981.2\",\"size\":\"3.12774\"}],\"bids\":[{\"price\":\"63910.2\",\"size\":\"0.00000\"},{\"price\":\"63906.2\",\"size\":\"3.11500\"}],\"offset\":3903503,\"nonce\":36958512,\"last_updated_at\":1785276641577628,\"begin_nonce\":36958504},\"timestamp\":1785276641583,\"type\":\"update/order_book\"}"
        "raw": "{\"channel\":\"order_book:1\",\"last_updated_at\":1785276641773510,\"offset\":3903504,\"order_book\":{\"code\":0,\"asks\":[{\"price\":\"63978.6\",\"size\":\"3.12774\"},{\"price\":\"63981.2\",\"size\":\"0.00000\"}],\"bids\":[{\"price\":\"63908.8\",\"size\":\"3.11500\"},{\"price\":\"63906.2\",\"size\":\"0.00000\"}],\"offset\":3903504,\"nonce\":36958514,\"last_updated_at\":1785276641773510,\"begin_nonce\":36958512},\"timestamp\":1785276641783,\"type\":\"update/order_book\"}"
        "raw": "{\"channel\":\"order_book:1\",\"last_updated_at\":1785276641917280,\"offset\":3903505,\"order_book\":{\"code\":0,\"asks\":[{\"price\":\"63977.3\",\"size\":\"3.12774\"},{\"price\":\"63978.6\",\"size\":\"0.00000\"}],\"bids\":[{\"price\":\"63910.1\",\"size\":\"3.11500\"},{\"price\":\"63908.8\",\"size\":\"0.00000\"}],\"offset\":3903505,\"nonce\":36958516,\"last_updated_at\":1785276641917280,\"begin_nonce\":36958514},\"timestamp\":1785276641934,\"type\":\"update/order_book\"}"
        "raw": "{\"channel\":\"order_book:1\",\"last_updated_at\":1785276642481374,\"offset\":3903506,\"order_book\":{\"code\":0,\"asks\":[{\"price\":\"63977.1\",\"size\":\"3.12774\"},{\"price\":\"63977.3\",\"size\":\"0.00000\"}],\"bids\":[],\"offset\":3903506,\"nonce\":36958522,\"last_updated_at\":1785276642481374,\"begin_nonce\":36958516},\"timestamp\":1785276642484,\"type\":\"update/order_book\"}"
        "raw": "{\"channel\":\"order_book:1\",\"last_updated_at\":1785276642483937,\"offset\":3903507,\"order_book\":{\"code\":0,\"asks\":[],\"bids\":[{\"price\":\"63910.3\",\"size\":\"3.11500\"},{\"price\":\"63910.1\",\"size\":\"0.00000\"}],\"offset\":3903507,\"nonce\":36958523,\"last_updated_at\":1785276642483937,\"begin_nonce\":36958522},\"timestamp\":1785276642534,\"type\":\"update/order_book\"}"
        "raw": "{\"channel\":\"order_book:1\",\"last_updated_at\":1785276642606247,\"offset\":3903511,\"order_book\":{\"code\":0,\"asks\":[{\"price\":\"63985.2\",\"size\":\"0.00163\"},{\"price\":\"63988.2\",\"size\":\"0.00000\"}],\"bids\":[{\"price\":\"63905.1\",\"size\":\"0.00000\"},{\"price\":\"63902.1\",\"size\":\"0.00149\"}],\"offset\":3903511,\"nonce\":36958529,\"last_updated_at\":1785276642606247,\"begin_nonce\":36958523},\"timestamp\":1785276642633,\"type\":\"update/order_book\"}"
        "raw": "{\"channel\":\"order_book:1\",\"last_updated_at\":1785276642721548,\"offset\":3903513,\"order_book\":{\"code\":0,\"asks\":[{\"price\":\"63977.0\",\"size\":\"3.12774\"},{\"price\":\"63977.1\",\"size\":\"0.00000\"}],\"bids\":[{\"price\":\"63910.3\",\"size\":\"0.00000\"},{\"price\":\"63909.5\",\"size\":\"3.11500\"}],\"offset\":3903513,\"nonce\":36958532,\"last_updated_at\":1785276642721548,\"begin_nonce\":36958529},\"timestamp\":1785276642734,\"type\":\"update/order_book\"}"
        "raw": "{\"channel\":\"order_book:1\",\"last_updated_at\":1785276642781266,\"offset\":3903521,\"order_book\":{\"code\":0,\"asks\":[{\"price\":\"63985.2\",\"size\":\"0.00000\"}],\"bids\":[{\"price\":\"63902.1\",\"size\":\"0.00000\"}],\"offset\":3903521,\"nonce\":36958540,\"last_updated_at\":1785276642781266,\"begin_nonce\":36958532},\"timestamp\":1785276642784,\"type\":\"update/order_book\"}"
        "raw": "{\"channel\":\"order_book:1\",\"last_updated_at\":1785276642882347,\"offset\":3903529,\"order_book\":{\"code\":0,\"asks\":[{\"price\":\"63983.0\",\"size\":\"0.00000\"}],\"bids\":[{\"price\":\"63899.9\",\"size\":\"0.00000\"}],\"offset\":3903529,\"nonce\":36958551,\"last_updated_at\":1785276642882347,\"begin_nonce\":36958545},\"timestamp\":1785276642883,\"type\":\"update/order_book\"}"
        "raw": "{\"channel\":\"order_book:1\",\"last_updated_at\":1785276642900916,\"offset\":3903535,\"order_book\":{\"code\":0,\"asks\":[{\"price\":\"63976.3\",\"size\":\"3.12800\"},{\"price\":\"63977.0\",\"size\":\"0.00000\"},{\"price\":\"63980.0\",\"size\":\"0.00261\"}],\"bids\":[{\"price\":\"63909.5\",\"size\":\"0.00000\"},{\"price\":\"63902.3\",\"size\":\"3.11526\"},{\"price\":\"63897.0\",\"size\":\"0.00149\"}],\"offset\":3903535,\"nonce\":36958558,\"last_updated_at\":1785276642900916,\"begin_nonce\":36958551},\"timestamp\":1785276642934,\"type\":\"update/order_book\"}"
        "raw": "{\"channel\":\"order_book:1\",\"last_updated_at\":1785276643081931,\"offset\":3903537,\"order_book\":{\"code\":0,\"asks\":[{\"price\":\"63976.3\",\"size\":\"0.00000\"},{\"price\":\"63976.5\",\"size\":\"3.12800\"}],\"bids\":[{\"price\":\"63902.3\",\"size\":\"0.00000\"},{\"price\":\"63897.9\",\"size\":\"9.34220\"}],\"offset\":3903537,\"nonce\":36958563,\"last_updated_at\":1785276643081931,\"begin_nonce\":36958558},\"timestamp\":1785276643083,\"type\":\"update/order_book\"}"
        "raw": "{\"channel\":\"order_book:1\",\"last_updated_at\":1785276643128243,\"offset\":3903538,\"order_book\":{\"code\":0,\"asks\":[{\"price\":\"63980.0\",\"size\":\"0.00098\"}],\"bids\":[],\"offset\":3903538,\"nonce\":36958568,\"last_updated_at\":1785276643128243,\"begin_nonce\":36958563},\"timestamp\":1785276643134,\"type\":\"update/order_book\"}"
        "raw": "{\"channel\":\"order_book:1\",\"last_updated_at\":1785276643134312,\"offset\":3903539,\"order_book\":{\"code\":0,\"asks\":[{\"price\":\"63980.1\",\"size\":\"0.00163\"}],\"bids\":[],\"offset\":3903539,\"nonce\":36958571,\"last_updated_at\":1785276643134312,\"begin_nonce\":36958568},\"timestamp\":1785276643184,\"type\":\"update/order_book\"}"
        "raw": "{\"channel\":\"order_book:1\",\"last_updated_at\":1785276643221750,\"offset\":3903541,\"order_book\":{\"code\":0,\"asks\":[{\"price\":\"63976.5\",\"size\":\"0.00000\"},{\"price\":\"63978.9\",\"size\":\"3.12800\"}],\"bids\":[{\"price\":\"63900.6\",\"size\":\"3.11526\"},{\"price\":\"63897.9\",\"size\":\"6.22694\"}],\"offset\":3903541,\"nonce\":36958574,\"last_updated_at\":1785276643221750,\"begin_nonce\":36958571},\"timestamp\":1785276643234,\"type\":\"update/order_book\"}"
        "raw": "{\"channel\":\"order_book:1\",\"last_updated_at\":1785276643405067,\"offset\":3903543,\"order_book\":{\"code\":0,\"asks\":[{\"price\":\"63977.6\",\"size\":\"3.12800\"},{\"price\":\"63978.9\",\"size\":\"0.00000\"}],\"bids\":[{\"price\":\"63901.8\",\"size\":\"3.11526\"},{\"price\":\"63900.6\",\"size\":\"0.00000\"}],\"offset\":3903543,\"nonce\":36958579,\"last_updated_at\":1785276643405067,\"begin_nonce\":36958574},\"timestamp\":1785276643434,\"type\":\"update/order_book\"}"
        "raw": "{\"channel\":\"order_book:1\",\"last_updated_at\":1785276643593432,\"offset\":3903545,\"order_book\":{\"code\":0,\"asks\":[{\"price\":\"63977.6\",\"size\":\"0.00000\"},{\"price\":\"63978.4\",\"size\":\"3.12800\"}],\"bids\":[{\"price\":\"63901.8\",\"size\":\"0.00000\"},{\"price\":\"63901.0\",\"size\":\"3.11526\"}],\"offset\":3903545,\"nonce\":36958586,\"last_updated_at\":1785276643593432,\"begin_nonce\":36958579},\"timestamp\":1785276643634,\"type\":\"update/order_book\"}"
        "raw": "{\"channel\":\"order_book:1\",\"last_updated_at\":1785276643728277,\"offset\":3903547,\"order_book\":{\"code\":0,\"asks\":[{\"price\":\"63977.4\",\"size\":\"3.12800\"},{\"price\":\"63978.4\",\"size\":\"0.00000\"}],\"bids\":[{\"price\":\"63902.0\",\"size\":\"3.11526\"},{\"price\":\"63901.0\",\"size\":\"0.00000\"}],\"offset\":3903547,\"nonce\":36958590,\"last_updated_at\":1785276643728277,\"begin_nonce\":36958586},\"timestamp\":1785276643734,\"type\":\"update/order_book\"}"
        "raw": "{\"channel\":\"order_book:1\",\"last_updated_at\":1785276643972611,\"offset\":3903549,\"order_book\":{\"code\":0,\"asks\":[{\"price\":\"63980.1\",\"size\":\"0.00000\"},{\"price\":\"63980.2\",\"size\":\"0.00163\"}],\"bids\":[],\"offset\":3903549,\"nonce\":36958596,\"last_updated_at\":1785276643972611,\"begin_nonce\":36958590},\"timestamp\":1785276643984,\"type\":\"update/order_book\"}"
        "raw": "{\"channel\":\"order_book:1\",\"last_updated_at\":1785276644002313,\"offset\":3903550,\"order_book\":{\"code\":0,\"asks\":[],\"bids\":[{\"price\":\"63897.1\",\"size\":\"0.00149\"},{\"price\":\"63897.0\",\"size\":\"0.00000\"}],\"offset\":3903550,\"nonce\":36958598,\"last_updated_at\":1785276644002313,\"begin_nonce\":36958596},\"timestamp\":1785276644034,\"type\":\"update/order_book\"}"
        "raw": "{\"channel\":\"order_book:1\",\"last_updated_at\":1785276644092096,\"offset\":3903551,\"order_book\":{\"code\":0,\"asks\":[{\"price\":\"63977.4\",\"size\":\"0.00000\"},{\"price\":\"63977.5\",\"size\":\"3.12800\"}],\"bids\":[],\"offset\":3903551,\"nonce\":36958601,\"last_updated_at\":1785276644092096,\"begin_nonce\":36958598},\"timestamp\":1785276644133,\"type\":\"update/order_book\"}"
        "raw": "{\"channel\":\"order_book:1\",\"last_updated_at\":1785276644232802,\"offset\":3903552,\"order_book\":{\"code\":0,\"asks\":[],\"bids\":[{\"price\":\"63868.8\",\"size\":\"0.00000\"},{\"price\":\"63724.8\",\"size\":\"15.61905\"}],\"offset\":3903552,\"nonce\":36958603,\"last_updated_at\":1785276644232802,\"begin_nonce\":36958601},\"timestamp\":1785276644234,\"type\":\"update/order_book\"}"
        "raw": "{\"channel\":\"order_book:1\",\"last_updated_at\":1785276644280164,\"offset\":3903561,\"order_book\":{\"code\":0,\"asks\":[],\"bids\":[{\"price\":\"63859.2\",\"size\":\"0.00000\"},{\"price\":\"63849.6\",\"size\":\"15.03093\"},{\"price\":\"63840.0\",\"size\":\"15.03185\"},{\"price\":\"63830.4\",\"size\":\"15.03093\"},{\"price\":\"63820.8\",\"size\":\"15.03093\"},{\"price\":\"63811.2\",\"size\":\"15.03093\"},{\"price\":\"63801.6\",\"size\":\"15.03093\"},{\"price\":\"63792.0\",\"size\":\"15.03093\"},{\"price\":\"63782.4\",\"size\":\"15.03093\"},{\"price\":\"63772.8\",\"size\":\"15.03093\"},{\"price\":\"63763.2\",\"size\":\"15.18422\"},{\"price\":\"63753.6\",\"size\":\"15.18422\"},{\"price\":\"63744.0\",\"size\":\"15.18422\"},{\"price\":\"63734.4\",\"size\":\"15.18422\"},{\"price\":\"63724.8\",\"size\":\"15.18422\"},{\"price\":\"63715.2\",\"size\":\"15.18422\"}],\"offset\":3903561,\"nonce\":36958612,\"last_updated_at\":1785276644280164,\"begin_nonce\":36958603},\"timestamp\":1785276644283,\"type\":\"update/order_book\"}"
        "raw": "{\"channel\":\"order_book:1\",\"last_updated_at\":1785276644328825,\"offset\":3903576,\"order_book\":{\"code\":0,\"asks\":[{\"price\":\"63977.5\",\"size\":\"0.00000\"},{\"price\":\"63979.2\",\"size\":\"0.00163\"},{\"price\":\"63980.1\",\"size\":\"3.12836\"},{\"price\":\"63980.2\",\"size\":\"0.00000\"}],\"bids\":[{\"price\":\"63902.0\",\"size\":\"0.00000\"},{\"price\":\"63897.9\",\"size\":\"0.00000\"},{\"price\":\"63897.1\",\"size\":\"0.00000\"},{\"price\":\"63896.1\",\"size\":\"0.00149\"},{\"price\":\"63888.3\",\"size\":\"3.08694\"},{\"price\":\"63883.5\",\"size\":\"6.17387\"},{\"price\":\"63849.6\",\"size\":\"15.38634\"},{\"price\":\"63840.0\",\"size\":\"15.38726\"},{\"price\":\"63830.4\",\"size\":\"15.38634\"},{\"price\":\"63820.8\",\"size\":\"15.38634\"},{\"price\":\"63811.2\",\"size\":\"15.38634\"},{\"price\":\"63801.6\",\"size\":\"15.38634\"},{\"price\":\"63792.0\",\"size\":\"15.38634\"},{\"price\":\"63782.4\",\"size\":\"15.38634\"},{\"price\":\"63772.8\",\"size\":\"15.38634\"},{\"price\":\"63763.2\",\"size\":\"15.38634\"},{\"price\":\"63753.6\",\"size\":\"15.38634\"},{\"price\":\"63744.0\",\"size\":\"15.38634\"},{\"price\":\"63734.4\",\"size\":\"15.38634\"},{\"price\":\"63724.8\",\"size\":\"15.38634\"},{\"price\":\"63715.2\",\"size\":\"15.38634\"}],\"offset\":3903576,\"nonce\":36958627,\"last_updated_at\":1785276644328825,\"begin_nonce\":36958612},\"timestamp\":1785276644333,\"type\":\"update/order_book\"}"
        "raw": "{\"channel\":\"order_book:1\",\"last_updated_at\":1785276644431601,\"offset\":3903581,\"order_book\":{\"code\":0,\"asks\":[{\"price\":\"63978.1\",\"size\":\"0.00163\"},{\"price\":\"63979.2\",\"size\":\"0.00000\"},{\"price\":\"63984.9\",\"size\":\"6.25673\"},{\"price\":\"63989.7\",\"size\":\"9.38509\"},{\"price\":\"63994.5\",\"size\":\"12.51345\"},{\"price\":\"64052.2\",\"size\":\"0.00000\"},{\"price\":\"64057.0\",\"size\":\"0.00000\"},{\"price\":\"64061.8\",\"size\":\"0.00000\"}],\"bids\":[{\"price\":\"63896.1\",\"size\":\"0.00000\"},{\"price\":\"63895.0\",\"size\":\"0.00149\"},{\"price\":\"63893.2\",\"size\":\"0.00000\"},{\"price\":\"63888.4\",\"size\":\"0.00000\"},{\"price\":\"63878.7\",\"size\":\"9.26080\"},{\"price\":\"63873.9\",\"size\":\"12.34773\"},{\"price\":\"63849.6\",\"size\":\"15.56266\"},{\"price\":\"63840.0\",\"size\":\"15.56358\"},{\"price\":\"63830.4\",\"size\":\"15.56266\"},{\"price\":\"63820.8\",\"size\":\"15.56266\"},{\"price\":\"63811.2\",\"size\":\"15.56266\"},{\"price\":\"63801.6\",\"size\":\"15.56266\"},{\"price\":\"63792.0\",\"size\":\"15.56266\"},{\"price\":\"63782.4\",\"size\":\"15.56266\"},{\"price\":\"63772.8\",\"size\":\"15.56266\"},{\"price\":\"63763.2\",\"size\":\"15.56266\"},{\"price\":\"63753.6\",\"size\":\"15.56266\"},{\"price\":\"63744.0\",\"size\":\"15.56266\"},{\"price\":\"63734.4\",\"size\":\"15.56266\"},{\"price\":\"63724.8\",\"size\":\"15.56266\"},{\"price\":\"63715.2\",\"size\":\"15.56266\"}],\"offset\":3903581,\"nonce\":36958632,\"last_updated_at\":1785276644431601,\"begin_nonce\":36958627},\"timestamp\":1785276644433,\"type\":\"update/order_book\"}"
        "raw": "{\"channel\":\"order_book:1\",\"last_updated_at\":1785276644523884,\"offset\":3903582,\"order_book\":{\"code\":0,\"asks\":[{\"price\":\"63977.4\",\"size\":\"3.12836\"},{\"price\":\"63980.1\",\"size\":\"0.00000\"}],\"bids\":[{\"price\":\"63890.6\",\"size\":\"3.11562\"},{\"price\":\"63888.3\",\"size\":\"0.00000\"}],\"offset\":3903582,\"nonce\":36958636,\"last_updated_at\":1785276644523884,\"begin_nonce\":36958632},\"timestamp\":1785276644533,\"type\":\"update/order_book\"}"
        "raw": "{\"channel\":\"order_book:1\",\"last_updated_at\":1785276644602441,\"offset\":3903584,\"order_book\":{\"code\":0,\"asks\":[{\"price\":\"63978.1\",\"size\":\"0.00000\"},{\"price\":\"63979.1\",\"size\":\"0.00163\"}],\"bids\":[],\"offset\":3903584,\"nonce\":36958641,\"last_updated_at\":1785276644602441,\"begin_nonce\":36958636},\"timestamp\":1785276644633,\"type\":\"update/order_book\"}"
        "raw": "{\"channel\":\"order_book:1\",\"last_updated_at\":1785276644730883,\"offset\":3903586,\"order_book\":{\"code\":0,\"asks\":[{\"price\":\"63979.1\",\"size\":\"0.00000\"}],\"bids\":[],\"offset\":3903586,\"nonce\":36958646,\"last_updated_at\":1785276644730883,\"begin_nonce\":36958641},\"timestamp\":1785276644734,\"type\":\"update/order_book\"}"
        "raw": "{\"channel\":\"order_book:1\",\"last_updated_at\":1785276644733296,\"offset\":3903587,\"order_book\":{\"code\":0,\"asks\":[{\"price\":\"63978.2\",\"size\":\"0.00163\"}],\"bids\":[],\"offset\":3903587,\"nonce\":36958647,\"last_updated_at\":1785276644733296,\"begin_nonce\":36958646},\"timestamp\":1785276644783,\"type\":\"update/order_book\"}"
        "raw": "{\"channel\":\"order_book:1\",\"last_updated_at\":1785276644826389,\"offset\":3903589,\"order_book\":{\"code\":0,\"asks\":[{\"price\":\"63973.4\",\"size\":\"3.12836\"},{\"price\":\"63977.4\",\"size\":\"0.00000\"}],\"bids\":[{\"price\":\"63891.9\",\"size\":\"3.11562\"},{\"price\":\"63890.6\",\"size\":\"0.00000\"}],\"offset\":3903589,\"nonce\":36958650,\"last_updated_at\":1785276644826389,\"begin_nonce\":36958647},\"timestamp\":1785276644834,\"type\":\"update/order_book\"}"
        "raw": "{\"channel\":\"order_book:1\",\"last_updated_at\":1785276644931522,\"offset\":3903590,\"order_book\":{\"code\":0,\"asks\":[{\"price\":\"63973.4\",\"size\":\"3.12835\"}],\"bids\":[],\"offset\":3903590,\"nonce\":36958655,\"last_updated_at\":1785276644931522,\"begin_nonce\":36958650},\"timestamp\":1785276644934,\"type\":\"update/order_book\"}"
        "raw": "{\"channel\":\"order_book:1\",\"last_updated_at\":1785276644955734,\"offset\":3903591,\"order_book\":{\"code\":0,\"asks\":[{\"price\":\"63971.6\",\"size\":\"3.12835\"},{\"price\":\"63973.4\",\"size\":\"0.00000\"}],\"bids\":[{\"price\":\"63893.7\",\"size\":\"3.11562\"},{\"price\":\"63891.9\",\"size\":\"0.00000\"}],\"offset\":3903591,\"nonce\":36958657,\"last_updated_at\":1785276644955734,\"begin_nonce\":36958655},\"timestamp\":1785276644984,\"type\":\"update/order_book\"}"
        "raw": "{\"channel\":\"order_book:1\",\"last_updated_at\":1785276645157676,\"offset\":3903593,\"order_book\":{\"code\":0,\"asks\":[{\"price\":\"63971.6\",\"size\":\"0.00000\"},{\"price\":\"63974.0\",\"size\":\"3.12835\"}],\"bids\":[{\"price\":\"63893.7\",\"size\":\"0.00000\"},{\"price\":\"63889.2\",\"size\":\"3.11562\"}],\"offset\":3903593,\"nonce\":36958666,\"last_updated_at\":1785276645157676,\"begin_nonce\":36958657},\"timestamp\":1785276645184,\"type\":\"update/order_book\"}"
        "raw": "{\"channel\":\"order_book:1\",\"last_updated_at\":1785276645324717,\"offset\":3903595,\"order_book\":{\"code\":0,\"asks\":[{\"price\":\"63969.9\",\"size\":\"3.12835\"},{\"price\":\"63974.0\",\"size\":\"0.00000\"}],\"bids\":[{\"price\":\"63893.3\",\"size\":\"3.11562\"},{\"price\":\"63889.2\",\"size\":\"0.00000\"}],\"offset\":3903595,\"nonce\":36958672,\"last_updated_at\":1785276645324717,\"begin_nonce\":36958666},\"timestamp\":1785276645333,\"type\":\"update/order_book\"}"
        "raw": "{\"channel\":\"order_book:1\",\"last_updated_at\":1785276645351945,\"offset\":3903597,\"order_book\":{\"code\":0,\"asks\":[],\"bids\":[{\"price\":\"63895.1\",\"size\":\"0.00149\"},{\"price\":\"63895.0\",\"size\":\"0.00000\"}],\"offset\":3903597,\"nonce\":36958677,\"last_updated_at\":1785276645351945,\"begin_nonce\":36958672},\"timestamp\":1785276645383,\"type\":\"update/order_book\"}"
        "raw": "{\"channel\":\"order_book:1\",\"last_updated_at\":1785276645546211,\"offset\":3903599,\"order_book\":{\"code\":0,\"asks\":[{\"price\":\"63969.7\",\"size\":\"3.12835\"},{\"price\":\"63969.9\",\"size\":\"0.00000\"}],\"bids\":[{\"price\":\"63894.0\",\"size\":\"3.11562\"},{\"price\":\"63893.3\",\"size\":\"0.00000\"}],\"offset\":3903599,\"nonce\":36958681,\"last_updated_at\":1785276645546211,\"begin_nonce\":36958677},\"timestamp\":1785276645584,\"type\":\"update/order_book\"}"
        "raw": "{\"channel\":\"order_book:1\",\"last_updated_at\":1785276645633586,\"offset\":3903600,\"order_book\":{\"code\":0,\"asks\":[{\"price\":\"63978.2\",\"size\":\"0.00000\"},{\"price\":\"63978.3\",\"size\":\"0.00163\"}],\"bids\":[],\"offset\":3903600,\"nonce\":36958683,\"last_updated_at\":1785276645633586,\"begin_nonce\":36958681},\"timestamp\":1785276645683,\"type\":\"update/order_book\"}"
        "raw": "{\"channel\":\"order_book:1\",\"last_updated_at\":1785276646103475,\"offset\":3903601,\"order_book\":{\"code\":0,\"asks\":[{\"price\":\"63969.7\",\"size\":\"0.00000\"},{\"price\":\"63969.8\",\"size\":\"3.12835\"}],\"bids\":[{\"price\":\"63894.0\",\"size\":\"0.00000\"},{\"price\":\"63893.9\",\"size\":\"3.11562\"}],\"offset\":3903601,\"nonce\":36958687,\"last_updated_at\":1785276646103475,\"begin_nonce\":36958683},\"timestamp\":1785276646134,\"type\":\"update/order_book\"}"
        "raw": "{\"channel\":\"order_book:1\",\"last_updated_at\":1785276646222081,\"offset\":3903603,\"order_book\":{\"code\":0,\"asks\":[{\"price\":\"63993.6\",\"size\":\"15.63443\"},{\"price\":\"64003.2\",\"size\":\"15.63443\"},{\"price\":\"64012.8\",\"size\":\"15.63443\"},{\"price\":\"64137.6\",\"size\":\"0.00000\"},{\"price\":\"64147.2\",\"size\":\"0.00000\"},{\"price\":\"64156.8\",\"size\":\"0.00000\"}],\"bids\":[],\"offset\":3903603,\"nonce\":36958689,\"last_updated_at\":1785276646222081,\"begin_nonce\":36958687},\"timestamp\":1785276646234,\"type\":\"update/order_book\"}"
        "raw": "{\"channel\":\"order_book:1\",\"last_updated_at\":1785276646321829,\"offset\":3903605,\"order_book\":{\"code\":0,\"asks\":[{\"price\":\"63964.7\",\"size\":\"3.12835\"},{\"price\":\"63969.8\",\"size\":\"0.00000\"}],\"bids\":[{\"price\":\"63895.3\",\"size\":\"3.11562\"},{\"price\":\"63893.9\",\"size\":\"0.00000\"}],\"offset\":3903605,\"nonce\":36958694,\"last_updated_at\":1785276646321829,\"begin_nonce\":36958689},\"timestamp\":1785276646333,\"type\":\"update/order_book\"}"
        "raw": "{\"channel\":\"order_book:1\",\"last_updated_at\":1785276646559902,\"offset\":3903606,\"order_book\":{\"code\":0,\"asks\":[{\"price\":\"63964.5\",\"size\":\"3.12835\"},{\"price\":\"63964.7\",\"size\":\"0.00000\"}],\"bids\":[{\"price\":\"63897.7\",\"size\":\"3.11562\"},{\"price\":\"63895.3\",\"size\":\"0.00000\"}],\"offset\":3903606,\"nonce\":36958696,\"last_updated_at\":1785276646559902,\"begin_nonce\":36958694},\"timestamp\":1785276646584,\"type\":\"update/order_book\"}"
        "raw": "{\"channel\":\"order_book:1\",\"last_updated_at\":1785276646731890,\"offset\":3903608,\"order_book\":{\"code\":0,\"asks\":[],\"bids\":[{\"price\":\"63895.2\",\"size\":\"0.00149\"},{\"price\":\"63895.1\",\"size\":\"0.00000\"}],\"offset\":3903608,\"nonce\":36958699,\"last_updated_at\":1785276646731890,\"begin_nonce\":36958696},\"timestamp\":1785276646733,\"type\":\"update/order_book\"}"
        "raw": "{\"channel\":\"order_book:1\",\"last_updated_at\":1785276647082529,\"offset\":3903611,\"order_book\":{\"code\":0,\"asks\":[{\"price\":\"63978.3\",\"size\":\"0.00000\"}],\"bids\":[{\"price\":\"63897.7\",\"size\":\"0.00000\"},{\"price\":\"63897.6\",\"size\":\"3.11562\"},{\"price\":\"63895.2\",\"size\":\"0.00000\"}],\"offset\":3903611,\"nonce\":36958708,\"last_updated_at\":1785276647082529,\"begin_nonce\":36958699},\"timestamp\":1785276647084,\"type\":\"update/order_book\"}"
        "raw": "{\"channel\":\"order_book:1\",\"last_updated_at\":1785276647280861,\"offset\":3903623,\"order_book\":{\"code\":0,\"asks\":[{\"price\":\"63976.2\",\"size\":\"0.00000\"},{\"price\":\"63993.6\",\"size\":\"0.00000\"},{\"price\":\"64137.6\",\"size\":\"15.63440\"}],\"bids\":[{\"price\":\"63893.1\",\"size\":\"0.00000\"},{\"price\":\"63890.3\",\"size\":\"0.00149\"}],\"offset\":3903623,\"nonce\":36958723,\"last_updated_at\":1785276647280861,\"begin_nonce\":36958709},\"timestamp\":1785276647285,\"type\":\"update/order_book\"}"
        "raw": "{\"channel\":\"order_book:1\",\"last_updated_at\":1785276647291996,\"offset\":3903625,\"order_book\":{\"code\":0,\"asks\":[{\"price\":\"63972.4\",\"size\":\"0.00163\"}],\"bids\":[{\"price\":\"63890.3\",\"size\":\"0.00000\"},{\"price\":\"63889.3\",\"size\":\"0.00149\"}],\"offset\":3903625,\"nonce\":36958726,\"last_updated_at\":1785276647291996,\"begin_nonce\":36958723},\"timestamp\":1785276647333,\"type\":\"update/order_book\"}"
        "raw": "{\"channel\":\"order_book:1\",\"last_updated_at\":1785276647439989,\"offset\":3903626,\"order_book\":{\"code\":0,\"asks\":[{\"price\":\"63964.5\",\"size\":\"0.00000\"},{\"price\":\"63964.6\",\"size\":\"3.12836\"}],\"bids\":[{\"price\":\"63897.6\",\"size\":\"0.00000\"},{\"price\":\"63894.4\",\"size\":\"3.11562\"}],\"offset\":3903626,\"nonce\":36958731,\"last_updated_at\":1785276647439989,\"begin_nonce\":36958726},\"timestamp\":1785276647484,\"type\":\"update/order_book\"}"
        "raw": "{\"channel\":\"order_book:1\",\"last_updated_at\":1785276647913432,\"offset\":3903628,\"order_book\":{\"code\":0,\"asks\":[{\"price\":\"63964.6\",\"size\":\"0.00000\"},{\"price\":\"63968.6\",\"size\":\"3.12836\"}],\"bids\":[{\"price\":\"63894.4\",\"size\":\"0.00000\"},{\"price\":\"63890.3\",\"size\":\"3.11562\"}],\"offset\":3903628,\"nonce\":36958744,\"last_updated_at\":1785276647913432,\"begin_nonce\":36958731},\"timestamp\":1785276647933,\"type\":\"update/order_book\"}"
        "raw": "{\"channel\":\"order_book:1\",\"last_updated_at\":1785276648036418,\"offset\":3903630,\"order_book\":{\"code\":0,\"asks\":[{\"price\":\"63965.1\",\"size\":\"3.12836\"},{\"price\":\"63968.6\",\"size\":\"0.00000\"}],\"bids\":[{\"price\":\"63891.2\",\"size\":\"3.11562\"},{\"price\":\"63890.3\",\"size\":\"0.00000\"}],\"offset\":3903630,\"nonce\":36958748,\"last_updated_at\":1785276648036418,\"begin_nonce\":36958744},\"timestamp\":1785276648083,\"type\":\"update/order_book\"}"
        "raw": "{\"channel\":\"order_book:1\",\"last_updated_at\":1785276648102839,\"offset\":3903631,\"order_book\":{\"code\":0,\"asks\":[{\"price\":\"63972.4\",\"size\":\"0.00000\"},{\"price\":\"63972.5\",\"size\":\"0.00163\"}],\"bids\":[],\"offset\":3903631,\"nonce\":36958749,\"last_updated_at\":1785276648102839,\"begin_nonce\":36958748},\"timestamp\":1785276648133,\"type\":\"update/order_book\"}"
