            "raw": "{\"channel\":\"order_book:1\",\"last_updated_at\":1785276549132996,\"offset\":3902775,\"order_book\":{\"code\":0,\"asks\":[{\"price\":\"64022.8\",\"size\":\"3.12552\"},{\"price\":\"64022.9\",\"size\":\"0.00000\"}],\"bids\":[{\"price\":\"63955.8\",\"size\":\"3.11277\"},{\"price\":\"63955.7\",\"size\":\"0.00000\"}],\"offset\":3902775,\"nonce\":36956922,\"last_updated_at\":1785276549132996,\"begin_nonce\":36956919},\"timestamp\":1785276549133,\"type\":\"update/order_book\"}"
            "raw": "{\"channel\":\"order_book:1\",\"last_updated_at\":1785276549971382,\"offset\":3902776,\"order_book\":{\"code\":0,\"asks\":[],\"bids\":[{\"price\":\"63955.8\",\"size\":\"0.00000\"},{\"price\":\"63955.7\",\"size\":\"3.11277\"}],\"offset\":3902776,\"nonce\":36956926,\"last_updated_at\":1785276549971382,\"begin_nonce\":36956922},\"timestamp\":1785276549984,\"type\":\"update/order_book\"}"
            "raw": "{\"channel\":\"order_book:1\",\"last_updated_at\":1785276550125986,\"offset\":3902777,\"order_book\":{\"code\":0,\"asks\":[],\"bids\":[{\"price\":\"62966.5\",\"size\":\"0.00000\"}],\"offset\":3902777,\"nonce\":36956928,\"last_updated_at\":1785276550125986,\"begin_nonce\":36956926},\"timestamp\":1785276550134,\"type\":\"update/order_book\"}"
            "raw": "{\"channel\":\"order_book:1\",\"last_updated_at\":1785276550507631,\"offset\":3902778,\"order_book\":{\"code\":0,\"asks\":[{\"price\":\"64054.0\",\"size\":\"0.00032\"}],\"bids\":[],\"offset\":3902778,\"nonce\":36956930,\"last_updated_at\":1785276550507631,\"begin_nonce\":36956928},\"timestamp\":1785276550534,\"type\":\"update/order_book\"}"
            "raw": "{\"channel\":\"order_book:1\",\"last_updated_at\":1785276550576776,\"offset\":3902779,\"order_book\":{\"code\":0,\"asks\":[],\"bids\":[{\"price\":\"63955.8\",\"size\":\"3.11277\"},{\"price\":\"63955.7\",\"size\":\"0.00000\"}],\"offset\":3902779,\"nonce\":36956931,\"last_updated_at\":1785276550576776,\"begin_nonce\":36956930},\"timestamp\":1785276550584,\"type\":\"update/order_book\"}"
            "raw": "{\"channel\":\"order_book:1\",\"last_updated_at\":1785276550637129,\"offset\":3902780,\"order_book\":{\"code\":0,\"asks\":[{\"price\":\"64054.0\",\"size\":\"0.00064\"}],\"bids\":[],\"offset\":3902780,\"nonce\":36956932,\"last_updated_at\":1785276550637129,\"begin_nonce\":36956931},\"timestamp\":1785276550683,\"type\":\"update/order_book\"}"
            "raw": "{\"channel\":\"order_book:1\",\"last_updated_at\":1785276550798552,\"offset\":3902781,\"order_book\":{\"code\":0,\"asks\":[{\"price\":\"64020.0\",\"size\":\"0.00096\"}],\"bids\":[],\"offset\":3902781,\"nonce\":36956934,\"last_updated_at\":1785276550798552,\"begin_nonce\":36956932},\"timestamp\":1785276550834,\"type\":\"update/order_book\"}"
            "raw": "{\"channel\":\"order_book:1\",\"last_updated_at\":1785276551146598,\"offset\":3902782,\"order_book\":{\"code\":0,\"asks\":[{\"price\":\"64022.8\",\"size\":\"0.00000\"},{\"price\":\"64022.9\",\"size\":\"3.12552\"}],\"bids\":[{\"price\":\"63955.8\",\"size\":\"0.00000\"},{\"price\":\"63955.7\",\"size\":\"3.11277\"}],\"offset\":3902782,\"nonce\":36956935,\"last_updated_at\":1785276551146598,\"begin_nonce\":36956934},\"timestamp\":1785276551185,\"type\":\"update/order_book\"}"
            "raw": "{\"channel\":\"order_book:1\",\"last_updated_at\":1785276551333004,\"offset\":3902783,\"order_book\":{\"code\":0,\"asks\":[{\"price\":\"64054.0\",\"size\":\"0.00096\"}],\"bids\":[],\"offset\":3902783,\"nonce\":36956939,\"last_updated_at\":1785276551333004,\"begin_nonce\":36956935},\"timestamp\":1785276551333,\"type\":\"update/order_book\"}"
            "raw": "{\"channel\":\"order_book:1\",\"last_updated_at\":1785276551701050,\"offset\":3902784,\"order_book\":{\"code\":0,\"asks\":[{\"price\":\"64022.7\",\"size\":\"3.12552\"},{\"price\":\"64022.9\",\"size\":\"0.00000\"}],\"bids\":[{\"price\":\"63955.9\",\"size\":\"3.11277\"},{\"price\":\"63955.7\",\"size\":\"0.00000\"}],\"offset\":3902784,\"nonce\":36956943,\"last_updated_at\":1785276551701050,\"begin_nonce\":36956939},\"timestamp\":1785276551734,\"type\":\"update/order_book\"}"
            "raw": "{\"channel\":\"order_book:1\",\"last_updated_at\":1785276552229116,\"offset\":3902786,\"order_book\":{\"code\":0,\"asks\":[{\"price\":\"64022.7\",\"size\":\"0.00000\"},{\"price\":\"64022.9\",\"size\":\"3.12552\"}],\"bids\":[{\"price\":\"63955.9\",\"size\":\"0.00000\"},{\"price\":\"63955.6\",\"size\":\"3.11277\"}],\"offset\":3902786,\"nonce\":36956946,\"last_updated_at\":1785276552229116,\"begin_nonce\":36956943},\"timestamp\":1785276552234,\"type\":\"update/order_book\"}"
            "raw": "{\"channel\":\"order_book:1\",\"last_updated_at\":1785276552758007,\"offset\":3902787,\"order_book\":{\"code\":0,\"asks\":[{\"price\":\"64022.8\",\"size\":\"3.12552\"},{\"price\":\"64022.9\",\"size\":\"0.00000\"}],\"bids\":[{\"price\":\"63955.8\",\"size\":\"3.11277\"},{\"price\":\"63955.6\",\"size\":\"0.00000\"}],\"offset\":3902787,\"nonce\":36956949,\"last_updated_at\":1785276552758007,\"begin_nonce\":36956946},\"timestamp\":1785276552783,\"type\":\"update/order_book\"}"
            "raw": "{\"channel\":\"order_book:1\",\"last_updated_at\":1785276553408480,\"offset\":3902789,\"order_book\":{\"code\":0,\"asks\":[{\"price\":\"64022.7\",\"size\":\"3.12552\"},{\"price\":\"64022.8\",\"size\":\"0.00000\"}],\"bids\":[{\"price\":\"63955.9\",\"size\":\"3.11277\"},{\"price\":\"63955.8\",\"size\":\"0.00000\"}],\"offset\":3902789,\"nonce\":36956953,\"last_updated_at\":1785276553408480,\"begin_nonce\":36956949},\"timestamp\":1785276553433,\"type\":\"update/order_book\"}"
            "raw": "{\"channel\":\"order_book:1\",\"last_updated_at\":1785276553753165,\"offset\":3902790,\"order_book\":{\"code\":0,\"asks\":[{\"price\":\"64022.7\",\"size\":\"0.00000\"},{\"price\":\"64022.8\",\"size\":\"3.12554\"}],\"bids\":[{\"price\":\"63955.9\",\"size\":\"0.00000\"},{\"price\":\"63955.0\",\"size\":\"3.11279\"}],\"offset\":3902790,\"nonce\":36956956,\"last_updated_at\":1785276553753165,\"begin_nonce\":36956953},\"timestamp\":1785276553783,\"type\":\"update/order_book\"}"
            "raw": "{\"channel\":\"order_book:1\",\"last_updated_at\":1785276553885783,\"offset\":3902791,\"order_book\":{\"code\":0,\"asks\":[{\"price\":\"64021.7\",\"size\":\"3.12559\"},{\"price\":\"64022.8\",\"size\":\"0.00000\"}],\"bids\":[{\"price\":\"63955.0\",\"size\":\"0.00000\"},{\"price\":\"63953.3\",\"size\":\"3.11284\"}],\"offset\":3902791,\"nonce\":36956957,\"last_updated_at\":1785276553885783,\"begin_nonce\":36956956},\"timestamp\":1785276553933,\"type\":\"update/order_book\"}"
            "raw": "{\"channel\":\"order_book:1\",\"last_updated_at\":1785276554389959,\"offset\":3902792,\"order_book\":{\"code\":0,\"asks\":[{\"price\":\"64021.3\",\"size\":\"3.12559\"},{\"price\":\"64021.7\",\"size\":\"0.00000\"}],\"bids\":[{\"price\":\"63953.7\",\"size\":\"3.11284\"},{\"price\":\"63953.3\",\"size\":\"0.00000\"}],\"offset\":3902792,\"nonce\":36956962,\"last_updated_at\":1785276554389959,\"begin_nonce\":36956957},\"timestamp\":1785276554433,\"type\":\"update/order_book\"}"
            "raw": "{\"channel\":\"order_book:1\",\"last_updated_at\":1785276554918783,\"offset\":3902793,\"order_book\":{\"code\":0,\"asks\":[{\"price\":\"64021.3\",\"size\":\"0.00000\"},{\"price\":\"64021.4\",\"size\":\"3.12559\"}],\"bids\":[{\"price\":\"63953.7\",\"size\":\"0.00000\"},{\"price\":\"63953.6\",\"size\":\"3.11284\"}],\"offset\":3902793,\"nonce\":36956966,\"last_updated_at\":1785276554918783,\"begin_nonce\":36956962},\"timestamp\":1785276554934,\"type\":\"update/order_book\"}"
            "raw": "{\"channel\":\"order_book:1\",\"last_updated_at\":1785276555420860,\"offset\":3902794,\"order_book\":{\"code\":0,\"asks\":[{\"price\":\"64020.6\",\"size\":\"3.12566\"},{\"price\":\"64021.4\",\"size\":\"0.00000\"}],\"bids\":[{\"price\":\"63953.6\",\"size\":\"0.00000\"},{\"price\":\"63951.0\",\"size\":\"3.11291\"}],\"offset\":3902794,\"nonce\":36956976,\"last_updated_at\":1785276555420860,\"begin_nonce\":36956966},\"timestamp\":1785276555433,\"type\":\"update/order_book\"}"
            "raw": "{\"channel\":\"order_book:1\",\"last_updated_at\":1785276555481785,\"offset\":3902795,\"order_book\":{\"code\":0,\"asks\":[],\"bids\":[{\"price\":\"63916.8\",\"size\":\"0.00000\"},{\"price\":\"63772.8\",\"size\":\"15.60567\"}],\"offset\":3902795,\"nonce\":36956983,\"last_updated_at\":1785276555481785,\"begin_nonce\":36956976},\"timestamp\":1785276555485,\"type\":\"update/order_book\"}"
            "raw": "{\"channel\":\"order_book:1\",\"last_updated_at\":1785276555727385,\"offset\":3902806,\"order_book\":{\"code\":0,\"asks\":[{\"price\":\"64013.8\",\"size\":\"3.12596\"},{\"price\":\"64020.6\",\"size\":\"0.00000\"}],\"bids\":[{\"price\":\"63951.0\",\"size\":\"0.00000\"},{\"price\":\"63942.2\",\"size\":\"3.11322\"},{\"price\":\"63907.2\",\"size\":\"14.09190\"},{\"price\":\"63897.6\",\"size\":\"14.09190\"},{\"price\":\"63888.0\",\"size\":\"14.24219\"},{\"price\":\"63878.4\",\"size\":\"14.24219\"},{\"price\":\"63868.8\",\"size\":\"14.09190\"},{\"price\":\"63859.2\",\"size\":\"14.24219\"},{\"price\":\"63849.6\",\"size\":\"14.24219\"},{\"price\":\"63840.0\",\"size\":\"14.24311\"},{\"price\":\"63830.4\",\"size\":\"14.24219\"},{\"price\":\"63820.8\",\"size\":\"14.24219\"},{\"price\":\"63811.2\",\"size\":\"14.24219\"},{\"price\":\"63801.6\",\"size\":\"14.24219\"},{\"price\":\"63792.0\",\"size\":\"14.24219\"},{\"price\":\"63782.4\",\"size\":\"14.24219\"},{\"price\":\"63772.8\",\"size\":\"14.24219\"}],\"offset\":3902806,\"nonce\":36957017,\"last_updated_at\":1785276555727385,\"begin_nonce\":36956983},\"timestamp\":1785276555736,\"type\":\"update/order_book\"}"
            "raw": "{\"channel\":\"order_book:1\",\"last_updated_at\":1785276555781568,\"offset\":3902810,\"order_book\":{\"code\":0,\"asks\":[],\"bids\":[{\"price\":\"63907.2\",\"size\":\"14.24219\"},{\"price\":\"63897.6\",\"size\":\"14.24219\"},{\"price\":\"63868.8\",\"size\":\"14.24219\"},{\"price\":\"63859.2\",\"size\":\"12.91816\"},{\"price\":\"63849.6\",\"size\":\"12.91816\"},{\"price\":\"63840.0\",\"size\":\"12.91908\"},{\"price\":\"63830.4\",\"size\":\"12.91816\"},{\"price\":\"63820.8\",\"size\":\"12.91816\"},{\"price\":\"63811.2\",\"size\":\"12.91816\"},{\"price\":\"63801.6\",\"size\":\"12.91816\"},{\"price\":\"63792.0\",\"size\":\"12.91816\"},{\"price\":\"63782.4\",\"size\":\"12.91816\"},{\"price\":\"63772.8\",\"size\":\"12.91816\"}],\"offset\":3902810,\"nonce\":36957023,\"last_updated_at\":1785276555781568,\"begin_nonce\":36957017},\"timestamp\":1785276555784,\"type\":\"update/order_book\"}"
            "raw": "{\"channel\":\"order_book:1\",\"last_updated_at\":1785276555811370,\"offset\":3902817,\"order_book\":{\"code\":0,\"asks\":[],\"bids\":[{\"price\":\"63907.2\",\"size\":\"13.05442\"},{\"price\":\"63897.6\",\"size\":\"13.05442\"},{\"price\":\"63888.0\",\"size\":\"13.05442\"},{\"price\":\"63878.4\",\"size\":\"13.05442\"},{\"price\":\"63868.8\",\"size\":\"13.05442\"},{\"price\":\"63859.2\",\"size\":\"13.05442\"},{\"price\":\"63849.6\",\"size\":\"13.05442\"},{\"price\":\"63840.0\",\"size\":\"13.05534\"},{\"price\":\"63830.4\",\"size\":\"13.05442\"},{\"price\":\"63820.8\",\"size\":\"13.05442\"},{\"price\":\"63811.2\",\"size\":\"13.05442\"},{\"price\":\"63801.6\",\"size\":\"13.05442\"},{\"price\":\"63792.0\",\"size\":\"13.05442\"},{\"price\":\"63782.4\",\"size\":\"13.05442\"},{\"price\":\"63772.8\",\"size\":\"13.05442\"}],\"offset\":3902817,\"nonce\":36957039,\"last_updated_at\":1785276555811370,\"begin_nonce\":36957023},\"timestamp\":1785276555839,\"type\":\"update/order_book\"}"
            "raw": "{\"channel\":\"order_book:1\",\"last_updated_at\":1785276555883824,\"offset\":3902820,\"order_book\":{\"code\":0,\"asks\":[{\"price\":\"64013.8\",\"size\":\"0.00000\"},{\"price\":\"64021.7\",\"size\":\"3.12615\"}],\"bids\":[{\"price\":\"63942.2\",\"size\":\"0.00000\"},{\"price\":\"63936.6\",\"size\":\"2.63609\"},{\"price\":\"63931.8\",\"size\":\"5.27218\"},{\"price\":\"63931.2\",\"size\":\"0.00000\"}],\"offset\":3902820,\"nonce\":36957046,\"last_updated_at\":1785276555883824,\"begin_nonce\":36957039},\"timestamp\":1785276555898,\"type\":\"update/order_book\"}"
            "raw": "{\"channel\":\"order_book:1\",\"last_updated_at\":1785276555940894,\"offset\":3902821,\"order_book\":{\"code\":0,\"asks\":[{\"price\":\"64026.6\",\"size\":\"6.25229\"},{\"price\":\"64033.8\",\"size\":\"0.00000\"}],\"bids\":[{\"price\":\"63927.0\",\"size\":\"7.90826\"},{\"price\":\"63926.4\",\"size\":\"0.00000\"},{\"price\":\"63888.0\",\"size\":\"13.21994\"},{\"price\":\"63859.2\",\"size\":\"13.21994\"},{\"price\":\"63830.4\",\"size\":\"13.21994\"},{\"price\":\"63801.6\",\"size\":\"13.21994\"},{\"price\":\"63772.8\",\"size\":\"13.21994\"}],\"offset\":3902821,\"nonce\":36957047,\"last_updated_at\":1785276555940894,\"begin_nonce\":36957046},\"timestamp\":1785276555984,\"type\":\"update/order_book\"}"
            "raw": "{\"channel\":\"order_book:1\",\"last_updated_at\":1785276556023910,\"offset\":3902829,\"order_book\":{\"code\":0,\"asks\":[{\"price\":\"64016.9\",\"size\":\"0.00163\"},{\"price\":\"64031.4\",\"size\":\"9.37843\"},{\"price\":\"64036.2\",\"size\":\"12.50457\"},{\"price\":\"64038.6\",\"size\":\"0.00000\"},{\"price\":\"64043.4\",\"size\":\"0.00000\"}],\"bids\":[{\"price\":\"63932.2\",\"size\":\"0.00149\"},{\"price\":\"63922.2\",\"size\":\"10.54435\"},{\"price\":\"63921.6\",\"size\":\"0.00000\"},{\"price\":\"63907.2\",\"size\":\"13.36701\"},{\"price\":\"63897.6\",\"size\":\"13.21994\"},{\"price\":\"63878.4\",\"size\":\"13.36701\"},{\"price\":\"63868.8\",\"size\":\"13.36701\"},{\"price\":\"63859.2\",\"size\":\"13.36701\"},{\"price\":\"63849.6\",\"size\":\"13.36701\"},{\"price\":\"63840.0\",\"size\":\"13.36793\"},{\"price\":\"63830.4\",\"size\":\"13.36701\"},{\"price\":\"63820.8\",\"size\":\"13.36701\"},{\"price\":\"63811.2\",\"size\":\"13.36701\"},{\"price\":\"63801.6\",\"size\":\"13.36701\"},{\"price\":\"63792.0\",\"size\":\"13.36701\"},{\"price\":\"63782.4\",\"size\":\"13.36701\"},{\"price\":\"63772.8\",\"size\":\"13.36701\"}],\"offset\":3902829,\"nonce\":36957056,\"last_updated_at\":1785276556023910,\"begin_nonce\":36957047},\"timestamp\":1785276556033,\"type\":\"update/order_book\"}"
            "raw": "{\"channel\":\"order_book:1\",\"last_updated_at\":1785276556129873,\"offset\":3902837,\"order_book\":{\"code\":0,\"asks\":[],\"bids\":[{\"price\":\"63897.6\",\"size\":\"13.54263\"},{\"price\":\"63888.0\",\"size\":\"13.36701\"},{\"price\":\"63878.4\",\"size\":\"13.54263\"},{\"price\":\"63859.2\",\"size\":\"13.54263\"},{\"price\":\"63849.6\",\"size\":\"13.54263\"},{\"price\":\"63840.0\",\"size\":\"13.54355\"},{\"price\":\"63830.4\",\"size\":\"13.54263\"},{\"price\":\"63820.8\",\"size\":\"13.54263\"},{\"price\":\"63811.2\",\"size\":\"13.54263\"},{\"price\":\"63801.6\",\"size\":\"13.54263\"},{\"price\":\"63792.0\",\"size\":\"13.54263\"},{\"price\":\"63782.4\",\"size\":\"13.54263\"},{\"price\":\"63772.8\",\"size\":\"13.54263\"}],\"offset\":3902837,\"nonce\":36957070,\"last_updated_at\":1785276556129873,\"begin_nonce\":36957056},\"timestamp\":1785276556134,\"type\":\"update/order_book\"}"
            "raw": "{\"channel\":\"order_book:1\",\"last_updated_at\":1785276556142750,\"offset\":3902839,\"order_book\":{\"code\":0,\"asks\":[],\"bids\":[{\"price\":\"63907.2\",\"size\":\"13.54263\"},{\"price\":\"63888.0\",\"size\":\"13.54263\"},{\"price\":\"63868.8\",\"size\":\"13.54263\"}],\"offset\":3902839,\"nonce\":36957075,\"last_updated_at\":1785276556142750,\"begin_nonce\":36957070},\"timestamp\":1785276556184,\"type\":\"update/order_book\"}"
            "raw": "{\"channel\":\"order_book:1\",\"last_updated_at\":1785276556223985,\"offset\":3902848,\"order_book\":{\"code\":0,\"asks\":[{\"price\":\"64016.9\",\"size\":\"0.00000\"},{\"price\":\"64020.0\",\"size\":\"0.00259\"}],\"bids\":[{\"price\":\"63897.6\",\"size\":\"13.70853\"},{\"price\":\"63888.0\",\"size\":\"13.70853\"},{\"price\":\"63878.4\",\"size\":\"13.70853\"},{\"price\":\"63868.8\",\"size\":\"13.70853\"},{\"price\":\"63859.2\",\"size\":\"13.70853\"},{\"price\":\"63849.6\",\"size\":\"13.70853\"},{\"price\":\"63840.0\",\"size\":\"13.70945\"},{\"price\":\"63820.8\",\"size\":\"13.70853\"},{\"price\":\"63811.2\",\"size\":\"13.70853\"},{\"price\":\"63801.6\",\"size\":\"13.70853\"},{\"price\":\"63792.0\",\"size\":\"13.70853\"},{\"price\":\"63782.4\",\"size\":\"13.70853\"},{\"price\":\"63772.8\",\"size\":\"13.70853\"}],\"offset\":3902848,\"nonce\":36957090,\"last_updated_at\":1785276556223985,\"begin_nonce\":36957075},\"timestamp\":1785276556234,\"type\":\"update/order_book\"}"
            "raw": "{\"channel\":\"order_book:1\",\"last_updated_at\":1785276556287731,\"offset\":3902854,\"order_book\":{\"code\":0,\"asks\":[],\"bids\":[{\"price\":\"63907.2\",\"size\":\"0.00000\"},{\"price\":\"63830.4\",\"size\":\"13.70853\"},{\"price\":\"63820.8\",\"size\":\"13.87078\"},{\"price\":\"63801.6\",\"size\":\"13.87078\"},{\"price\":\"63792.0\",\"size\":\"13.87078\"},{\"price\":\"63772.8\",\"size\":\"13.87078\"},{\"price\":\"63763.2\",\"size\":\"13.87078\"}],\"offset\":3902854,\"nonce\":36957099,\"last_updated_at\":1785276556287731,\"begin_nonce\":36957090},\"timestamp\":1785276556293,\"type\":\"update/order_book\"}"
            "raw": "{\"channel\":\"order_book:1\",\"last_updated_at\":1785276556325871,\"offset\":3902865,\"order_book\":{\"code\":0,\"asks\":[],\"bids\":[{\"price\":\"63897.6\",\"size\":\"13.87078\"},{\"price\":\"63888.0\",\"size\":\"14.10222\"},{\"price\":\"63878.4\",\"size\":\"14.10222\"},{\"price\":\"63868.8\",\"size\":\"13.87078\"},{\"price\":\"63859.2\",\"size\":\"14.10222\"},{\"price\":\"63849.6\",\"size\":\"14.10222\"},{\"price\":\"63840.0\",\"size\":\"14.10314\"},{\"price\":\"63830.4\",\"size\":\"14.10222\"},{\"price\":\"63820.8\",\"size\":\"14.10222\"},{\"price\":\"63811.2\",\"size\":\"14.10222\"},{\"price\":\"63801.6\",\"size\":\"14.10222\"},{\"price\":\"63792.0\",\"size\":\"14.10222\"},{\"price\":\"63782.4\",\"size\":\"14.10222\"},{\"price\":\"63772.8\",\"size\":\"14.10222\"},{\"price\":\"63763.2\",\"size\":\"14.10222\"}],\"offset\":3902865,\"nonce\":36957111,\"last_updated_at\":1785276556325871,\"begin_nonce\":36957099},\"timestamp\":1785276556334,\"type\":\"update/order_book\"}"
            "raw": "{\"channel\":\"order_book:1\",\"last_updated_at\":1785276556340128,\"offset\":3902867,\"order_book\":{\"code\":0,\"asks\":[],\"bids\":[{\"price\":\"63897.6\",\"size\":\"14.10222\"},{\"price\":\"63868.8\",\"size\":\"14.10222\"}],\"offset\":3902867,\"nonce\":36957117,\"last_updated_at\":1785276556340128,\"begin_nonce\":36957111},\"timestamp\":1785276556384,\"type\":\"update/order_book\"}"
            "raw": "{\"channel\":\"order_book:1\",\"last_updated_at\":1785276556528812,\"offset\":3902876,\"order_book\":{\"code\":0,\"asks\":[{\"price\":\"64021.7\",\"size\":\"0.00000\"},{\"price\":\"64022.5\",\"size\":\"3.12615\"}],\"bids\":[],\"offset\":3902876,\"nonce\":36957137,\"last_updated_at\":1785276556528812,\"begin_nonce\":36957134},\"timestamp\":1785276556535,\"type\":\"update/order_book\"}"
            "raw": "{\"channel\":\"order_book:1\",\"last_updated_at\":1785276556583609,\"offset\":3902878,\"order_book\":{\"code\":0,\"asks\":[{\"price\":\"64026.6\",\"size\":\"0.00000\"},{\"price\":\"64027.3\",\"size\":\"6.25229\"}],\"bids\":[{\"price\":\"63936.6\",\"size\":\"0.00000\"},{\"price\":\"63936.2\",\"size\":\"2.91458\"},{\"price\":\"63801.6\",\"size\":\"14.61328\"},{\"price\":\"63772.8\",\"size\":\"14.61328\"}],\"offset\":3902878,\"nonce\":36957141,\"last_updated_at\":1785276556583609,\"begin_nonce\":36957137},\"timestamp\":1785276556584,\"type\":\"update/order_book\"}"
            "raw": "{\"channel\":\"order_book:1\",\"last_updated_at\":1785276556633052,\"offset\":3902892,\"order_book\":{\"code\":0,\"asks\":[{\"price\":\"64017.0\",\"size\":\"0.00000\"},{\"price\":\"64020.0\",\"size\":\"0.00259\"},{\"price\":\"64031.4\",\"size\":\"0.00000\"},{\"price\":\"64032.1\",\"size\":\"9.37843\"},{\"price\":\"64036.2\",\"size\":\"0.00000\"},{\"price\":\"64036.9\",\"size\":\"12.50457\"}],\"bids\":[{\"price\":\"63931.8\",\"size\":\"0.00000\"},{\"price\":\"63931.4\",\"size\":\"5.82915\"},{\"price\":\"63927.0\",\"size\":\"0.00000\"},{\"price\":\"63926.6\",\"size\":\"8.74373\"},{\"price\":\"63922.2\",\"size\":\"0.00000\"},{\"price\":\"63921.8\",\"size\":\"11.65830\"},{\"price\":\"63897.6\",\"size\":\"14.83477\"},{\"price\":\"63888.0\",\"size\":\"14.61328\"},{\"price\":\"63878.4\",\"size\":\"14.83477\"},{\"price\":\"63868.8\",\"size\":\"14.83477\"},{\"price\":\"63859.2\",\"size\":\"14.83477\"},{\"price\":\"63849.6\",\"size\":\"14.83477\"},{\"price\":\"63840.0\",\"size\":\"14.83569\"},{\"price\":\"63830.4\",\"size\":\"14.83477\"},{\"price\":\"63820.8\",\"size\":\"14.83477\"},{\"price\":\"63811.2\",\"size\":\"15.03771\"},{\"price\":\"63801.6\",\"size\":\"14.83477\"},{\"price\":\"63792.0\",\"size\":\"15.03771\"},{\"price\":\"63782.4\",\"size\":\"15.03771\"},{\"price\":\"63772.8\",\"size\":\"14.83477\"},{\"price\":\"63763.2\",\"size\":\"15.03771\"}],\"offset\":3902892,\"nonce\":36957158,\"last_updated_at\":1785276556633052,\"begin_nonce\":36957141},\"timestamp\":1785276556634,\"type\":\"update/order_book\"}"
            "raw": "{\"channel\":\"order_book:1\",\"last_updated_at\":1785276556681193,\"offset\":3902895,\"order_book\":{\"code\":0,\"asks\":[],\"bids\":[{\"price\":\"63888.0\",\"size\":\"14.83477\"},{\"price\":\"63868.8\",\"size\":\"15.03771\"},{\"price\":\"63840.0\",\"size\":\"15.03863\"},{\"price\":\"63820.8\",\"size\":\"15.03771\"}],\"offset\":3902895,\"nonce\":36957163,\"last_updated_at\":1785276556681193,\"begin_nonce\":36957158},\"timestamp\":1785276556683,\"type\":\"update/order_book\"}"
            "raw": "{\"channel\":\"order_book:1\",\"last_updated_at\":1785276556731908,\"offset\":3902906,\"order_book\":{\"code\":0,\"asks\":[],\"bids\":[{\"price\":\"63960.0\",\"size\":\"0.00094\"},{\"price\":\"63897.6\",\"size\":\"15.22075\"},{\"price\":\"63888.0\",\"size\":\"15.03771\"},{\"price\":\"63878.4\",\"size\":\"15.03771\"},{\"price\":\"63868.8\",\"size\":\"15.22075\"},{\"price\":\"63859.2\",\"size\":\"15.22075\"},{\"price\":\"63849.6\",\"size\":\"15.03771\"},{\"price\":\"63840.0\",\"size\":\"15.22167\"},{\"price\":\"63830.4\",\"size\":\"15.22075\"},{\"price\":\"63811.2\",\"size\":\"15.22075\"},{\"price\":\"63801.6\",\"size\":\"15.22075\"},{\"price\":\"63782.4\",\"size\":\"15.22075\"},{\"price\":\"63772.8\",\"size\":\"15.22075\"}],\"offset\":3902906,\"nonce\":36957179,\"last_updated_at\":1785276556731908,\"begin_nonce\":36957163},\"timestamp\":1785276556734,\"type\":\"update/order_book\"}"
            "raw": "{\"channel\":\"order_book:1\",\"last_updated_at\":1785276556780095,\"offset\":3902909,\"order_book\":{\"code\":0,\"asks\":[],\"bids\":[{\"price\":\"63888.0\",\"size\":\"15.22075\"},{\"price\":\"63878.4\",\"size\":\"15.22075\"},{\"price\":\"63849.6\",\"size\":\"15.22075\"},{\"price\":\"63820.8\",\"size\":\"15.22075\"},{\"price\":\"63792.0\",\"size\":\"15.22075\"},{\"price\":\"63763.2\",\"size\":\"15.22075\"}],\"offset\":3902909,\"nonce\":36957184,\"last_updated_at\":1785276556780095,\"begin_nonce\":36957179},\"timestamp\":1785276556783,\"type\":\"update/order_book\"}"
            "raw": "{\"channel\":\"order_book:1\",\"last_updated_at\":1785276556831562,\"offset\":3902920,\"order_book\":{\"code\":0,\"asks\":[{\"price\":\"64020.0\",\"size\":\"0.00096\"},{\"price\":\"64022.4\",\"size\":\"3.12615\"},{\"price\":\"64022.5\",\"size\":\"0.00000\"}],\"bids\":[{\"price\":\"63931.4\",\"size\":\"0.00000\"},{\"price\":\"63925.2\",\"size\":\"6.21440\"},{\"price\":\"63897.6\",\"size\":\"15.52476\"},{\"price\":\"63888.0\",\"size\":\"15.52476\"},{\"price\":\"63868.8\",\"size\":\"15.52476\"},{\"price\":\"63859.2\",\"size\":\"15.52476\"},{\"price\":\"63840.0\",\"size\":\"15.52568\"},{\"price\":\"63830.4\",\"size\":\"15.52476\"},{\"price\":\"63820.8\",\"size\":\"15.52476\"},{\"price\":\"63811.2\",\"size\":\"15.52476\"},{\"price\":\"63801.6\",\"size\":\"15.52476\"},{\"price\":\"63792.0\",\"size\":\"15.52476\"},{\"price\":\"63782.4\",\"size\":\"15.52476\"},{\"price\":\"63772.8\",\"size\":\"15.52476\"},{\"price\":\"63763.2\",\"size\":\"15.52476\"}],\"offset\":3902920,\"nonce\":36957201,\"last_updated_at\":1785276556831562,\"begin_nonce\":36957184},\"timestamp\":1785276556834,\"type\":\"update/order_book\"}"
            "raw": "{\"channel\":\"order_book:1\",\"last_updated_at\":1785276556882458,\"offset\":3902924,\"order_book\":{\"code\":0,\"asks\":[{\"price\":\"64017.0\",\"size\":\"0.00163\"}],\"bids\":[{\"price\":\"63936.2\",\"size\":\"0.00000\"},{\"price\":\"63930.0\",\"size\":\"3.10720\"},{\"price\":\"63878.4\",\"size\":\"15.52476\"},{\"price\":\"63849.6\",\"size\":\"15.52476\"}],\"offset\":3902924,\"nonce\":36957205,\"last_updated_at\":1785276556882458,\"begin_nonce\":36957201},\"timestamp\":1785276556884,\"type\":\"update/order_book\"}"
            "raw": "{\"channel\":\"order_book:1\",\"last_updated_at\":1785276556932286,\"offset\":3902926,\"order_book\":{\"code\":0,\"asks\":[{\"price\":\"64027.2\",\"size\":\"6.25229\"},{\"price\":\"64027.3\",\"size\":\"0.00000\"},{\"price\":\"64036.8\",\"size\":\"12.50457\"},{\"price\":\"64036.9\",\"size\":\"0.00000\"}],\"bids\":[{\"price\":\"63926.6\",\"size\":\"0.00000\"},{\"price\":\"63920.4\",\"size\":\"9.32160\"}],\"offset\":3902926,\"nonce\":36957210,\"last_updated_at\":1785276556932286,\"begin_nonce\":36957205},\"timestamp\":1785276556933,\"type\":\"update/order_book\"}"
            "raw": "{\"channel\":\"order_book:1\",\"last_updated_at\":1785276556981849,\"offset\":3902928,\"order_book\":{\"code\":0,\"asks\":[{\"price\":\"64017.0\",\"size\":\"0.00000\"},{\"price\":\"64032.0\",\"size\":\"9.37843\"},{\"price\":\"64032.1\",\"size\":\"0.00000\"}],\"bids\":[{\"price\":\"63921.8\",\"size\":\"0.00000\"},{\"price\":\"63915.6\",\"size\":\"12.42880\"}],\"offset\":3902928,\"nonce\":36957213,\"last_updated_at\":1785276556981849,\"begin_nonce\":36957210},\"timestamp\":1785276556986,\"type\":\"update/order_book\"}"
            "raw": "{\"channel\":\"order_book:1\",\"last_updated_at\":1785276557001998,\"offset\":3902933,\"order_book\":{\"code\":0,\"asks\":[{\"price\":\"64020.0\",\"size\":\"0.00259\"}],\"bids\":[{\"price\":\"63932.2\",\"size\":\"0.00000\"},{\"price\":\"63929.4\",\"size\":\"0.00149\"}],\"offset\":3902933,\"nonce\":36957222,\"last_updated_at\":1785276557001998,\"begin_nonce\":36957213},\"timestamp\":1785276557033,\"type\":\"update/order_book\"}"
            "raw": "{\"channel\":\"order_book:1\",\"last_updated_at\":1785276557131386,\"offset\":3902939,\"order_book\":{\"code\":0,\"asks\":[{\"price\":\"64022.4\",\"size\":\"0.00000\"},{\"price\":\"64027.2\",\"size\":\"0.00000\"},{\"price\":\"64032.0\",\"size\":\"0.00000\"},{\"price\":\"64032.8\",\"size\":\"6.25229\"},{\"price\":\"64035.1\",\"size\":\"3.12615\"},{\"price\":\"64036.8\",\"size\":\"0.00000\"},{\"price\":\"64037.6\",\"size\":\"9.37843\"},{\"price\":\"64042.4\",\"size\":\"12.50457\"},{\"price\":\"64060.8\",\"size\":\"0.00000\"},{\"price\":\"64204.8\",\"size\":\"15.61784\"}],\"bids\":[{\"price\":\"63930.0\",\"size\":\"0.00000\"},{\"price\":\"63925.2\",\"size\":\"0.00000\"},{\"price\":\"63920.4\",\"size\":\"0.00000\"},{\"price\":\"63917.3\",\"size\":\"3.11340\"},{\"price\":\"63914.8\",\"size\":\"9.34019\"},{\"price\":\"63912.5\",\"size\":\"6.22680\"},{\"price\":\"63897.6\",\"size\":\"0.00000\"},{\"price\":\"63753.6\",\"size\":\"15.61084\"}],\"offset\":3902939,\"nonce\":36957236,\"last_updated_at\":1785276557131386,\"begin_nonce\":36957222},\"timestamp\":1785276557133,\"type\":\"update/order_book\"}"
            "raw": "{\"channel\":\"order_book:1\",\"last_updated_at\":1785276557181737,\"offset\":3902941,\"order_book\":{\"code\":0,\"asks\":[{\"price\":\"64020.0\",\"size\":\"0.00096\"}],\"bids\":[{\"price\":\"63915.6\",\"size\":\"0.00000\"},{\"price\":\"63910.0\",\"size\":\"12.45359\"}],\"offset\":3902941,\"nonce\":36957241,\"last_updated_at\":1785276557181737,\"begin_nonce\":36957236},\"timestamp\":1785276557183,\"type\":\"update/order_book\"}"
            "raw": "{\"channel\":\"order_book:1\",\"last_updated_at\":1785276557236042,\"offset\":3902943,\"order_book\":{\"code\":0,\"asks\":[{\"price\":\"64032.8\",\"size\":\"0.00000\"},{\"price\":\"64039.9\",\"size\":\"6.25229\"},{\"price\":\"64042.4\",\"size\":\"0.00000\"},{\"price\":\"64049.5\",\"size\":\"12.50457\"}],\"bids\":[{\"price\":\"63910.0\",\"size\":\"0.00000\"},{\"price\":\"63902.9\",\"size\":\"12.45359\"}],\"offset\":3902943,\"nonce\":36957247,\"last_updated_at\":1785276557236042,\"begin_nonce\":36957241},\"timestamp\":1785276557283,\"type\":\"update/order_book\"}"
            "raw": "{\"channel\":\"order_book:1\",\"last_updated_at\":1785276557313889,\"offset\":3902947,\"order_book\":{\"code\":0,\"asks\":[{\"price\":\"64035.1\",\"size\":\"0.00000\"},{\"price\":\"64037.6\",\"size\":\"0.00000\"},{\"price\":\"64038.5\",\"size\":\"3.12614\"},{\"price\":\"64044.7\",\"size\":\"9.37843\"}],\"bids\":[{\"price\":\"63917.3\",\"size\":\"0.00000\"},{\"price\":\"63914.8\",\"size\":\"0.00000\"},{\"price\":\"63914.0\",\"size\":\"3.11340\"},{\"price\":\"63907.7\",\"size\":\"9.34019\"},{\"price\":\"63888.0\",\"size\":\"0.00000\"},{\"price\":\"63744.0\",\"size\":\"15.61273\"}],\"offset\":3902947,\"nonce\":36957262,\"last_updated_at\":1785276557313889,\"begin_nonce\":36957247},\"timestamp\":1785276557334,\"type\":\"update/order_book\"}"
            "raw": "{\"channel\":\"order_book:1\",\"last_updated_at\":1785276557428568,\"offset\":3902949,\"order_book\":{\"code\":0,\"asks\":[{\"price\":\"64039.9\",\"size\":\"0.00000\"},{\"price\":\"64047.6\",\"size\":\"6.25228\"},{\"price\":\"64070.4\",\"size\":\"0.00000\"},{\"price\":\"64214.4\",\"size\":\"15.61542\"}],\"bids\":[{\"price\":\"63907.7\",\"size\":\"0.00000\"},{\"price\":\"63900.0\",\"size\":\"9.34119\"}],\"offset\":3902949,\"nonce\":36957267,\"last_updated_at\":1785276557428568,\"begin_nonce\":36957262},\"timestamp\":1785276557434,\"type\":\"update/order_book\"}"
            "raw": "{\"channel\":\"order_book:1\",\"last_updated_at\":1785276557481695,\"offset\":3902953,\"order_book\":{\"code\":0,\"asks\":[{\"price\":\"64020.0\",\"size\":\"0.00259\"},{\"price\":\"64047.6\",\"size\":\"0.00000\"},{\"price\":\"64052.2\",\"size\":\"6.25243\"}],\"bids\":[{\"price\":\"63914.0\",\"size\":\"0.00000\"},{\"price\":\"63909.6\",\"size\":\"3.11340\"},{\"price\":\"63902.9\",\"size\":\"0.00000\"},{\"price\":\"63900.0\",\"size\":\"0.00100\"},{\"price\":\"63895.3\",\"size\":\"12.45358\"},{\"price\":\"63893.2\",\"size\":\"9.34041\"}],\"offset\":3902953,\"nonce\":36957272,\"last_updated_at\":1785276557481695,\"begin_nonce\":36957267},\"timestamp\":1785276557484,\"type\":\"update/order_book\"}"
            "raw": "{\"channel\":\"order_book:1\",\"last_updated_at\":1785276557520958,\"offset\":3902958,\"order_book\":{\"code\":0,\"asks\":[{\"price\":\"64038.5\",\"size\":\"0.00000\"},{\"price\":\"64044.7\",\"size\":\"0.00000\"},{\"price\":\"64047.4\",\"size\":\"3.12622\"},{\"price\":\"64049.5\",\"size\":\"0.00000\"},{\"price\":\"64057.0\",\"size\":\"9.37864\"},{\"price\":\"64061.8\",\"size\":\"12.50485\"}],\"bids\":[{\"price\":\"63912.5\",\"size\":\"0.00000\"},{\"price\":\"63909.6\",\"size\":\"0.00000\"},{\"price\":\"63902.7\",\"size\":\"3.11347\"},{\"price\":\"63897.9\",\"size\":\"6.22694\"},{\"price\":\"63895.3\",\"size\":\"0.00000\"},{\"price\":\"63888.4\",\"size\":\"12.45387\"},{\"price\":\"63878.4\",\"size\":\"0.00000\"},{\"price\":\"63734.4\",\"size\":\"15.61512\"}],\"offset\":3902958,\"nonce\":36957279,\"last_updated_at\":1785276557520958,\"begin_nonce\":36957272},\"timestamp\":1785276557534,\"type\":\"update/order_book\"}"
            "raw": "{\"channel\":\"order_book:1\",\"last_updated_at\":1785276557533136,\"offset\":3902959,\"order_book\":{\"code\":0,\"asks\":[],\"bids\":[{\"price\":\"63902.7\",\"size\":\"0.00000\"},{\"price\":\"63901.1\",\"size\":\"3.11347\"}],\"offset\":3902959,\"nonce\":36957280,\"last_updated_at\":1785276557533136,\"begin_nonce\":36957279},\"timestamp\":1785276557584,\"type\":\"update/order_book\"}"
            "raw": "{\"channel\":\"order_book:1\",\"last_updated_at\":1785276557624133,\"offset\":3902960,\"order_book\":{\"code\":0,\"asks\":[{\"price\":\"64042.4\",\"size\":\"3.12622\"},{\"price\":\"64047.4\",\"size\":\"0.00000\"}],\"bids\":[{\"price\":\"63901.1\",\"size\":\"0.00000\"},{\"price\":\"63898.2\",\"size\":\"3.11347\"}],\"offset\":3902960,\"nonce\":36957283,\"last_updated_at\":1785276557624133,\"begin_nonce\":36957280},\"timestamp\":1785276557633,\"type\":\"update/order_book\"}"
            "raw": "{\"channel\":\"order_book:1\",\"last_updated_at\":1785276557839506,\"offset\":3902961,\"order_book\":{\"code\":0,\"asks\":[{\"price\":\"64029.7\",\"size\":\"3.12622\"},{\"price\":\"64042.4\",\"size\":\"0.00000\"}],\"bids\":[{\"price\":\"63917.2\",\"size\":\"3.11347\"},{\"price\":\"63898.2\",\"size\":\"0.00000\"}],\"offset\":3902961,\"nonce\":36957295,\"last_updated_at\":1785276557839506,\"begin_nonce\":36957283},\"timestamp\":1785276557884,\"type\":\"update/order_book\"}"
            "raw": "{\"channel\":\"order_book:1\",\"last_updated_at\":1785276557953605,\"offset\":3902963,\"order_book\":{\"code\":0,\"asks\":[{\"price\":\"64051.2\",\"size\":\"15.62059\"},{\"price\":\"64060.8\",\"size\":\"15.62059\"},{\"price\":\"64070.4\",\"size\":\"15.62059\"},{\"price\":\"64195.2\",\"size\":\"0.00000\"},{\"price\":\"64204.8\",\"size\":\"0.00000\"},{\"price\":\"64214.4\",\"size\":\"0.00000\"}],\"bids\":[{\"price\":\"63897.6\",\"size\":\"15.60975\"},{\"price\":\"63888.0\",\"size\":\"15.60975\"},{\"price\":\"63878.4\",\"size\":\"15.60975\"},{\"price\":\"63753.6\",\"size\":\"0.00000\"},{\"price\":\"63744.0\",\"size\":\"0.00000\"},{\"price\":\"63734.4\",\"size\":\"0.00000\"}],\"offset\":3902963,\"nonce\":36957300,\"last_updated_at\":1785276557953605,\"begin_nonce\":36957295},\"timestamp\":1785276557985,\"type\":\"update/order_book\"}"
            "raw": "{\"channel\":\"order_book:1\",\"last_updated_at\":1785276558001557,\"offset\":3902964,\"order_book\":{\"code\":0,\"asks\":[{\"price\":\"64016.3\",\"size\":\"3.12622\"},{\"price\":\"64029.7\",\"size\":\"0.00000\"}],\"bids\":[{\"price\":\"63933.8\",\"size\":\"3.11347\"},{\"price\":\"63917.2\",\"size\":\"0.00000\"}],\"offset\":3902964,\"nonce\":36957301,\"last_updated_at\":1785276558001557,\"begin_nonce\":36957300},\"timestamp\":1785276558033,\"type\":\"update/order_book\"}"
            "raw": "{\"channel\":\"order_book:1\",\"last_updated_at\":1785276558229360,\"offset\":3902965,\"order_book\":{\"code\":0,\"asks\":[{\"price\":\"64010.0\",\"size\":\"3.12622\"},{\"price\":\"64016.3\",\"size\":\"0.00000\"}],\"bids\":[{\"price\":\"63940.1\",\"size\":\"3.11347\"},{\"price\":\"63933.8\",\"size\":\"0.00000\"}],\"offset\":3902965,\"nonce\":36957307,\"last_updated_at\":1785276558229360,\"begin_nonce\":36957301},\"timestamp\":1785276558234,\"type\":\"update/order_book\"}"
            "raw": "{\"channel\":\"order_book:1\",\"last_updated_at\":1785276558303894,\"offset\":3902967,\"order_book\":{\"code\":0,\"asks\":[{\"price\":\"64016.3\",\"size\":\"0.00163\"},{\"price\":\"64020.0\",\"size\":\"0.00096\"}],\"bids\":[],\"offset\":3902967,\"nonce\":36957309,\"last_updated_at\":1785276558303894,\"begin_nonce\":36957307},\"timestamp\":1785276558334,\"type\":\"update/order_book\"}"
            "raw": "{\"channel\":\"order_book:1\",\"last_updated_at\":1785276558378605,\"offset\":3902969,\"order_book\":{\"code\":0,\"asks\":[],\"bids\":[{\"price\":\"63929.5\",\"size\":\"0.00149\"},{\"price\":\"63929.4\",\"size\":\"0.00000\"}],\"offset\":3902969,\"nonce\":36957312,\"last_updated_at\":1785276558378605,\"begin_nonce\":36957309},\"timestamp\":1785276558384,\"type\":\"update/order_book\"}"
            "raw": "{\"channel\":\"order_book:1\",\"last_updated_at\":1785276558483065,\"offset\":3902970,\"order_book\":{\"code\":0,\"asks\":[{\"price\":\"64009.3\",\"size\":\"3.12622\"},{\"price\":\"64010.0\",\"size\":\"0.00000\"}],\"bids\":[{\"price\":\"63940.8\",\"size\":\"3.11347\"},{\"price\":\"63940.1\",\"size\":\"0.00000\"}],\"offset\":3902970,\"nonce\":36957313,\"last_updated_at\":1785276558483065,\"begin_nonce\":36957312},\"timestamp\":1785276558485,\"type\":\"update/order_book\"}"
            "raw": "{\"channel\":\"order_book:1\",\"last_updated_at\":1785276558532684,\"offset\":3902971,\"order_book\":{\"code\":0,\"asks\":[{\"price\":\"64014.6\",\"size\":\"0.00163\"},{\"price\":\"64016.3\",\"size\":\"0.00000\"}],\"bids\":[],\"offset\":3902971,\"nonce\":36957315,\"last_updated_at\":1785276558532684,\"begin_nonce\":36957313},\"timestamp\":1785276558533,\"type\":\"update/order_book\"}"
            "raw": "{\"channel\":\"order_book:1\",\"last_updated_at\":1785276558601510,\"offset\":3902972,\"order_book\":{\"code\":0,\"asks\":[{\"price\":\"64014.6\",\"size\":\"0.00000\"},{\"price\":\"64014.7\",\"size\":\"0.00163\"}],\"bids\":[],\"offset\":3902972,\"nonce\":36957317,\"last_updated_at\":1785276558601510,\"begin_nonce\":36957315},\"timestamp\":1785276558634,\"type\":\"update/order_book\"}"
            "raw": "{\"channel\":\"order_book:1\",\"last_updated_at\":1785276558730216,\"offset\":3902973,\"order_book\":{\"code\":0,\"asks\":[{\"price\":\"64009.3\",\"size\":\"0.00000\"},{\"price\":\"64010.3\",\"size\":\"3.12622\"}],\"bids\":[{\"price\":\"63940.8\",\"size\":\"0.00000\"},{\"price\":\"63939.1\",\"size\":\"3.11347\"}],\"offset\":3902973,\"nonce\":36957319,\"last_updated_at\":1785276558730216,\"begin_nonce\":36957317},\"timestamp\":1785276558734,\"type\":\"update/order_book\"}"
            "raw": "{\"channel\":\"order_book:1\",\"last_updated_at\":1785276558930757,\"offset\":3902974,\"order_book\":{\"code\":0,\"asks\":[{\"price\":\"64008.7\",\"size\":\"3.12622\"},{\"price\":\"64010.3\",\"size\":\"0.00000\"}],\"bids\":[],\"offset\":3902974,\"nonce\":36957323,\"last_updated_at\":1785276558930757,\"begin_nonce\":36957319},\"timestamp\":1785276558934,\"type\":\"update/order_book\"}"
            "raw": "{\"channel\":\"order_book:1\",\"last_updated_at\":1785276559147556,\"offset\":3902975,\"order_book\":{\"code\":0,\"asks\":[{\"price\":\"64008.7\",\"size\":\"0.00000\"},{\"price\":\"64009.5\",\"size\":\"3.12622\"}],\"bids\":[{\"price\":\"63940.0\",\"size\":\"3.11444\"},{\"price\":\"63939.1\",\"size\":\"0.00000\"}],\"offset\":3902975,\"nonce\":36957329,\"last_updated_at\":1785276559147556,\"begin_nonce\":36957323},\"timestamp\":1785276559184,\"type\":\"update/order_book\"}"
            "raw": "{\"channel\":\"order_book:1\",\"last_updated_at\":1785276559394828,\"offset\":3902976,\"order_book\":{\"code\":0,\"asks\":[{\"price\":\"64008.6\",\"size\":\"3.12622\"},{\"price\":\"64009.5\",\"size\":\"0.00000\"}],\"bids\":[{\"price\":\"63941.5\",\"size\":\"3.11347\"},{\"price\":\"63940.0\",\"size\":\"0.00097\"}],\"offset\":3902976,\"nonce\":36957332,\"last_updated_at\":1785276559394828,\"begin_nonce\":36957329},\"timestamp\":1785276559433,\"type\":\"update/order_book\"}"
            "raw": "{\"channel\":\"order_book:1\",\"last_updated_at\":1785276559663201,\"offset\":3902978,\"order_book\":{\"code\":0,\"asks\":[{\"price\":\"64014.7\",\"size\":\"0.00000\"},{\"price\":\"64014.8\",\"size\":\"0.00163\"}],\"bids\":[],\"offset\":3902978,\"nonce\":36957337,\"last_updated_at\":1785276559663201,\"begin_nonce\":36957332},\"timestamp\":1785276559683,\"type\":\"update/order_book\"}"
            "raw": "{\"channel\":\"order_book:1\",\"last_updated_at\":1785276560743253,\"offset\":3902980,\"order_book\":{\"code\":0,\"asks\":[{\"price\":\"64014.8\",\"size\":\"0.00000\"},{\"price\":\"64014.9\",\"size\":\"0.00163\"}],\"bids\":[],\"offset\":3902980,\"nonce\":36957342,\"last_updated_at\":1785276560743253,\"begin_nonce\":36957337},\"timestamp\":1785276560783,\"type\":\"update/order_book\"}"
            "raw": "{\"channel\":\"order_book:1\",\"last_updated_at\":1785276561481844,\"offset\":3902981,\"order_book\":{\"code\":0,\"asks\":[{\"price\":\"64008.5\",\"size\":\"3.12622\"},{\"price\":\"64008.6\",\"size\":\"0.00000\"}],\"bids\":[{\"price\":\"63941.6\",\"size\":\"3.11347\"},{\"price\":\"63941.5\",\"size\":\"0.00000\"}],\"offset\":3902981,\"nonce\":36957346,\"last_updated_at\":1785276561481844,\"begin_nonce\":36957342},\"timestamp\":1785276561484,\"type\":\"update/order_book\"}"
            "raw": "{\"channel\":\"order_book:1\",\"last_updated_at\":1785276561991730,\"offset\":3902982,\"order_book\":{\"code\":0,\"asks\":[{\"price\":\"64008.5\",\"size\":\"0.00000\"},{\"price\":\"64008.6\",\"size\":\"3.12622\"}],\"bids\":[{\"price\":\"63941.6\",\"size\":\"0.00000\"},{\"price\":\"63941.5\",\"size\":\"3.11347\"}],\"offset\":3902982,\"nonce\":36957350,\"last_updated_at\":1785276561991730,\"begin_nonce\":36957346},\"timestamp\":1785276562034,\"type\":\"update/order_book\"}"
            "raw": "{\"channel\":\"order_book:1\",\"last_updated_at\":1785276562037145,\"offset\":3902983,\"order_book\":{\"code\":0,\"asks\":[{\"price\":\"64008.6\",\"size\":\"3.12621\"}],\"bids\":[],\"offset\":3902983,\"nonce\":36957351,\"last_updated_at\":1785276562037145,\"begin_nonce\":36957350},\"timestamp\":1785276562084,\"type\":\"update/order_book\"}"
            "raw": "{\"channel\":\"order_book:1\",\"last_updated_at\":1785276562273887,\"offset\":3902984,\"order_book\":{\"code\":0,\"asks\":[{\"price\":\"64014.9\",\"size\":\"0.00000\"},{\"price\":\"64015.0\",\"size\":\"0.00163\"}],\"bids\":[],\"offset\":3902984,\"nonce\":36957354,\"last_updated_at\":1785276562273887,\"begin_nonce\":36957351},\"timestamp\":1785276562284,\"type\":\"update/order_book\"}"
            "raw": "{\"channel\":\"order_book:1\",\"last_updated_at\":1785276562375125,\"offset\":3902986,\"order_book\":{\"code\":0,\"asks\":[{\"price\":\"64014.9\",\"size\":\"0.00163\"},{\"price\":\"64015.0\",\"size\":\"0.00000\"}],\"bids\":[],\"offset\":3902986,\"nonce\":36957356,\"last_updated_at\":1785276562375125,\"begin_nonce\":36957354},\"timestamp\":1785276562384,\"type\":\"update/order_book\"}"
            "raw": "{\"channel\":\"order_book:1\",\"last_updated_at\":1785276562513347,\"offset\":3902987,\"order_book\":{\"code\":0,\"asks\":[{\"price\":\"64014.9\",\"size\":\"0.00000\"},{\"price\":\"64015.0\",\"size\":\"0.00163\"}],\"bids\":[],\"offset\":3902987,\"nonce\":36957357,\"last_updated_at\":1785276562513347,\"begin_nonce\":36957356},\"timestamp\":1785276562533,\"type\":\"update/order_book\"}"
            "raw": "{\"channel\":\"order_book:1\",\"last_updated_at\":1785276563413496,\"offset\":3902988,\"order_book\":{\"code\":0,\"asks\":[{\"price\":\"64014.9\",\"size\":\"0.00163\"},{\"price\":\"64015.0\",\"size\":\"0.00000\"}],\"bids\":[],\"offset\":3902988,\"nonce\":36957360,\"last_updated_at\":1785276563413496,\"begin_nonce\":36957357},\"timestamp\":1785276563434,\"type\":\"update/order_book\"}"
            "raw": "{\"channel\":\"order_book:1\",\"last_updated_at\":1785276564119123,\"offset\":3902989,\"order_book\":{\"code\":0,\"asks\":[{\"price\":\"64008.6\",\"size\":\"0.00000\"},{\"price\":\"64008.7\",\"size\":\"3.12621\"}],\"bids\":[{\"price\":\"63941.5\",\"size\":\"0.00000\"},{\"price\":\"63941.4\",\"size\":\"3.11347\"}],\"offset\":3902989,\"nonce\":36957365,\"last_updated_at\":1785276564119123,\"begin_nonce\":36957360},\"timestamp\":1785276564134,\"type\":\"update/order_book\"}"
            "raw": "{\"channel\":\"order_book:1\",\"last_updated_at\":1785276564394335,\"offset\":3902991,\"order_book\":{\"code\":0,\"asks\":[],\"bids\":[{\"price\":\"63929.6\",\"size\":\"0.00149\"},{\"price\":\"63929.5\",\"size\":\"0.00000\"}],\"offset\":3902991,\"nonce\":36957370,\"last_updated_at\":1785276564394335,\"begin_nonce\":36957365},\"timestamp\":1785276564433,\"type\":\"update/order_book\"}"
            "raw": "{\"channel\":\"order_book:1\",\"last_updated_at\":1785276564553669,\"offset\":3902992,\"order_book\":{\"code\":0,\"asks\":[{\"price\":\"64014.8\",\"size\":\"0.00163\"},{\"price\":\"64014.9\",\"size\":\"0.00000\"}],\"bids\":[],\"offset\":3902992,\"nonce\":36957371,\"last_updated_at\":1785276564553669,\"begin_nonce\":36957370},\"timestamp\":1785276564584,\"type\":\"update/order_book\"}"
            "raw": "{\"channel\":\"order_book:1\",\"last_updated_at\":1785276564652999,\"offset\":3902993,\"order_book\":{\"code\":0,\"asks\":[{\"price\":\"64008.5\",\"size\":\"3.12621\"},{\"price\":\"64008.7\",\"size\":\"0.00000\"}],\"bids\":[{\"price\":\"63941.6\",\"size\":\"3.11347\"},{\"price\":\"63941.4\",\"size\":\"0.00000\"}],\"offset\":3902993,\"nonce\":36957373,\"last_updated_at\":1785276564652999,\"begin_nonce\":36957371},\"timestamp\":1785276564684,\"type\":\"update/order_book\"}"
            "raw": "{\"channel\":\"order_book:1\",\"last_updated_at\":1785276565015129,\"offset\":3902995,\"order_book\":{\"code\":0,\"asks\":[],\"bids\":[{\"price\":\"63929.7\",\"size\":\"0.00149\"},{\"price\":\"63929.6\",\"size\":\"0.00000\"}],\"offset\":3902995,\"nonce\":36957377,\"last_updated_at\":1785276565015129,\"begin_nonce\":36957373},\"timestamp\":1785276565034,\"type\":\"update/order_book\"}"
            "raw": "{\"channel\":\"order_book:1\",\"last_updated_at\":1785276565180969,\"offset\":3902997,\"order_book\":{\"code\":0,\"asks\":[{\"price\":\"64008.5\",\"size\":\"0.00000\"},{\"price\":\"64008.6\",\"size\":\"3.12621\"}],\"bids\":[{\"price\":\"63941.6\",\"size\":\"0.00000\"},{\"price\":\"63941.5\",\"size\":\"3.11347\"}],\"offset\":3902997,\"nonce\":36957379,\"last_updated_at\":1785276565180969,\"begin_nonce\":36957377},\"timestamp\":1785276565184,\"type\":\"update/order_book\"}"
            "raw": "{\"channel\":\"order_book:1\",\"last_updated_at\":1785276565590808,\"offset\":3902998,\"order_book\":{\"code\":0,\"asks\":[],\"bids\":[{\"price\":\"63929.8\",\"size\":\"0.00149\"},{\"price\":\"63929.7\",\"size\":\"0.00000\"}],\"offset\":3902998,\"nonce\":36957382,\"last_updated_at\":1785276565590808,\"begin_nonce\":36957379},\"timestamp\":1785276565633,\"type\":\"update/order_book\"}"
            "raw": "{\"channel\":\"order_book:1\",\"last_updated_at\":1785276565723465,\"offset\":3903000,\"order_book\":{\"code\":0,\"asks\":[{\"price\":\"64014.7\",\"size\":\"0.00163\"},{\"price\":\"64014.8\",\"size\":\"0.00000\"}],\"bids\":[],\"offset\":3903000,\"nonce\":36957384,\"last_updated_at\":1785276565723465,\"begin_nonce\":36957382},\"timestamp\":1785276565734,\"type\":\"update/order_book\"}"
            "raw": "{\"channel\":\"order_book:1\",\"last_updated_at\":1785276566093078,\"offset\":3903002,\"order_book\":{\"code\":0,\"asks\":[],\"bids\":[{\"price\":\"63929.9\",\"size\":\"0.00149\"},{\"price\":\"63929.8\",\"size\":\"0.00000\"}],\"offset\":3903002,\"nonce\":36957389,\"last_updated_at\":1785276566093078,\"begin_nonce\":36957384},\"timestamp\":1785276566133,\"type\":\"update/order_book\"}"
            "raw": "{\"channel\":\"order_book:1\",\"last_updated_at\":1785276566503184,\"offset\":3903004,\"order_book\":{\"code\":0,\"asks\":[],\"bids\":[{\"price\":\"63930.0\",\"size\":\"0.00149\"},{\"price\":\"63929.9\",\"size\":\"0.00000\"}],\"offset\":3903004,\"nonce\":36957392,\"last_updated_at\":1785276566503184,\"begin_nonce\":36957389},\"timestamp\":1785276566534,\"type\":\"update/order_book\"}"
            "raw": "{\"channel\":\"order_book:1\",\"last_updated_at\":1785276566701499,\"offset\":3903006,\"order_book\":{\"code\":0,\"asks\":[{\"price\":\"64008.5\",\"size\":\"3.12621\"},{\"price\":\"64008.6\",\"size\":\"0.00000\"}],\"bids\":[{\"price\":\"63941.6\",\"size\":\"3.11347\"},{\"price\":\"63941.5\",\"size\":\"0.00000\"}],\"offset\":3903006,\"nonce\":36957395,\"last_updated_at\":1785276566701499,\"begin_nonce\":36957392},\"timestamp\":1785276566734,\"type\":\"update/order_book\"}"
            "raw": "{\"channel\":\"order_book:1\",\"last_updated_at\":1785276566850281,\"offset\":3903007,\"order_book\":{\"code\":0,\"asks\":[],\"bids\":[{\"price\":\"63930.1\",\"size\":\"0.00149\"},{\"price\":\"63930.0\",\"size\":\"0.00000\"}],\"offset\":3903007,\"nonce\":36957396,\"last_updated_at\":1785276566850281,\"begin_nonce\":36957395},\"timestamp\":1785276566883,\"type\":\"update/order_book\"}"
            "raw": "{\"channel\":\"order_book:1\",\"last_updated_at\":1785276567294288,\"offset\":3903009,\"order_book\":{\"code\":0,\"asks\":[],\"bids\":[{\"price\":\"63930.2\",\"size\":\"0.00149\"},{\"price\":\"63930.1\",\"size\":\"0.00000\"}],\"offset\":3903009,\"nonce\":36957401,\"last_updated_at\":1785276567294288,\"begin_nonce\":36957396},\"timestamp\":1785276567334,\"type\":\"update/order_book\"}"
            "raw": "{\"channel\":\"order_book:1\",\"last_updated_at\":1785276567507677,\"offset\":3903013,\"order_book\":{\"code\":0,\"asks\":[{\"price\":\"64014.7\",\"size\":\"0.00000\"},{\"price\":\"64016.4\",\"size\":\"0.00163\"}],\"bids\":[{\"price\":\"63931.9\",\"size\":\"0.00149\"},{\"price\":\"63930.2\",\"size\":\"0.00000\"}],\"offset\":3903013,\"nonce\":36957405,\"last_updated_at\":1785276567507677,\"begin_nonce\":36957401},\"timestamp\":1785276567534,\"type\":\"update/order_book\"}"
            "raw": "{\"channel\":\"order_book:1\",\"last_updated_at\":1785276567600345,\"offset\":3903015,\"order_book\":{\"code\":0,\"asks\":[{\"price\":\"64016.3\",\"size\":\"0.00163\"},{\"price\":\"64016.4\",\"size\":\"0.00000\"}],\"bids\":[],\"offset\":3903015,\"nonce\":36957408,\"last_updated_at\":1785276567600345,\"begin_nonce\":36957405},\"timestamp\":1785276567633,\"type\":\"update/order_book\"}"
            "raw": "{\"channel\":\"order_book:1\",\"last_updated_at\":1785276567762394,\"offset\":3903017,\"order_book\":{\"code\":0,\"asks\":[],\"bids\":[{\"price\":\"63932.0\",\"size\":\"0.00149\"},{\"price\":\"63931.9\",\"size\":\"0.00000\"}],\"offset\":3903017,\"nonce\":36957413,\"last_updated_at\":1785276567762394,\"begin_nonce\":36957408},\"timestamp\":1785276567784,\"type\":\"update/order_book\"}"
